File: RE3Sb3A2O14/Data/Nd3Sb3Mg2O14 MT 1.8 to 300 5000 oe 53.8 mg.dc.dat
[Header]
TITLE,MPMS DC Measurement
BYAPP,MPMS Measurement,2.1,Summary
FILEOPENTIME, 1431620219.692000 5/14/2015, 12:16:59 PM

INFO, APPNAME, MPMS MultiVu Application, Revision 1.60,  Build 081

INFO, NAME, Nd3Sb3Mg2O14
INFO, WEIGHT, 53.800
INFO, AREA, 1.000
INFO, LENGTH, 1.000
INFO, SHAPE, 0
INFO, COMMENT,
INFO, SEQUENCE FILE: MT up.seq_5 to 300_quick.seq


INFO, BACKGROUND DATA FILE:, None


STARTUPAXIS,X,4,LINEAR,AUTO,0.000000,0.000000
STARTUPAXIS,Y1,5,LINEAR,AUTO,0.000000,0.000000


STARTUPGROUP,Longitudinal
FIELDGROUP,Longitudinal,1,2,3,4,5,6,7,8,9,15,16,17,18,27,28
FIELDGROUP,Transverse,1,2,3,4,10,11,12,13,14,19,20,21,22,27,28

PLOT_APPEARANCE,ALL,HORZ_GRID_ON,VERT_GRID_ON,MARKERS_AND_LINES

[Data]
Time,Comment,Field (Oe),Temperature (K),Long Moment (emu),Long Scan Std Dev,Long Algorithm,Long Reg Fit,Long Percent Error (%),Trans Moment (emu),Trans Scan Std Dev,Trans Algorithm,Trans Reg Fit,Trans Percent Error (%),Long Moment [w/o ABS] (emu),Long Scan Std Dev [w/o ABS],Long Reg Fit [w/o ABS],Long Percent Error [w/o ABS] (%),Trans Moment [w/o ABS] (emu),Trans Scan Std Dev [w/o ABS],Trans Reg Fit [w/o ABS],Trans Percent Error [w/o ABS] (%),Points per Scan,Scans per Measurement,Scan Length (cm),Delta Temp (K),Rot Position (deg),Error,EC Comp. Running,Using ABS,
1431620219.692,,5.000000e+003,1.773137e+000,3.165264e-001,1.176740e-004,3,9.886228e-001,3.717667e-002,,,,,,,,,,,,,,32,2,4.000000e+000,2.032042e-003,0.000000e+000,0,,0,
1431620398.022,,5.000000e+003,2.745384e+000,2.065848e-001,2.237924e-002,3,9.861592e-001,1.083296e+001,,,,,,,,,,,,,,32,2,4.000000e+000,8.354959e-001,0.000000e+000,0,,0,
1431620505.892,,5.000000e+003,3.604637e+000,1.563147e-001,1.518111e-002,3,9.866508e-001,9.711884e+000,,,,,,,,,,,,,,32,2,4.000000e+000,9.719238e-001,0.000000e+000,0,,0,
1431620584.072,,5.000000e+003,4.637010e+000,1.236218e-001,1.928898e-003,3,9.890153e-001,1.560322e+000,,,,,,,,,,,,,,32,2,4.000000e+000,2.024527e-001,0.000000e+000,0,,0,
1431620611.452,,5.000000e+003,4.854568e+000,1.182304e-001,1.779777e-003,3,9.888340e-001,1.505346e+000,,,,,,,,,,,,,,32,2,4.000000e+000,2.111111e-001,0.000000e+000,0,,0,
1431620642.022,,5.000000e+003,5.103002e+000,1.127848e-001,1.765099e-003,3,9.888480e-001,1.565016e+000,,,,,,,,,,,,,,32,2,4.000000e+000,2.081990e-001,0.000000e+000,0,,0,
1431620666.812,,5.000000e+003,5.315364e+000,1.084355e-001,1.407278e-003,3,9.888779e-001,1.297802e+000,,,,,,,,,,,,,,32,2,4.000000e+000,1.813850e-001,0.000000e+000,0,,0,
1431620692.042,,5.000000e+003,5.520989e+000,1.045910e-001,1.356238e-003,3,9.888856e-001,1.296706e+000,,,,,,,,,,,,,,32,2,4.000000e+000,2.008009e-001,0.000000e+000,0,,0,
1431620743.822,,5.000000e+003,5.933594e+000,9.742762e-002,1.241293e-003,3,9.890149e-001,1.274067e+000,,,,,,,,,,,,,,32,2,4.000000e+000,1.787529e-001,0.000000e+000,0,,0,
1431620808.002,,5.000000e+003,6.442153e+000,8.991659e-002,9.933379e-004,3,9.889532e-001,1.104733e+000,,,,,,,,,,,,,,32,2,4.000000e+000,1.964350e-001,0.000000e+000,0,,0,
1431620870.633,,5.000000e+003,6.936607e+000,8.353001e-002,8.673874e-004,3,9.888110e-001,1.038414e+000,,,,,,,,,,,,,,32,2,4.000000e+000,1.898789e-001,0.000000e+000,0,,0,
1431620934.343,,5.000000e+003,7.479292e+000,7.765698e-002,9.046979e-004,3,9.885192e-001,1.164992e+000,,,,,,,,,,,,,,32,2,4.000000e+000,2.345691e-001,0.000000e+000,0,,0,
1431620991.873,,5.000000e+003,7.958531e+000,7.299712e-002,7.060704e-004,3,9.888836e-001,9.672579e-001,,,,,,,,,,,,,,32,2,4.000000e+000,1.887012e-001,0.000000e+000,0,,0,
1431621064.553,,5.000000e+003,8.549416e+000,6.796978e-002,4.966005e-004,3,9.890268e-001,7.306195e-001,,,,,,,,,,,,,,32,2,4.000000e+000,1.651993e-001,0.000000e+000,0,,0,
1431621116.173,,5.000000e+003,8.957673e+000,6.496353e-002,4.894092e-004,3,9.889454e-001,7.533599e-001,,,,,,,,,,,,,,32,2,4.000000e+000,1.918583e-001,0.000000e+000,0,,0,
1431621180.963,,5.000000e+003,9.467918e+000,6.149489e-002,4.623377e-004,3,9.889317e-001,7.518311e-001,,,,,,,,,,,,,,32,2,4.000000e+000,1.898661e-001,0.000000e+000,0,,0,
1431621242.653,,5.000000e+003,9.971547e+000,5.848682e-002,4.140137e-004,3,9.886962e-001,7.078753e-001,,,,,,,,,,,,,,32,2,4.000000e+000,1.710510e-001,0.000000e+000,0,,0,
1431621305.013,,5.000000e+003,1.046111e+001,5.574888e-002,3.525110e-004,3,9.887323e-001,6.323194e-001,,,,,,,,,,,,,,32,2,4.000000e+000,1.694298e-001,0.000000e+000,0,,0,
1431621369.443,,5.000000e+003,1.097455e+001,5.317722e-002,3.235903e-004,3,9.889728e-001,6.085131e-001,,,,,,,,,,,,,,32,2,4.000000e+000,1.824999e-001,0.000000e+000,0,,0,
1431621435.213,,5.000000e+003,1.148336e+001,5.085916e-002,2.827843e-004,3,9.887073e-001,5.560145e-001,,,,,,,,,,,,,,32,2,4.000000e+000,1.866903e-001,0.000000e+000,0,,0,
1431621504.363,,5.000000e+003,1.200235e+001,4.865509e-002,4.192663e-004,3,9.885241e-001,8.617111e-001,,,,,,,,,,,,,,32,2,4.000000e+000,2.234602e-001,0.000000e+000,0,,0,
1431621563.553,,5.000000e+003,1.250099e+001,4.669980e-002,2.524333e-004,3,9.888740e-001,5.405447e-001,,,,,,,,,,,,,,32,2,4.000000e+000,1.917496e-001,0.000000e+000,0,,0,
1431621623.414,,5.000000e+003,1.298454e+001,4.505849e-002,2.212551e-004,3,9.888145e-001,4.910399e-001,,,,,,,,,,,,,,32,2,4.000000e+000,1.742306e-001,0.000000e+000,0,,0,
1431621682.334,,5.000000e+003,1.349628e+001,4.347592e-002,1.880250e-004,3,9.891459e-001,4.324808e-001,,,,,,,,,,,,,,32,2,4.000000e+000,1.739502e-001,0.000000e+000,0,,0,
1431621745.904,,5.000000e+003,1.401019e+001,4.198785e-002,2.059111e-004,3,9.888682e-001,4.904063e-001,,,,,,,,,,,,,,32,2,4.000000e+000,1.977901e-001,0.000000e+000,0,,0,
1431621806.884,,5.000000e+003,1.450765e+001,4.062903e-002,1.941600e-004,3,9.890049e-001,4.778849e-001,,,,,,,,,,,,,,32,2,4.000000e+000,2.018900e-001,0.000000e+000,0,,0,
1431621866.804,,5.000000e+003,1.501381e+001,3.934792e-002,1.727836e-004,3,9.888448e-001,4.391176e-001,,,,,,,,,,,,,,32,2,4.000000e+000,1.912508e-001,0.000000e+000,0,,0,
1431621928.824,,5.000000e+003,1.551772e+001,3.815705e-002,1.737293e-004,3,9.889051e-001,4.553007e-001,,,,,,,,,,,,,,32,2,4.000000e+000,1.967402e-001,0.000000e+000,0,,0,
1431621990.564,,5.000000e+003,1.602486e+001,3.702457e-002,1.572235e-004,3,9.892847e-001,4.246465e-001,,,,,,,,,,,,,,32,2,4.000000e+000,1.822805e-001,0.000000e+000,0,,0,
1431622050.114,,5.000000e+003,1.651985e+001,3.599044e-002,1.373882e-004,3,9.889833e-001,3.817352e-001,,,,,,,,,,,,,,32,2,4.000000e+000,1.865005e-001,0.000000e+000,0,,0,
1431622113.154,,5.000000e+003,1.703428e+001,3.498774e-002,1.473823e-004,3,9.889178e-001,4.212397e-001,,,,,,,,,,,,,,32,2,4.000000e+000,1.851196e-001,0.000000e+000,0,,0,
1431622175.844,,5.000000e+003,1.753678e+001,3.405091e-002,1.275522e-004,3,9.892288e-001,3.745925e-001,,,,,,,,,,,,,,32,2,4.000000e+000,1.924400e-001,0.000000e+000,0,,0,
1431622239.064,,5.000000e+003,1.804397e+001,3.319135e-002,1.337267e-004,3,9.890206e-001,4.028963e-001,,,,,,,,,,,,,,32,2,4.000000e+000,2.015400e-001,0.000000e+000,0,,0,
1431622299.655,,5.000000e+003,1.854363e+001,3.236212e-002,1.238933e-004,3,9.889604e-001,3.828343e-001,,,,,,,,,,,,,,32,2,4.000000e+000,1.994705e-001,0.000000e+000,0,,0,
1431622357.535,,5.000000e+003,1.904320e+001,3.158443e-002,1.002963e-004,3,9.887975e-001,3.175499e-001,,,,,,,,,,,,,,32,2,4.000000e+000,1.809902e-001,0.000000e+000,0,,0,
1431622419.985,,5.000000e+003,1.953368e+001,3.086783e-002,1.128311e-004,3,9.889245e-001,3.655297e-001,,,,,,,,,,,,,,32,2,4.000000e+000,1.612701e-001,0.000000e+000,0,,0,
1431622487.505,,5.000000e+003,2.005191e+001,3.013857e-002,9.500822e-005,3,9.888635e-001,3.152379e-001,,,,,,,,,,,,,,32,2,4.000000e+000,1.778107e-001,0.000000e+000,0,,0,
1431622552.405,,5.000000e+003,2.057949e+001,2.945041e-002,9.517022e-005,3,9.886455e-001,3.231541e-001,,,,,,,,,,,,,,32,2,4.000000e+000,1.987514e-001,0.000000e+000,0,,0,
1431622623.375,,5.000000e+003,2.117153e+001,2.868157e-002,9.351200e-005,3,9.888092e-001,3.260352e-001,,,,,,,,,,,,,,32,2,4.000000e+000,2.007389e-001,0.000000e+000,0,,0,
1431622673.235,,5.000000e+003,2.157021e+001,2.820014e-002,8.605464e-005,3,9.889858e-001,3.051568e-001,,,,,,,,,,,,,,32,2,4.000000e+000,1.883087e-001,0.000000e+000,0,,0,
1431622735.225,,5.000000e+003,2.207414e+001,2.761956e-002,7.784260e-005,3,9.887526e-001,2.818386e-001,,,,,,,,,,,,,,32,2,4.000000e+000,1.901512e-001,0.000000e+000,0,,0,
1431622798.035,,5.000000e+003,2.257939e+001,2.706409e-002,7.437338e-005,3,9.890832e-001,2.748047e-001,,,,,,,,,,,,,,32,2,4.000000e+000,1.952591e-001,0.000000e+000,0,,0,
1431622859.155,,5.000000e+003,2.308453e+001,2.652751e-002,7.801118e-005,3,9.890244e-001,2.940765e-001,,,,,,,,,,,,,,32,2,4.000000e+000,1.957092e-001,0.000000e+000,0,,0,
1431622919.595,,5.000000e+003,2.358622e+001,2.601570e-002,6.850838e-005,3,9.891691e-001,2.633347e-001,,,,,,,,,,,,,,32,2,4.000000e+000,1.893692e-001,0.000000e+000,0,,0,
1431622980.645,,5.000000e+003,2.409243e+001,2.553456e-002,6.917879e-005,3,9.888941e-001,2.709222e-001,,,,,,,,,,,,,,32,2,4.000000e+000,1.904411e-001,0.000000e+000,0,,0,
1431623043.536,,5.000000e+003,2.457931e+001,2.508033e-002,5.511754e-005,3,9.890434e-001,2.197640e-001,,,,,,,,,,,,,,32,2,4.000000e+000,1.573811e-001,0.000000e+000,0,,0,
1431623186.936,,5.000000e+003,2.499380e+001,2.469810e-002,3.805070e-006,3,9.885088e-001,1.540633e-002,,,,,,,,,,,,,,32,2,4.000000e+000,7.099152e-003,0.000000e+000,0,,0,
1431623265.176,,5.000000e+003,2.499780e+001,2.469628e-002,0.000000e+000,3,9.889842e-001,0.000000e+000,,,,,,,,,,,,,,32,1,4.000000e+000,6.210327e-003,0.000000e+000,0,,0,
1431623331.006,,5.000000e+003,2.843182e+001,2.216104e-002,0.000000e+000,3,9.886618e-001,0.000000e+000,,,,,,,,,,,,,,32,1,4.000000e+000,6.837711e-001,0.000000e+000,0,,0,
1431623378.526,,5.000000e+003,3.131255e+001,2.034487e-002,0.000000e+000,3,9.888930e-001,0.000000e+000,,,,,,,,,,,,,,32,1,4.000000e+000,6.629791e-001,0.000000e+000,0,,0,
1431623425.976,,5.000000e+003,3.435426e+001,1.879798e-002,0.000000e+000,3,9.885713e-001,0.000000e+000,,,,,,,,,,,,,,32,1,4.000000e+000,7.098618e-001,0.000000e+000,0,,0,
1431623473.896,,5.000000e+003,3.739975e+001,1.749592e-002,0.000000e+000,3,9.885278e-001,0.000000e+000,,,,,,,,,,,,,,32,1,4.000000e+000,8.322296e-001,0.000000e+000,0,,0,
1431623518.956,,5.000000e+003,4.035206e+001,1.641287e-002,0.000000e+000,3,9.889138e-001,0.000000e+000,,,,,,,,,,,,,,32,1,4.000000e+000,7.169800e-001,0.000000e+000,0,,0,
1431623565.346,,5.000000e+003,4.337637e+001,1.547573e-002,0.000000e+000,3,9.888660e-001,0.000000e+000,,,,,,,,,,,,,,32,1,4.000000e+000,7.313080e-001,0.000000e+000,0,,0,
1431623610.616,,5.000000e+003,4.636988e+001,1.464889e-002,0.000000e+000,3,9.892254e-001,0.000000e+000,,,,,,,,,,,,,,32,1,4.000000e+000,6.990891e-001,0.000000e+000,0,,0,
1431623667.916,,5.000000e+003,5.024421e+001,1.372896e-002,0.000000e+000,3,9.894704e-001,0.000000e+000,,,,,,,,,,,,,,32,1,4.000000e+000,7.584991e-001,0.000000e+000,0,,0,
1431623698.516,,5.000000e+003,5.228487e+001,1.332242e-002,0.000000e+000,3,9.889755e-001,0.000000e+000,,,,,,,,,,,,,,32,1,4.000000e+000,6.558113e-001,0.000000e+000,0,,0,
1431623745.897,,5.000000e+003,5.536592e+001,1.273314e-002,0.000000e+000,3,9.890565e-001,0.000000e+000,,,,,,,,,,,,,,32,1,4.000000e+000,6.782417e-001,0.000000e+000,0,,0,
1431623789.947,,5.000000e+003,5.823808e+001,1.222077e-002,0.000000e+000,3,9.886469e-001,0.000000e+000,,,,,,,,,,,,,,32,1,4.000000e+000,6.598206e-001,0.000000e+000,0,,0,
1431623836.737,,5.000000e+003,6.128653e+001,1.173062e-002,0.000000e+000,3,9.887475e-001,0.000000e+000,,,,,,,,,,,,,,32,1,4.000000e+000,6.399612e-001,0.000000e+000,0,,0,
1431623882.707,,5.000000e+003,6.418133e+001,1.130731e-002,0.000000e+000,3,9.890835e-001,0.000000e+000,,,,,,,,,,,,,,32,1,4.000000e+000,5.904121e-001,0.000000e+000,0,,0,
1431623932.317,,5.000000e+003,6.721693e+001,1.089765e-002,0.000000e+000,3,9.890035e-001,0.000000e+000,,,,,,,,,,,,,,32,1,4.000000e+000,6.594315e-001,0.000000e+000,0,,0,
1431623977.167,,5.000000e+003,7.017723e+001,1.055345e-002,0.000000e+000,3,9.887853e-001,0.000000e+000,,,,,,,,,,,,,,32,1,4.000000e+000,6.633606e-001,0.000000e+000,0,,0,
1431624025.787,,5.000000e+003,7.326883e+001,1.019629e-002,0.000000e+000,3,9.889316e-001,0.000000e+000,,,,,,,,,,,,,,32,1,4.000000e+000,7.303391e-001,0.000000e+000,0,,0,
1431624070.217,,5.000000e+003,7.623564e+001,9.893262e-003,0.000000e+000,3,9.888293e-001,0.000000e+000,,,,,,,,,,,,,,32,1,4.000000e+000,7.471237e-001,0.000000e+000,0,,0,
1431624116.157,,5.000000e+003,7.926772e+001,9.597850e-003,0.000000e+000,3,9.889019e-001,0.000000e+000,,,,,,,,,,,,,,32,1,4.000000e+000,7.576828e-001,0.000000e+000,0,,0,
1431624160.607,,5.000000e+003,8.228401e+001,9.335776e-003,0.000000e+000,3,9.884223e-001,0.000000e+000,,,,,,,,,,,,,,32,1,4.000000e+000,6.930923e-001,0.000000e+000,0,,0,
1431624205.577,,5.000000e+003,8.525460e+001,9.074098e-003,0.000000e+000,3,9.889938e-001,0.000000e+000,,,,,,,,,,,,,,32,1,4.000000e+000,7.300568e-001,0.000000e+000,0,,0,
1431624249.397,,5.000000e+003,8.814581e+001,8.848978e-003,0.000000e+000,3,9.888975e-001,0.000000e+000,,,,,,,,,,,,,,32,1,4.000000e+000,6.997604e-001,0.000000e+000,0,,0,
1431624295.857,,5.000000e+003,9.113872e+001,8.610780e-003,0.000000e+000,3,9.891405e-001,0.000000e+000,,,,,,,,,,,,,,32,1,4.000000e+000,7.262497e-001,0.000000e+000,0,,0,
1431624340.327,,5.000000e+003,9.414055e+001,8.399449e-003,0.000000e+000,3,9.889595e-001,0.000000e+000,,,,,,,,,,,,,,32,1,4.000000e+000,7.626190e-001,0.000000e+000,0,,0,
1431624387.167,,5.000000e+003,9.724212e+001,8.197549e-003,0.000000e+000,3,9.893348e-001,0.000000e+000,,,,,,,,,,,,,,32,1,4.000000e+000,6.786957e-001,0.000000e+000,0,,0,
1431624432.397,,5.000000e+003,1.001189e+002,8.009857e-003,0.000000e+000,3,9.888952e-001,0.000000e+000,,,,,,,,,,,,,,32,1,4.000000e+000,7.258530e-001,0.000000e+000,0,,0,
1431624476.868,,5.000000e+003,1.031172e+002,7.835960e-003,0.000000e+000,3,9.890256e-001,0.000000e+000,,,,,,,,,,,,,,32,1,4.000000e+000,7.361984e-001,0.000000e+000,0,,0,
1431624521.418,,5.000000e+003,1.060723e+002,7.667568e-003,0.000000e+000,3,9.888629e-001,0.000000e+000,,,,,,,,,,,,,,32,1,4.000000e+000,6.374969e-001,0.000000e+000,0,,0,
1431624568.558,,5.000000e+003,1.090983e+002,7.500339e-003,0.000000e+000,3,9.893712e-001,0.000000e+000,,,,,,,,,,,,,,32,1,4.000000e+000,5.932007e-001,0.000000e+000,0,,0,
1431624629.198,,5.000000e+003,1.129706e+002,7.300613e-003,0.000000e+000,3,9.892763e-001,0.000000e+000,,,,,,,,,,,,,,32,1,4.000000e+000,8.121033e-001,0.000000e+000,0,,0,
1431624660.868,,5.000000e+003,1.150739e+002,7.200608e-003,0.000000e+000,3,9.889727e-001,0.000000e+000,,,,,,,,,,,,,,32,1,4.000000e+000,6.955032e-001,0.000000e+000,0,,0,
1431624707.378,,5.000000e+003,1.180612e+002,7.058381e-003,0.000000e+000,3,9.890321e-001,0.000000e+000,,,,,,,,,,,,,,32,1,4.000000e+000,7.589951e-001,0.000000e+000,0,,0,
1431624755.458,,5.000000e+003,1.210594e+002,6.919224e-003,0.000000e+000,3,9.892087e-001,0.000000e+000,,,,,,,,,,,,,,32,1,4.000000e+000,6.256027e-001,0.000000e+000,0,,0,
1431624805.028,,5.000000e+003,1.240678e+002,6.776160e-003,0.000000e+000,3,9.894304e-001,0.000000e+000,,,,,,,,,,,,,,32,1,4.000000e+000,7.656021e-001,0.000000e+000,0,,0,
1431624850.738,,5.000000e+003,1.270027e+002,6.672437e-003,0.000000e+000,3,9.892644e-001,0.000000e+000,,,,,,,,,,,,,,32,1,4.000000e+000,6.680984e-001,0.000000e+000,0,,0,
1431624896.518,,5.000000e+003,1.299766e+002,6.557950e-003,0.000000e+000,3,9.886248e-001,0.000000e+000,,,,,,,,,,,,,,32,1,4.000000e+000,7.028961e-001,0.000000e+000,0,,0,
1431624943.048,,5.000000e+003,1.329954e+002,6.441934e-003,0.000000e+000,3,9.890385e-001,0.000000e+000,,,,,,,,,,,,,,32,1,4.000000e+000,6.362000e-001,0.000000e+000,0,,0,
1431624984.978,,5.000000e+003,1.359676e+002,6.335917e-003,0.000000e+000,3,9.885850e-001,0.000000e+000,,,,,,,,,,,,,,32,1,4.000000e+000,6.923981e-001,0.000000e+000,0,,0,
1431625029.688,,5.000000e+003,1.389641e+002,6.225843e-003,0.000000e+000,3,9.889432e-001,0.000000e+000,,,,,,,,,,,,,,32,1,4.000000e+000,7.079010e-001,0.000000e+000,0,,0,
1431625075.808,,5.000000e+003,1.419921e+002,6.125276e-003,0.000000e+000,3,9.888434e-001,0.000000e+000,,,,,,,,,,,,,,32,1,4.000000e+000,6.911011e-001,0.000000e+000,0,,0,
1431625124.738,,5.000000e+003,1.450152e+002,6.022190e-003,0.000000e+000,3,9.892147e-001,0.000000e+000,,,,,,,,,,,,,,32,1,4.000000e+000,6.857910e-001,0.000000e+000,0,,0,
1431625169.159,,5.000000e+003,1.478700e+002,5.930679e-003,0.000000e+000,3,9.887629e-001,0.000000e+000,,,,,,,,,,,,,,32,1,4.000000e+000,5.980072e-001,0.000000e+000,0,,0,
1431625217.869,,5.000000e+003,1.508980e+002,5.837602e-003,0.000000e+000,3,9.890508e-001,0.000000e+000,,,,,,,,,,,,,,32,1,4.000000e+000,6.830902e-001,0.000000e+000,0,,0,
1431625265.109,,5.000000e+003,1.539821e+002,5.749069e-003,0.000000e+000,3,9.887620e-001,0.000000e+000,,,,,,,,,,,,,,32,1,4.000000e+000,6.992950e-001,0.000000e+000,0,,0,
1431625309.839,,5.000000e+003,1.568973e+002,5.667672e-003,0.000000e+000,3,9.882607e-001,0.000000e+000,,,,,,,,,,,,,,32,1,4.000000e+000,6.859894e-001,0.000000e+000,0,,0,
1431625357.359,,5.000000e+003,1.598996e+002,5.581765e-003,0.000000e+000,3,9.887931e-001,0.000000e+000,,,,,,,,,,,,,,32,1,4.000000e+000,7.341003e-001,0.000000e+000,0,,0,
1431625402.289,,5.000000e+003,1.629227e+002,5.503563e-003,0.000000e+000,3,9.887778e-001,0.000000e+000,,,,,,,,,,,,,,32,1,4.000000e+000,6.838074e-001,0.000000e+000,0,,0,
1431625446.699,,5.000000e+003,1.658662e+002,5.424635e-003,0.000000e+000,3,9.893767e-001,0.000000e+000,,,,,,,,,,,,,,32,1,4.000000e+000,7.388000e-001,0.000000e+000,0,,0,
1431625494.109,,5.000000e+003,1.689338e+002,5.345119e-003,0.000000e+000,3,9.892333e-001,0.000000e+000,,,,,,,,,,,,,,32,1,4.000000e+000,6.826019e-001,0.000000e+000,0,,0,
1431625538.659,,5.000000e+003,1.718726e+002,5.282710e-003,0.000000e+000,3,9.887722e-001,0.000000e+000,,,,,,,,,,,,,,32,1,4.000000e+000,7.058868e-001,0.000000e+000,0,,0,
1431625585.999,,5.000000e+003,1.748854e+002,5.203006e-003,0.000000e+000,3,9.889941e-001,0.000000e+000,,,,,,,,,,,,,,32,1,4.000000e+000,8.119965e-001,0.000000e+000,0,,0,
1431625629.399,,5.000000e+003,1.778999e+002,5.135755e-003,0.000000e+000,3,9.892499e-001,0.000000e+000,,,,,,,,,,,,,,32,1,4.000000e+000,7.901917e-001,0.000000e+000,0,,0,
1431625673.899,,5.000000e+003,1.807948e+002,5.075941e-003,0.000000e+000,3,9.885052e-001,0.000000e+000,,,,,,,,,,,,,,32,1,4.000000e+000,7.134094e-001,0.000000e+000,0,,0,
1431625721.869,,5.000000e+003,1.838748e+002,5.002262e-003,0.000000e+000,3,9.894555e-001,0.000000e+000,,,,,,,,,,,,,,32,1,4.000000e+000,7.823029e-001,0.000000e+000,0,,0,
1431625767.239,,5.000000e+003,1.867963e+002,4.940619e-003,0.000000e+000,3,9.890388e-001,0.000000e+000,,,,,,,,,,,,,,32,1,4.000000e+000,6.748047e-001,0.000000e+000,0,,0,
1431625815.009,,5.000000e+003,1.898656e+002,4.879029e-003,0.000000e+000,3,9.895482e-001,0.000000e+000,,,,,,,,,,,,,,32,1,4.000000e+000,7.044067e-001,0.000000e+000,0,,0,
1431625859.499,,5.000000e+003,1.927784e+002,4.818821e-003,0.000000e+000,3,9.889571e-001,0.000000e+000,,,,,,,,,,,,,,32,1,4.000000e+000,6.679077e-001,0.000000e+000,0,,0,
1431625905.960,,5.000000e+003,1.958262e+002,4.758078e-003,0.000000e+000,3,9.893879e-001,0.000000e+000,,,,,,,,,,,,,,32,1,4.000000e+000,7.735901e-001,0.000000e+000,0,,0,
1431625951.420,,5.000000e+003,1.987760e+002,4.702090e-003,0.000000e+000,3,9.894083e-001,0.000000e+000,,,,,,,,,,,,,,32,1,4.000000e+000,6.564026e-001,0.000000e+000,0,,0,
1431625997.960,,5.000000e+003,2.017733e+002,4.646517e-003,0.000000e+000,3,9.896067e-001,0.000000e+000,,,,,,,,,,,,,,32,1,4.000000e+000,7.388000e-001,0.000000e+000,0,,0,
1431626043.730,,5.000000e+003,2.047898e+002,4.594088e-003,0.000000e+000,3,9.897388e-001,0.000000e+000,,,,,,,,,,,,,,32,1,4.000000e+000,6.306000e-001,0.000000e+000,0,,0,
1431626089.580,,5.000000e+003,2.077169e+002,4.540037e-003,0.000000e+000,3,9.893695e-001,0.000000e+000,,,,,,,,,,,,,,32,1,4.000000e+000,6.296997e-001,0.000000e+000,0,,0,
1431626135.860,,5.000000e+003,2.107375e+002,4.488409e-003,0.000000e+000,3,9.900751e-001,0.000000e+000,,,,,,,,,,,,,,32,1,4.000000e+000,7.465057e-001,0.000000e+000,0,,0,
1431626182.170,,5.000000e+003,2.137159e+002,4.439117e-003,0.000000e+000,3,9.897553e-001,0.000000e+000,,,,,,,,,,,,,,32,1,4.000000e+000,7.274933e-001,0.000000e+000,0,,0,
1431626228.440,,5.000000e+003,2.167596e+002,4.387324e-003,0.000000e+000,3,9.899050e-001,0.000000e+000,,,,,,,,,,,,,,32,1,4.000000e+000,6.445007e-001,0.000000e+000,0,,0,
1431626273.970,,5.000000e+003,2.197742e+002,4.341152e-003,0.000000e+000,3,9.893413e-001,0.000000e+000,,,,,,,,,,,,,,32,1,4.000000e+000,7.908936e-001,0.000000e+000,0,,0,
1431626317.440,,5.000000e+003,2.227480e+002,4.295251e-003,0.000000e+000,3,9.892204e-001,0.000000e+000,,,,,,,,,,,,,,32,1,4.000000e+000,8.235016e-001,0.000000e+000,0,,0,
1431626361.820,,5.000000e+003,2.257072e+002,4.249352e-003,0.000000e+000,3,9.896646e-001,0.000000e+000,,,,,,,,,,,,,,32,1,4.000000e+000,5.975952e-001,0.000000e+000,0,,0,
1431626409.660,,5.000000e+003,2.286543e+002,4.209890e-003,0.000000e+000,3,9.892353e-001,0.000000e+000,,,,,,,,,,,,,,32,1,4.000000e+000,6.363983e-001,0.000000e+000,0,,0,
1431626456.620,,5.000000e+003,2.316559e+002,4.159505e-003,0.000000e+000,3,9.899793e-001,0.000000e+000,,,,,,,,,,,,,,32,1,4.000000e+000,7.246094e-001,0.000000e+000,0,,0,
1431626503.180,,5.000000e+003,2.346671e+002,4.111019e-003,0.000000e+000,3,9.905483e-001,0.000000e+000,,,,,,,,,,,,,,32,1,4.000000e+000,6.459961e-001,0.000000e+000,0,,0,
1431626548.190,,5.000000e+003,2.376421e+002,4.075401e-003,0.000000e+000,3,9.899702e-001,0.000000e+000,,,,,,,,,,,,,,32,1,4.000000e+000,6.125031e-001,0.000000e+000,0,,0,
1431626595.021,,5.000000e+003,2.406709e+002,4.035515e-003,0.000000e+000,3,9.895174e-001,0.000000e+000,,,,,,,,,,,,,,32,1,4.000000e+000,6.091003e-001,0.000000e+000,0,,0,
1431626639.451,,5.000000e+003,2.435939e+002,3.997297e-003,0.000000e+000,3,9.897390e-001,0.000000e+000,,,,,,,,,,,,,,32,1,4.000000e+000,6.961975e-001,0.000000e+000,0,,0,
1431626682.511,,5.000000e+003,2.465482e+002,3.961290e-003,0.000000e+000,3,9.899751e-001,0.000000e+000,,,,,,,,,,,,,,32,1,4.000000e+000,6.793976e-001,0.000000e+000,0,,0,
1431626728.901,,5.000000e+003,2.495990e+002,3.919609e-003,0.000000e+000,3,9.898458e-001,0.000000e+000,,,,,,,,,,,,,,32,1,4.000000e+000,7.377014e-001,0.000000e+000,0,,0,
1431626775.511,,5.000000e+003,2.526306e+002,3.881445e-003,0.000000e+000,3,9.900696e-001,0.000000e+000,,,,,,,,,,,,,,32,1,4.000000e+000,6.919861e-001,0.000000e+000,0,,0,
1431626823.091,,5.000000e+003,2.555557e+002,3.844915e-003,0.000000e+000,3,9.902577e-001,0.000000e+000,,,,,,,,,,,,,,32,1,4.000000e+000,6.286011e-001,0.000000e+000,0,,0,
1431626870.671,,5.000000e+003,2.585123e+002,3.809681e-003,0.000000e+000,3,9.905781e-001,0.000000e+000,,,,,,,,,,,,,,32,1,4.000000e+000,6.653137e-001,0.000000e+000,0,,0,
1431626914.801,,5.000000e+003,2.616401e+002,3.776799e-003,0.000000e+000,3,9.901927e-001,0.000000e+000,,,,,,,,,,,,,,32,1,4.000000e+000,8.633118e-001,0.000000e+000,0,,0,
1431626955.581,,5.000000e+003,2.646578e+002,3.738859e-003,0.000000e+000,3,9.904921e-001,0.000000e+000,,,,,,,,,,,,,,32,1,4.000000e+000,8.382874e-001,0.000000e+000,0,,0,
1431626995.111,,5.000000e+003,2.675638e+002,3.705509e-003,0.000000e+000,3,9.909056e-001,0.000000e+000,,,,,,,,,,,,,,32,1,4.000000e+000,6.836243e-001,0.000000e+000,0,,0,
1431627039.501,,5.000000e+003,2.704955e+002,3.674407e-003,0.000000e+000,3,9.900979e-001,0.000000e+000,,,,,,,,,,,,,,32,1,4.000000e+000,6.755066e-001,0.000000e+000,0,,0,
1431627085.311,,5.000000e+003,2.734521e+002,3.637683e-003,0.000000e+000,3,9.908051e-001,0.000000e+000,,,,,,,,,,,,,,32,1,4.000000e+000,7.083130e-001,0.000000e+000,0,,0,
1431627132.941,,5.000000e+003,2.764797e+002,3.602351e-003,0.000000e+000,3,9.913397e-001,0.000000e+000,,,,,,,,,,,,,,32,1,4.000000e+000,7.594910e-001,0.000000e+000,0,,0,
1431627179.041,,5.000000e+003,2.795236e+002,3.576603e-003,0.000000e+000,3,9.906188e-001,0.000000e+000,,,,,,,,,,,,,,32,1,4.000000e+000,7.164917e-001,0.000000e+000,0,,0,
1431627224.341,,5.000000e+003,2.825200e+002,3.545612e-003,0.000000e+000,3,9.904317e-001,0.000000e+000,,,,,,,,,,,,,,32,1,4.000000e+000,6.975098e-001,0.000000e+000,0,,0,
1431627270.121,,5.000000e+003,2.854905e+002,3.518067e-003,0.000000e+000,3,9.906055e-001,0.000000e+000,,,,,,,,,,,,,,32,1,4.000000e+000,8.504028e-001,0.000000e+000,0,,0,
1431627316.012,,5.000000e+003,2.885051e+002,3.485304e-003,0.000000e+000,3,9.907006e-001,0.000000e+000,,,,,,,,,,,,,,32,1,4.000000e+000,6.452942e-001,0.000000e+000,0,,0,
1431627361.602,,5.000000e+003,2.914359e+002,3.456508e-003,0.000000e+000,3,9.909071e-001,0.000000e+000,,,,,,,,,,,,,,32,1,4.000000e+000,6.786194e-001,0.000000e+000,0,,0,
1431627407.362,,5.000000e+003,2.943726e+002,3.431520e-003,0.000000e+000,3,9.896271e-001,0.000000e+000,,,,,,,,,,,,,,32,1,4.000000e+000,6.347046e-001,0.000000e+000,0,,0,
1431627455.262,,5.000000e+003,2.973706e+002,3.394628e-003,0.000000e+000,3,9.914537e-001,0.000000e+000,,,,,,,,,,,,,,32,1,4.000000e+000,5.836182e-001,0.000000e+000,0,,0,
1431627735.952,,5.000000e+003,3.000089e+002,3.363721e-003,0.000000e+000,3,9.902932e-001,0.000000e+000,,,,,,,,,,,,,,32,1,4.000000e+000,3.051758e-002,0.000000e+000,0,,0,