File: RE3Sb3A2O14/Data/Nd3Sb3Zn2O14 MT 5000 oe.dc.dat
[Header]
TITLE,MPMS DC Measurement
BYAPP,MPMS Measurement,2.1,Summary
FILEOPENTIME, 1434039272.954000 6/11/2015, 12:14:32 PM

INFO, APPNAME, MPMS MultiVu Application, Revision 1.60,  Build 081

INFO, NAME, Nd3Sb3Zn2O14
INFO, WEIGHT, 77.700
INFO, AREA, 1.000
INFO, LENGTH, 1.000
INFO, SHAPE, 0
INFO, COMMENT,
INFO, SEQUENCE FILE: MT up.seq_5 to 300_quick.seq


INFO, BACKGROUND DATA FILE:, None


STARTUPAXIS,X,4,LINEAR,AUTO,0.000000,0.000000
STARTUPAXIS,Y1,5,LINEAR,AUTO,0.000000,0.000000


STARTUPGROUP,Longitudinal
FIELDGROUP,Longitudinal,1,2,3,4,5,6,7,8,9,15,16,17,18,27,28
FIELDGROUP,Transverse,1,2,3,4,10,11,12,13,14,19,20,21,22,27,28

PLOT_APPEARANCE,ALL,HORZ_GRID_ON,VERT_GRID_ON,MARKERS_AND_LINES

[Data]
Time,Comment,Field (Oe),Temperature (K),Long Moment (emu),Long Scan Std Dev,Long Algorithm,Long Reg Fit,Long Percent Error (%),Trans Moment (emu),Trans Scan Std Dev,Trans Algorithm,Trans Reg Fit,Trans Percent Error (%),Long Moment [w/o ABS] (emu),Long Scan Std Dev [w/o ABS],Long Reg Fit [w/o ABS],Long Percent Error [w/o ABS] (%),Trans Moment [w/o ABS] (emu),Trans Scan Std Dev [w/o ABS],Trans Reg Fit [w/o ABS],Trans Percent Error [w/o ABS] (%),Points per Scan,Scans per Measurement,Scan Length (cm),Delta Temp (K),Rot Position (deg),Error,EC Comp. Running,Using ABS,
1434039272.954,,5.000000e+003,1.779681e+000,3.569214e-001,1.258273e-003,3,9.939506e-001,3.525350e-001,,,,,,,,,,,,,,32,2,4.000000e+000,6.774068e-003,0.000000e+000,0,,0,
1434039459.894,,5.000000e+003,2.757407e+000,2.312940e-001,2.657759e-002,3,9.903624e-001,1.149082e+001,,,,,,,,,,,,,,32,2,4.000000e+000,8.497341e-001,0.000000e+000,0,,0,
1434039566.974,,5.000000e+003,3.686408e+000,1.752554e-001,1.671869e-002,3,9.922294e-001,9.539610e+000,,,,,,,,,,,,,,32,2,4.000000e+000,9.539292e-001,0.000000e+000,0,,0,
1434039694.145,,5.000000e+003,5.033805e+000,1.279984e-001,1.438029e-003,3,9.942792e-001,1.123474e+000,,,,,,,,,,,,,,32,2,4.000000e+000,1.665769e-001,0.000000e+000,0,,0,
1434039719.215,,5.000000e+003,5.245470e+000,1.236215e-001,1.618197e-003,3,9.941078e-001,1.308992e+000,,,,,,,,,,,,,,32,2,4.000000e+000,1.956649e-001,0.000000e+000,0,,0,
1434039744.015,,5.000000e+003,5.455735e+000,1.189977e-001,1.586650e-003,3,9.941518e-001,1.333345e+000,,,,,,,,,,,,,,32,2,4.000000e+000,2.011781e-001,0.000000e+000,0,,0,
1434039768.255,,5.000000e+003,5.661841e+000,1.148326e-001,1.415512e-003,3,9.939946e-001,1.232675e+000,,,,,,,,,,,,,,32,2,4.000000e+000,1.966009e-001,0.000000e+000,0,,0,
1434039792.655,,5.000000e+003,5.862118e+000,1.111213e-001,1.251962e-003,3,9.940689e-001,1.126662e+000,,,,,,,,,,,,,,32,2,4.000000e+000,1.704488e-001,0.000000e+000,0,,0,
1434039817.055,,5.000000e+003,6.052875e+000,1.077227e-001,1.110685e-003,3,9.939317e-001,1.031060e+000,,,,,,,,,,,,,,32,2,4.000000e+000,1.914010e-001,0.000000e+000,0,,0,
1434039865.405,,5.000000e+003,6.437078e+000,1.014209e-001,1.123324e-003,3,9.938282e-001,1.107586e+000,,,,,,,,,,,,,,32,2,4.000000e+000,1.947913e-001,0.000000e+000,0,,0,
1434039930.825,,5.000000e+003,6.966705e+000,9.391840e-002,1.370552e-003,3,9.937038e-001,1.459301e+000,,,,,,,,,,,,,,32,2,4.000000e+000,2.648277e-001,0.000000e+000,0,,0,
1434039986.195,,5.000000e+003,7.448601e+000,8.803753e-002,8.390911e-004,3,9.941610e-001,9.531061e-001,,,,,,,,,,,,,,32,2,4.000000e+000,1.943197e-001,0.000000e+000,0,,0,
1434040047.445,,5.000000e+003,7.955507e+000,8.258039e-002,7.959380e-004,3,9.936821e-001,9.638341e-001,,,,,,,,,,,,,,32,2,4.000000e+000,1.974421e-001,0.000000e+000,0,,0,
1434040110.235,,5.000000e+003,8.457378e+000,7.786620e-002,6.697713e-004,3,9.938369e-001,8.601567e-001,,,,,,,,,,,,,,32,2,4.000000e+000,1.855087e-001,0.000000e+000,0,,0,
1434040172.645,,5.000000e+003,8.952782e+000,7.368422e-002,5.661849e-004,3,9.939281e-001,7.683938e-001,,,,,,,,,,,,,,32,2,4.000000e+000,1.846581e-001,0.000000e+000,0,,0,
1434040246.905,,5.000000e+003,9.569382e+000,6.916846e-002,4.653223e-004,3,9.940493e-001,6.727377e-001,,,,,,,,,,,,,,32,2,4.000000e+000,1.784182e-001,0.000000e+000,0,,0,
1434040297.665,,5.000000e+003,9.961809e+000,6.655994e-002,4.213842e-004,3,9.938613e-001,6.330898e-001,,,,,,,,,,,,,,32,2,4.000000e+000,1.867886e-001,0.000000e+000,0,,0,
1434040361.925,,5.000000e+003,1.047511e+001,6.342515e-002,4.624036e-004,3,9.939615e-001,7.290541e-001,,,,,,,,,,,,,,32,2,4.000000e+000,1.853294e-001,0.000000e+000,0,,0,
1434040426.146,,5.000000e+003,1.097901e+001,6.061193e-002,4.013460e-004,3,9.940706e-001,6.621568e-001,,,,,,,,,,,,,,32,2,4.000000e+000,1.744394e-001,0.000000e+000,0,,0,
1434040489.356,,5.000000e+003,1.148586e+001,5.803958e-002,3.935752e-004,3,9.936173e-001,6.781152e-001,,,,,,,,,,,,,,32,2,4.000000e+000,2.009401e-001,0.000000e+000,0,,0,
1434040550.256,,5.000000e+003,1.197391e+001,5.579390e-002,3.169101e-004,3,9.940569e-001,5.680013e-001,,,,,,,,,,,,,,32,2,4.000000e+000,1.778898e-001,0.000000e+000,0,,0,
1434040615.986,,5.000000e+003,1.250277e+001,5.344689e-002,2.501705e-004,3,9.940236e-001,4.680731e-001,,,,,,,,,,,,,,32,2,4.000000e+000,1.741304e-001,0.000000e+000,0,,0,
1434040677.076,,5.000000e+003,1.299644e+001,5.160025e-002,2.478656e-004,3,9.938632e-001,4.803574e-001,,,,,,,,,,,,,,32,2,4.000000e+000,1.782703e-001,0.000000e+000,0,,0,
1434040739.886,,5.000000e+003,1.349527e+001,4.987810e-002,2.389858e-004,3,9.938768e-001,4.791397e-001,,,,,,,,,,,,,,32,2,4.000000e+000,1.774502e-001,0.000000e+000,0,,0,
1434040807.646,,5.000000e+003,1.400709e+001,4.825464e-002,2.489772e-004,3,9.941106e-001,5.159653e-001,,,,,,,,,,,,,,32,2,4.000000e+000,1.917000e-001,0.000000e+000,0,,0,
1434040871.086,,5.000000e+003,1.450603e+001,4.673960e-002,2.416858e-004,3,9.936795e-001,5.170901e-001,,,,,,,,,,,,,,32,2,4.000000e+000,1.842699e-001,0.000000e+000,0,,0,
1434040935.646,,5.000000e+003,1.501515e+001,4.530877e-002,2.183786e-004,3,9.935603e-001,4.819788e-001,,,,,,,,,,,,,,32,2,4.000000e+000,1.822701e-001,0.000000e+000,0,,0,
1434040997.876,,5.000000e+003,1.552256e+001,4.399198e-002,1.814000e-004,3,9.938487e-001,4.123480e-001,,,,,,,,,,,,,,32,2,4.000000e+000,1.823502e-001,0.000000e+000,0,,0,
1434041059.456,,5.000000e+003,1.601398e+001,4.279074e-002,1.920895e-004,3,9.936168e-001,4.489044e-001,,,,,,,,,,,,,,32,2,4.000000e+000,1.882305e-001,0.000000e+000,0,,0,
1434041121.396,,5.000000e+003,1.652247e+001,4.160612e-002,1.807863e-004,3,9.936081e-001,4.345185e-001,,,,,,,,,,,,,,32,2,4.000000e+000,1.808014e-001,0.000000e+000,0,,0,
1434041182.227,,5.000000e+003,1.702726e+001,4.052724e-002,1.785024e-004,3,9.937166e-001,4.404505e-001,,,,,,,,,,,,,,32,2,4.000000e+000,1.944294e-001,0.000000e+000,0,,0,
1434041245.127,,5.000000e+003,1.753924e+001,3.947272e-002,1.676602e-004,3,9.937574e-001,4.247495e-001,,,,,,,,,,,,,,32,2,4.000000e+000,1.986904e-001,0.000000e+000,0,,0,
1434041308.117,,5.000000e+003,1.804725e+001,3.849702e-002,1.473770e-004,3,9.935356e-001,3.828270e-001,,,,,,,,,,,,,,32,2,4.000000e+000,2.083092e-001,0.000000e+000,0,,0,
1434041369.327,,5.000000e+003,1.853922e+001,3.760734e-002,1.500928e-004,3,9.936731e-001,3.991051e-001,,,,,,,,,,,,,,32,2,4.000000e+000,1.928806e-001,0.000000e+000,0,,0,
1434041431.397,,5.000000e+003,1.903776e+001,3.674093e-002,1.296806e-004,3,9.938381e-001,3.529595e-001,,,,,,,,,,,,,,32,2,4.000000e+000,1.883507e-001,0.000000e+000,0,,0,
1434041494.907,,5.000000e+003,1.955405e+001,3.590271e-002,1.212855e-004,3,9.937047e-001,3.378170e-001,,,,,,,,,,,,,,32,2,4.000000e+000,1.876812e-001,0.000000e+000,0,,0,
1434041557.877,,5.000000e+003,2.005185e+001,3.512946e-002,1.386447e-004,3,9.937166e-001,3.946679e-001,,,,,,,,,,,,,,32,2,4.000000e+000,1.937599e-001,0.000000e+000,0,,0,
1434041625.917,,5.000000e+003,2.057706e+001,3.437883e-002,1.478195e-004,3,9.936710e-001,4.299726e-001,,,,,,,,,,,,,,32,2,4.000000e+000,2.093086e-001,0.000000e+000,0,,0,
1434041683.327,,5.000000e+003,2.106928e+001,3.368449e-002,1.189885e-004,3,9.937192e-001,3.532440e-001,,,,,,,,,,,,,,32,2,4.000000e+000,1.905899e-001,0.000000e+000,0,,0,
1434041743.917,,5.000000e+003,2.156393e+001,3.302483e-002,1.230635e-004,3,9.934750e-001,3.726394e-001,,,,,,,,,,,,,,32,2,4.000000e+000,1.909103e-001,0.000000e+000,0,,0,
1434041810.307,,5.000000e+003,2.207689e+001,3.238006e-002,1.069713e-004,3,9.937177e-001,3.303618e-001,,,,,,,,,,,,,,32,2,4.000000e+000,1.986599e-001,0.000000e+000,0,,0,
1434041866.268,,5.000000e+003,2.257669e+001,3.175069e-002,1.206901e-004,3,9.938348e-001,3.801182e-001,,,,,,,,,,,,,,32,2,4.000000e+000,1.944904e-001,0.000000e+000,0,,0,
1434041929.208,,5.000000e+003,2.308052e+001,3.117663e-002,1.075061e-004,3,9.938465e-001,3.448290e-001,,,,,,,,,,,,,,32,2,4.000000e+000,1.826801e-001,0.000000e+000,0,,0,
1434041993.958,,5.000000e+003,2.358361e+001,3.060747e-002,8.729798e-005,3,9.937934e-001,2.852179e-001,,,,,,,,,,,,,,32,2,4.000000e+000,1.836815e-001,0.000000e+000,0,,0,
1434042058.078,,5.000000e+003,2.409551e+001,3.005481e-002,7.446031e-005,3,9.939579e-001,2.477484e-001,,,,,,,,,,,,,,32,2,4.000000e+000,1.996403e-001,0.000000e+000,0,,0,
1434042144.288,,5.000000e+003,2.478734e+001,2.932041e-002,5.801118e-005,3,9.935618e-001,1.978526e-001,,,,,,,,,,,,,,32,2,4.000000e+000,1.922798e-001,0.000000e+000,0,,0,
1434042259.248,,5.000000e+003,2.499081e+001,2.911820e-002,2.283701e-005,3,9.936483e-001,7.842865e-002,,,,,,,,,,,,,,32,2,4.000000e+000,5.319595e-003,0.000000e+000,0,,0,
1434042337.868,,5.000000e+003,2.500013e+001,2.912970e-002,0.000000e+000,3,9.935770e-001,0.000000e+000,,,,,,,,,,,,,,32,1,4.000000e+000,0.000000e+000,0.000000e+000,0,,0,
1434042402.258,,5.000000e+003,2.834339e+001,2.637385e-002,0.000000e+000,3,9.938728e-001,0.000000e+000,,,,,,,,,,,,,,32,1,4.000000e+000,6.943798e-001,0.000000e+000,0,,0,
1434042449.268,,5.000000e+003,3.138316e+001,2.428134e-002,0.000000e+000,3,9.941769e-001,0.000000e+000,,,,,,,,,,,,,,32,1,4.000000e+000,7.703209e-001,0.000000e+000,0,,0,
1434042488.268,,5.000000e+003,3.437992e+001,2.256788e-002,0.000000e+000,3,9.937212e-001,0.000000e+000,,,,,,,,,,,,,,32,1,4.000000e+000,7.623672e-001,0.000000e+000,0,,0,
1434042532.908,,5.000000e+003,3.734095e+001,2.117892e-002,0.000000e+000,3,9.937863e-001,0.000000e+000,,,,,,,,,,,,,,32,1,4.000000e+000,6.942978e-001,0.000000e+000,0,,0,
1434042579.869,,5.000000e+003,4.035687e+001,1.994608e-002,0.000000e+000,3,9.942304e-001,0.000000e+000,,,,,,,,,,,,,,32,1,4.000000e+000,7.205811e-001,0.000000e+000,0,,0,
1434042624.399,,5.000000e+003,4.333118e+001,1.890550e-002,0.000000e+000,3,9.940637e-001,0.000000e+000,,,,,,,,,,,,,,32,1,4.000000e+000,7.089691e-001,0.000000e+000,0,,0,
1434042668.889,,5.000000e+003,4.629266e+001,1.801317e-002,0.000000e+000,3,9.940894e-001,0.000000e+000,,,,,,,,,,,,,,32,1,4.000000e+000,6.000519e-001,0.000000e+000,0,,0,
1434042716.539,,5.000000e+003,4.939345e+001,1.721772e-002,0.000000e+000,3,9.938023e-001,0.000000e+000,,,,,,,,,,,,,,32,1,4.000000e+000,7.283821e-001,0.000000e+000,0,,0,
1434042760.169,,5.000000e+003,5.230566e+001,1.651261e-002,0.000000e+000,3,9.940828e-001,0.000000e+000,,,,,,,,,,,,,,32,1,4.000000e+000,7.538300e-001,0.000000e+000,0,,0,
1434042805.229,,5.000000e+003,5.524664e+001,1.587464e-002,0.000000e+000,3,9.939793e-001,0.000000e+000,,,,,,,,,,,,,,32,1,4.000000e+000,6.519279e-001,0.000000e+000,0,,0,
1434042853.119,,5.000000e+003,5.828762e+001,1.528188e-002,0.000000e+000,3,9.938094e-001,0.000000e+000,,,,,,,,,,,,,,32,1,4.000000e+000,6.816483e-001,0.000000e+000,0,,0,
1434042911.319,,5.000000e+003,6.206486e+001,1.457159e-002,0.000000e+000,3,9.937663e-001,0.000000e+000,,,,,,,,,,,,,,32,1,4.000000e+000,6.874504e-001,0.000000e+000,0,,0,
1434042944.199,,5.000000e+003,6.419468e+001,1.423439e-002,0.000000e+000,3,9.938850e-001,0.000000e+000,,,,,,,,,,,,,,32,1,4.000000e+000,6.404915e-001,0.000000e+000,0,,0,
1434042990.309,,5.000000e+003,6.730304e+001,1.376317e-002,0.000000e+000,3,9.937940e-001,0.000000e+000,,,,,,,,,,,,,,32,1,4.000000e+000,7.677078e-001,0.000000e+000,0,,0,
1434043037.009,,5.000000e+003,7.034663e+001,1.332763e-002,0.000000e+000,3,9.941011e-001,0.000000e+000,,,,,,,,,,,,,,32,1,4.000000e+000,7.477951e-001,0.000000e+000,0,,0,
1434043081.749,,5.000000e+003,7.327705e+001,1.294457e-002,0.000000e+000,3,9.942293e-001,0.000000e+000,,,,,,,,,,,,,,32,1,4.000000e+000,7.464752e-001,0.000000e+000,0,,0,
1434043125.869,,5.000000e+003,7.621536e+001,1.258185e-002,0.000000e+000,3,9.941046e-001,0.000000e+000,,,,,,,,,,,,,,32,1,4.000000e+000,7.179794e-001,0.000000e+000,0,,0,
1434043169.679,,5.000000e+003,7.923495e+001,1.223824e-002,0.000000e+000,3,9.939744e-001,0.000000e+000,,,,,,,,,,,,,,32,1,4.000000e+000,7.477798e-001,0.000000e+000,0,,0,
1434043213.719,,5.000000e+003,8.229855e+001,1.191748e-002,0.000000e+000,3,9.936969e-001,0.000000e+000,,,,,,,,,,,,,,32,1,4.000000e+000,7.164917e-001,0.000000e+000,0,,0,
1434043256.609,,5.000000e+003,8.528938e+001,1.160311e-002,0.000000e+000,3,9.938391e-001,0.000000e+000,,,,,,,,,,,,,,32,1,4.000000e+000,7.447357e-001,0.000000e+000,0,,0,
1434043300.330,,5.000000e+003,8.817900e+001,1.131591e-002,0.000000e+000,3,9.941228e-001,0.000000e+000,,,,,,,,,,,,,,32,1,4.000000e+000,7.530212e-001,0.000000e+000,0,,0,
1434043345.410,,5.000000e+003,9.115530e+001,1.104445e-002,0.000000e+000,3,9.935530e-001,0.000000e+000,,,,,,,,,,,,,,32,1,4.000000e+000,6.582336e-001,0.000000e+000,0,,0,
1434043392.360,,5.000000e+003,9.420235e+001,1.078494e-002,0.000000e+000,3,9.937635e-001,0.000000e+000,,,,,,,,,,,,,,32,1,4.000000e+000,5.758209e-001,0.000000e+000,0,,0,
1434043438.250,,5.000000e+003,9.713169e+001,1.054712e-002,0.000000e+000,3,9.937718e-001,0.000000e+000,,,,,,,,,,,,,,32,1,4.000000e+000,6.410980e-001,0.000000e+000,0,,0,
1434043484.050,,5.000000e+003,1.001238e+002,1.032108e-002,0.000000e+000,3,9.937138e-001,0.000000e+000,,,,,,,,,,,,,,32,1,4.000000e+000,7.021027e-001,0.000000e+000,0,,0,
1434043530.020,,5.000000e+003,1.031425e+002,1.009599e-002,0.000000e+000,3,9.939733e-001,0.000000e+000,,,,,,,,,,,,,,32,1,4.000000e+000,7.516022e-001,0.000000e+000,0,,0,
1434043573.830,,5.000000e+003,1.060829e+002,9.895238e-003,0.000000e+000,3,9.939048e-001,0.000000e+000,,,,,,,,,,,,,,32,1,4.000000e+000,7.066040e-001,0.000000e+000,0,,0,
1434043620.850,,5.000000e+003,1.092129e+002,9.683129e-003,0.000000e+000,3,9.938869e-001,0.000000e+000,,,,,,,,,,,,,,32,1,4.000000e+000,6.390991e-001,0.000000e+000,0,,0,
1434043664.900,,5.000000e+003,1.121251e+002,9.497231e-003,0.000000e+000,3,9.939948e-001,0.000000e+000,,,,,,,,,,,,,,32,1,4.000000e+000,7.751999e-001,0.000000e+000,0,,0,
1434043708.410,,5.000000e+003,1.150334e+002,9.319454e-003,0.000000e+000,3,9.940503e-001,0.000000e+000,,,,,,,,,,,,,,32,1,4.000000e+000,6.856995e-001,0.000000e+000,0,,0,
1434043753.260,,5.000000e+003,1.180248e+002,9.148001e-003,0.000000e+000,3,9.940451e-001,0.000000e+000,,,,,,,,,,,,,,32,1,4.000000e+000,6.968994e-001,0.000000e+000,0,,0,
1434043799.180,,5.000000e+003,1.210706e+002,8.973453e-003,0.000000e+000,3,9.939514e-001,0.000000e+000,,,,,,,,,,,,,,32,1,4.000000e+000,6.460037e-001,0.000000e+000,0,,0,
1434043847.990,,5.000000e+003,1.240844e+002,8.810889e-003,0.000000e+000,3,9.943830e-001,0.000000e+000,,,,,,,,,,,,,,32,1,4.000000e+000,6.766968e-001,0.000000e+000,0,,0,
1434043893.640,,5.000000e+003,1.269863e+002,8.661038e-003,0.000000e+000,3,9.938159e-001,0.000000e+000,,,,,,,,,,,,,,32,1,4.000000e+000,6.343994e-001,0.000000e+000,0,,0,
1434043940.520,,5.000000e+003,1.299788e+002,8.513775e-003,0.000000e+000,3,9.939685e-001,0.000000e+000,,,,,,,,,,,,,,32,1,4.000000e+000,7.145996e-001,0.000000e+000,0,,0,
1434043988.010,,5.000000e+003,1.330767e+002,8.377628e-003,0.000000e+000,3,9.936296e-001,0.000000e+000,,,,,,,,,,,,,,32,1,4.000000e+000,7.100067e-001,0.000000e+000,0,,0,
1434044034.561,,5.000000e+003,1.359716e+002,8.229005e-003,0.000000e+000,3,9.941686e-001,0.000000e+000,,,,,,,,,,,,,,32,1,4.000000e+000,6.754913e-001,0.000000e+000,0,,0,
1434044082.261,,5.000000e+003,1.390362e+002,8.094350e-003,0.000000e+000,3,9.940957e-001,0.000000e+000,,,,,,,,,,,,,,32,1,4.000000e+000,6.775970e-001,0.000000e+000,0,,0,
1434044128.151,,5.000000e+003,1.419592e+002,7.967082e-003,0.000000e+000,3,9.943514e-001,0.000000e+000,,,,,,,,,,,,,,32,1,4.000000e+000,6.816101e-001,0.000000e+000,0,,0,
1434044174.281,,5.000000e+003,1.449500e+002,7.845039e-003,0.000000e+000,3,9.945667e-001,0.000000e+000,,,,,,,,,,,,,,32,1,4.000000e+000,7.660980e-001,0.000000e+000,0,,0,
1434044218.911,,5.000000e+003,1.479357e+002,7.721452e-003,0.000000e+000,3,9.942839e-001,0.000000e+000,,,,,,,,,,,,,,32,1,4.000000e+000,7.221069e-001,0.000000e+000,0,,0,
1434044276.081,,5.000000e+003,1.517614e+002,7.568500e-003,0.000000e+000,3,9.939770e-001,0.000000e+000,,,,,,,,,,,,,,32,1,4.000000e+000,7.164001e-001,0.000000e+000,0,,0,
1434044310.291,,5.000000e+003,1.539854e+002,7.488488e-003,0.000000e+000,3,9.946535e-001,0.000000e+000,,,,,,,,,,,,,,32,1,4.000000e+000,6.672058e-001,0.000000e+000,0,,0,
1434044356.871,,5.000000e+003,1.569059e+002,7.381951e-003,0.000000e+000,3,9.947098e-001,0.000000e+000,,,,,,,,,,,,,,32,1,4.000000e+000,5.974121e-001,0.000000e+000,0,,0,
1434044402.151,,5.000000e+003,1.598537e+002,7.277829e-003,0.000000e+000,3,9.945835e-001,0.000000e+000,,,,,,,,,,,,,,32,1,4.000000e+000,6.362000e-001,0.000000e+000,0,,0,
1434044450.031,,5.000000e+003,1.628958e+002,7.172220e-003,0.000000e+000,3,9.946785e-001,0.000000e+000,,,,,,,,,,,,,,32,1,4.000000e+000,6.717072e-001,0.000000e+000,0,,0,
1434044496.361,,5.000000e+003,1.658873e+002,7.075677e-003,0.000000e+000,3,9.944686e-001,0.000000e+000,,,,,,,,,,,,,,32,1,4.000000e+000,6.650085e-001,0.000000e+000,0,,0,
1434044542.291,,5.000000e+003,1.689046e+002,6.975718e-003,0.000000e+000,3,9.942826e-001,0.000000e+000,,,,,,,,,,,,,,32,1,4.000000e+000,7.077942e-001,0.000000e+000,0,,0,
1434044586.701,,5.000000e+003,1.718058e+002,6.884042e-003,0.000000e+000,3,9.946660e-001,0.000000e+000,,,,,,,,,,,,,,32,1,4.000000e+000,6.591034e-001,0.000000e+000,0,,0,
1434044633.931,,5.000000e+003,1.748908e+002,6.785558e-003,0.000000e+000,3,9.948953e-001,0.000000e+000,,,,,,,,,,,,,,32,1,4.000000e+000,6.823883e-001,0.000000e+000,0,,0,
1434044678.021,,5.000000e+003,1.778559e+002,6.701465e-003,0.000000e+000,3,9.947838e-001,0.000000e+000,,,,,,,,,,,,,,32,1,4.000000e+000,6.134033e-001,0.000000e+000,0,,0,
1434044722.382,,5.000000e+003,1.808003e+002,6.616090e-003,0.000000e+000,3,9.944274e-001,0.000000e+000,,,,,,,,,,,,,,32,1,4.000000e+000,6.478119e-001,0.000000e+000,0,,0,
1434044768.712,,5.000000e+003,1.837486e+002,6.532340e-003,0.000000e+000,3,9.948434e-001,0.000000e+000,,,,,,,,,,,,,,32,1,4.000000e+000,6.308899e-001,0.000000e+000,0,,0,
1434044816.852,,5.000000e+003,1.867939e+002,6.448482e-003,0.000000e+000,3,9.944171e-001,0.000000e+000,,,,,,,,,,,,,,32,1,4.000000e+000,6.824951e-001,0.000000e+000,0,,0,
1434044863.652,,5.000000e+003,1.898668e+002,6.370392e-003,0.000000e+000,3,9.946269e-001,0.000000e+000,,,,,,,,,,,,,,32,1,4.000000e+000,6.244049e-001,0.000000e+000,0,,0,
1434044910.972,,5.000000e+003,1.927960e+002,6.298057e-003,0.000000e+000,3,9.944772e-001,0.000000e+000,,,,,,,,,,,,,,32,1,4.000000e+000,7.010040e-001,0.000000e+000,0,,0,
1434044960.142,,5.000000e+003,1.958014e+002,6.206226e-003,0.000000e+000,3,9.951416e-001,0.000000e+000,,,,,,,,,,,,,,32,1,4.000000e+000,6.544037e-001,0.000000e+000,0,,0,
1434045005.442,,5.000000e+003,1.987374e+002,6.155789e-003,0.000000e+000,3,9.948930e-001,0.000000e+000,,,,,,,,,,,,,,32,1,4.000000e+000,6.824036e-001,0.000000e+000,0,,0,
1434045052.592,,5.000000e+003,2.017737e+002,6.076043e-003,0.000000e+000,3,9.949987e-001,0.000000e+000,,,,,,,,,,,,,,32,1,4.000000e+000,6.666870e-001,0.000000e+000,0,,0,
1434045099.692,,5.000000e+003,2.048414e+002,6.003585e-003,0.000000e+000,3,9.951632e-001,0.000000e+000,,,,,,,,,,,,,,32,1,4.000000e+000,8.258057e-001,0.000000e+000,0,,0,
1434045139.892,,5.000000e+003,2.078029e+002,5.939192e-003,0.000000e+000,3,9.954051e-001,0.000000e+000,,,,,,,,,,,,,,32,1,4.000000e+000,6.875000e-001,0.000000e+000,0,,0,
1434045182.382,,5.000000e+003,2.107518e+002,5.869549e-003,0.000000e+000,3,9.949965e-001,0.000000e+000,,,,,,,,,,,,,,32,1,4.000000e+000,7.366943e-001,0.000000e+000,0,,0,
1434045225.592,,5.000000e+003,2.136801e+002,5.807666e-003,0.000000e+000,3,9.950181e-001,0.000000e+000,,,,,,,,,,,,,,32,1,4.000000e+000,7.170105e-001,0.000000e+000,0,,0,
1434045271.952,,5.000000e+003,2.167173e+002,5.741798e-003,0.000000e+000,3,9.955111e-001,0.000000e+000,,,,,,,,,,,,,,32,1,4.000000e+000,6.649017e-001,0.000000e+000,0,,0,
1434045319.362,,5.000000e+003,2.197197e+002,5.678720e-003,0.000000e+000,3,9.955605e-001,0.000000e+000,,,,,,,,,,,,,,32,1,4.000000e+000,7.048950e-001,0.000000e+000,0,,0,
1434045365.002,,5.000000e+003,2.226859e+002,5.616687e-003,0.000000e+000,3,9.951971e-001,0.000000e+000,,,,,,,,,,,,,,32,1,4.000000e+000,6.802979e-001,0.000000e+000,0,,0,
1434045411.632,,5.000000e+003,2.256661e+002,5.559951e-003,0.000000e+000,3,9.955797e-001,0.000000e+000,,,,,,,,,,,,,,32,1,4.000000e+000,6.085968e-001,0.000000e+000,0,,0,
1434045459.773,,5.000000e+003,2.287044e+002,5.499902e-003,0.000000e+000,3,9.957011e-001,0.000000e+000,,,,,,,,,,,,,,32,1,4.000000e+000,6.483002e-001,0.000000e+000,0,,0,
1434045506.593,,5.000000e+003,2.316833e+002,5.446577e-003,0.000000e+000,3,9.957426e-001,0.000000e+000,,,,,,,,,,,,,,32,1,4.000000e+000,6.653137e-001,0.000000e+000,0,,0,
1434045552.143,,5.000000e+003,2.346402e+002,5.404561e-003,0.000000e+000,3,9.955501e-001,0.000000e+000,,,,,,,,,,,,,,32,1,4.000000e+000,6.459045e-001,0.000000e+000,0,,0,
1434045598.313,,5.000000e+003,2.376205e+002,5.333824e-003,0.000000e+000,3,9.961138e-001,0.000000e+000,,,,,,,,,,,,,,32,1,4.000000e+000,6.499023e-001,0.000000e+000,0,,0,
1434045645.263,,5.000000e+003,2.406421e+002,5.287730e-003,0.000000e+000,3,9.958627e-001,0.000000e+000,,,,,,,,,,,,,,32,1,4.000000e+000,6.089020e-001,0.000000e+000,0,,0,
1434045692.553,,5.000000e+003,2.436659e+002,5.234248e-003,0.000000e+000,3,9.964541e-001,0.000000e+000,,,,,,,,,,,,,,32,1,4.000000e+000,6.898041e-001,0.000000e+000,0,,0,
1434045736.623,,5.000000e+003,2.466553e+002,5.180548e-003,0.000000e+000,3,9.957437e-001,0.000000e+000,,,,,,,,,,,,,,32,1,4.000000e+000,6.867065e-001,0.000000e+000,0,,0,
1434045780.693,,5.000000e+003,2.495741e+002,5.111518e-003,0.000000e+000,3,9.948821e-001,0.000000e+000,,,,,,,,,,,,,,32,1,4.000000e+000,6.684875e-001,0.000000e+000,0,,0,
1434045827.283,,5.000000e+003,2.526190e+002,5.085873e-003,0.000000e+000,3,9.951522e-001,0.000000e+000,,,,,,,,,,,,,,32,1,4.000000e+000,7.341919e-001,0.000000e+000,0,,0,
1434045868.613,,5.000000e+003,2.556087e+002,5.030443e-003,0.000000e+000,3,9.950159e-001,0.000000e+000,,,,,,,,,,,,,,32,1,4.000000e+000,7.299957e-001,0.000000e+000,0,,0,
1434045911.303,,5.000000e+003,2.585551e+002,4.969248e-003,0.000000e+000,3,9.942337e-001,0.000000e+000,,,,,,,,,,,,,,32,1,4.000000e+000,6.876831e-001,0.000000e+000,0,,0,
1434045956.273,,5.000000e+003,2.614525e+002,4.911616e-003,0.000000e+000,3,9.940955e-001,0.000000e+000,,,,,,,,,,,,,,32,1,4.000000e+000,6.201172e-001,0.000000e+000,0,,0,
1434046005.113,,5.000000e+003,2.644886e+002,4.878751e-003,0.000000e+000,3,9.958833e-001,0.000000e+000,,,,,,,,,,,,,,32,1,4.000000e+000,6.665039e-001,0.000000e+000,0,,0,
1434046051.683,,5.000000e+003,2.674501e+002,4.838367e-003,0.000000e+000,3,9.964113e-001,0.000000e+000,,,,,,,,,,,,,,32,1,4.000000e+000,6.272888e-001,0.000000e+000,0,,0,
1434046100.313,,5.000000e+003,2.705009e+002,4.788403e-003,0.000000e+000,3,9.966362e-001,0.000000e+000,,,,,,,,,,,,,,32,1,4.000000e+000,6.348877e-001,0.000000e+000,0,,0,
1434046145.724,,5.000000e+003,2.734782e+002,4.754644e-003,0.000000e+000,3,9.966471e-001,0.000000e+000,,,,,,,,,,,,,,32,1,4.000000e+000,6.584167e-001,0.000000e+000,0,,0,
1434046192.724,,5.000000e+003,2.765402e+002,4.712758e-003,0.000000e+000,3,9.961548e-001,0.000000e+000,,,,,,,,,,,,,,32,1,4.000000e+000,7.084961e-001,0.000000e+000,0,,0,
1434046238.224,,5.000000e+003,2.794455e+002,4.672871e-003,0.000000e+000,3,9.966939e-001,0.000000e+000,,,,,,,,,,,,,,32,1,4.000000e+000,7.160034e-001,0.000000e+000,0,,0,
1434046286.354,,5.000000e+003,2.824890e+002,4.631680e-003,0.000000e+000,3,9.965295e-001,0.000000e+000,,,,,,,,,,,,,,32,1,4.000000e+000,7.597046e-001,0.000000e+000,0,,0,
1434046333.394,,5.000000e+003,2.854537e+002,4.600203e-003,0.000000e+000,3,9.961784e-001,0.000000e+000,,,,,,,,,,,,,,32,1,4.000000e+000,6.673279e-001,0.000000e+000,0,,0,
1434046381.814,,5.000000e+003,2.885142e+002,4.542576e-003,0.000000e+000,3,9.968949e-001,0.000000e+000,,,,,,,,,,,,,,32,1,4.000000e+000,5.704956e-001,0.000000e+000,0,,0,
1434046427.414,,5.000000e+003,2.914261e+002,4.514345e-003,0.000000e+000,3,9.962503e-001,0.000000e+000,,,,,,,,,,,,,,32,1,4.000000e+000,7.740173e-001,0.000000e+000,0,,0,
1434046471.124,,5.000000e+003,2.943622e+002,4.476377e-003,0.000000e+000,3,9.963995e-001,0.000000e+000,,,,,,,,,,,,,,32,1,4.000000e+000,6.541138e-001,0.000000e+000,0,,0,
1434046517.994,,5.000000e+003,2.973798e+002,4.438668e-003,0.000000e+000,3,9.961730e-001,0.000000e+000,,,,,,,,,,,,,,32,1,4.000000e+000,6.634827e-001,0.000000e+000,0,,0,
1434046800.824,,5.000000e+003,3.000077e+002,4.383119e-003,0.000000e+000,3,9.966930e-001,0.000000e+000,,,,,,,,,,,,,,32,1,4.000000e+000,1.019287e-002,0.000000e+000,0,,0,