File: Publications/RE3Sb3A2O14/Data/Pr3Sb3Mg2O14.dc.dat
[Header]
TITLE,MPMS DC Measurement
BYAPP,MPMS Measurement,2.1,Summary
FILEOPENTIME, 1430923939.975000 5/6/2015, 10:52:19 AM

INFO, APPNAME, MPMS MultiVu Application, Revision 1.60,  Build 081

INFO, NAME, Pr3Sb3Mg2O14
INFO, WEIGHT, 58.300
INFO, AREA, 1.000
INFO, LENGTH, 1.000
INFO, SHAPE, 0
INFO, COMMENT,
INFO, SEQUENCE FILE: MT up.seq_5 to 300_quick.seq


INFO, BACKGROUND DATA FILE:, None


STARTUPAXIS,X,4,LINEAR,AUTO,0.000000,0.000000
STARTUPAXIS,Y1,5,LINEAR,AUTO,0.000000,0.000000


STARTUPGROUP,Longitudinal
FIELDGROUP,Longitudinal,1,2,3,4,5,6,7,8,9,15,16,17,18,27,28
FIELDGROUP,Transverse,1,2,3,4,10,11,12,13,14,19,20,21,22,27,28

PLOT_APPEARANCE,ALL,HORZ_GRID_ON,VERT_GRID_ON,MARKERS_AND_LINES

[Data]
Time,Comment,Field (Oe),Temperature (K),Long Moment (emu),Long Scan Std Dev,Long Algorithm,Long Reg Fit,Long Percent Error (%),Trans Moment (emu),Trans Scan Std Dev,Trans Algorithm,Trans Reg Fit,Trans Percent Error (%),Long Moment [w/o ABS] (emu),Long Scan Std Dev [w/o ABS],Long Reg Fit [w/o ABS],Long Percent Error [w/o ABS] (%),Trans Moment [w/o ABS] (emu),Trans Scan Std Dev [w/o ABS],Trans Reg Fit [w/o ABS],Trans Percent Error [w/o ABS] (%),Points per Scan,Scans per Measurement,Scan Length (cm),Delta Temp (K),Rot Position (deg),Error,EC Comp. Running,Using ABS,
1430923939.975,,1.000000e+003,1.978152e+000,4.857143e-003,2.858742e-006,3,9.931660e-001,5.885645e-002,,,,,,,,,,,,,,32,2,4.000000e+000,1.017094e-002,0.000000e+000,0,,0,
1430924041.835,,1.000000e+003,2.608104e+000,4.606794e-003,2.608462e-005,3,9.933625e-001,5.662207e-001,,,,,,,,,,,,,,32,2,4.000000e+000,2.029421e-001,0.000000e+000,0,,0,
1430924104.765,,1.000000e+003,3.095114e+000,4.473300e-003,2.212973e-005,3,9.929936e-001,4.947070e-001,,,,,,,,,,,,,,32,2,4.000000e+000,1.830351e-001,0.000000e+000,0,,0,
1430924170.235,,1.000000e+003,3.689556e+000,4.349666e-003,2.852156e-005,3,9.934539e-001,6.557184e-001,,,,,,,,,,,,,,32,2,4.000000e+000,3.560271e-001,0.000000e+000,0,,0,
1430924213.025,,1.000000e+003,4.121058e+000,4.278109e-003,1.654527e-005,3,9.941686e-001,3.867426e-001,,,,,,,,,,,,,,32,2,4.000000e+000,2.182531e-001,0.000000e+000,0,,0,
1430924275.055,,1.000000e+003,4.611325e+000,4.205849e-003,1.157886e-005,3,9.935643e-001,2.753037e-001,,,,,,,,,,,,,,32,2,4.000000e+000,2.023687e-001,0.000000e+000,0,,0,
1430924340.595,,1.000000e+003,5.102302e+000,4.145062e-003,1.409417e-005,3,9.927021e-001,3.400231e-001,,,,,,,,,,,,,,32,2,4.000000e+000,2.178459e-001,0.000000e+000,0,,0,
1430924398.695,,1.000000e+003,5.571152e+000,4.089294e-003,9.801118e-006,3,9.936495e-001,2.396775e-001,,,,,,,,,,,,,,32,2,4.000000e+000,1.525488e-001,0.000000e+000,0,,0,
1430924467.856,,1.000000e+003,6.107005e+000,4.040141e-003,6.790252e-006,3,9.933943e-001,1.680697e-001,,,,,,,,,,,,,,32,2,4.000000e+000,1.881599e-001,0.000000e+000,0,,0,
1430924527.416,,1.000000e+003,6.588268e+000,4.003167e-003,1.135462e-005,3,9.929145e-001,2.836410e-001,,,,,,,,,,,,,,32,2,4.000000e+000,1.770372e-001,0.000000e+000,0,,0,
1430924590.266,,1.000000e+003,7.095690e+000,3.960048e-003,4.672703e-006,3,9.936186e-001,1.179961e-001,,,,,,,,,,,,,,32,2,4.000000e+000,2.016258e-001,0.000000e+000,0,,0,
1430924653.246,,1.000000e+003,7.602794e+000,3.925852e-003,3.596641e-006,3,9.932512e-001,9.161427e-002,,,,,,,,,,,,,,32,2,4.000000e+000,1.733284e-001,0.000000e+000,0,,0,
1430924715.396,,1.000000e+003,8.139194e+000,3.893459e-003,6.073262e-006,3,9.937401e-001,1.559863e-001,,,,,,,,,,,,,,32,2,4.000000e+000,2.283964e-001,0.000000e+000,0,,0,
1430924772.476,,1.000000e+003,8.607690e+000,3.866389e-003,4.840961e-006,3,9.937009e-001,1.252062e-001,,,,,,,,,,,,,,32,2,4.000000e+000,2.011719e-001,0.000000e+000,0,,0,
1430924819.706,,1.000000e+003,9.105408e+000,3.840809e-003,4.097464e-006,3,9.936999e-001,1.066823e-001,,,,,,,,,,,,,,32,2,4.000000e+000,1.735497e-001,0.000000e+000,0,,0,
1430924884.796,,1.000000e+003,9.594284e+000,3.817834e-003,4.075567e-006,3,9.935126e-001,1.067508e-001,,,,,,,,,,,,,,32,2,4.000000e+000,1.761007e-001,0.000000e+000,0,,0,
1430924949.406,,1.000000e+003,1.009131e+001,3.794703e-003,3.189990e-006,3,9.936483e-001,8.406428e-002,,,,,,,,,,,,,,32,2,4.000000e+000,1.775293e-001,0.000000e+000,0,,0,
1430925012.576,,1.000000e+003,1.060456e+001,3.773123e-003,2.695258e-006,3,9.937614e-001,7.143309e-002,,,,,,,,,,,,,,32,2,4.000000e+000,1.825104e-001,0.000000e+000,0,,0,
1430925074.226,,1.000000e+003,1.110186e+001,3.748838e-003,1.188673e-006,3,9.936892e-001,3.170777e-002,,,,,,,,,,,,,,32,2,4.000000e+000,1.900997e-001,0.000000e+000,0,,0,
1430925137.616,,1.000000e+003,1.158346e+001,3.734106e-003,1.537537e-006,3,9.947205e-001,4.117550e-002,,,,,,,,,,,,,,32,2,4.000000e+000,1.606092e-001,0.000000e+000,0,,0,
1430925208.247,,1.000000e+003,1.213974e+001,3.716124e-003,4.325979e-006,3,9.936015e-001,1.164110e-001,,,,,,,,,,,,,,32,2,4.000000e+000,1.686602e-001,0.000000e+000,0,,0,
1430925264.447,,1.000000e+003,1.260589e+001,3.699780e-003,1.824333e-006,3,9.933439e-001,4.930922e-002,,,,,,,,,,,,,,32,2,4.000000e+000,1.943693e-001,0.000000e+000,0,,0,
1430925325.127,,1.000000e+003,1.309853e+001,3.680611e-003,4.967401e-006,3,9.943407e-001,1.349613e-001,,,,,,,,,,,,,,32,2,4.000000e+000,1.713705e-001,0.000000e+000,0,,0,
1430925387.967,,1.000000e+003,1.359833e+001,3.665813e-003,2.330918e-006,3,9.940125e-001,6.358530e-002,,,,,,,,,,,,,,32,2,4.000000e+000,1.870699e-001,0.000000e+000,0,,0,
1430925450.357,,1.000000e+003,1.410732e+001,3.650434e-003,3.541159e-006,3,9.941369e-001,9.700650e-002,,,,,,,,,,,,,,32,2,4.000000e+000,2.007599e-001,0.000000e+000,0,,0,
1430925509.077,,1.000000e+003,1.460087e+001,3.635870e-003,2.711886e-006,3,9.939549e-001,7.458700e-002,,,,,,,,,,,,,,32,2,4.000000e+000,1.836700e-001,0.000000e+000,0,,0,
1430925573.617,,1.000000e+003,1.510301e+001,3.625858e-003,2.594995e-006,3,9.944122e-001,7.156912e-002,,,,,,,,,,,,,,32,2,4.000000e+000,1.855803e-001,0.000000e+000,0,,0,
1430925635.627,,1.000000e+003,1.560208e+001,3.610918e-003,8.307539e-006,3,9.936094e-001,2.300672e-001,,,,,,,,,,,,,,32,2,4.000000e+000,1.815405e-001,0.000000e+000,0,,0,
1430925697.537,,1.000000e+003,1.609631e+001,3.594019e-003,1.725551e-006,3,9.940321e-001,4.801174e-002,,,,,,,,,,,,,,32,2,4.000000e+000,1.878300e-001,0.000000e+000,0,,0,
1430925757.977,,1.000000e+003,1.659717e+001,3.580364e-003,3.325815e-006,3,9.942213e-001,9.289040e-002,,,,,,,,,,,,,,32,2,4.000000e+000,1.914101e-001,0.000000e+000,0,,0,
1430925820.107,,1.000000e+003,1.710349e+001,3.568413e-003,3.343266e-006,3,9.942061e-001,9.369055e-002,,,,,,,,,,,,,,32,2,4.000000e+000,1.910191e-001,0.000000e+000,0,,0,
1430925879.018,,1.000000e+003,1.760069e+001,3.550753e-003,2.657886e-006,3,9.939882e-001,7.485414e-002,,,,,,,,,,,,,,32,2,4.000000e+000,1.947594e-001,0.000000e+000,0,,0,
1430925941.618,,1.000000e+003,1.809734e+001,3.537516e-003,1.281692e-006,3,9.939239e-001,3.623142e-002,,,,,,,,,,,,,,32,2,4.000000e+000,1.921005e-001,0.000000e+000,0,,0,
1430926004.258,,1.000000e+003,1.860681e+001,3.524599e-003,2.810339e-006,3,9.944543e-001,7.973499e-002,,,,,,,,,,,,,,32,2,4.000000e+000,2.002602e-001,0.000000e+000,0,,0,
1430926064.228,,1.000000e+003,1.909948e+001,3.507625e-003,1.393316e-006,3,9.941983e-001,3.972247e-002,,,,,,,,,,,,,,32,2,4.000000e+000,1.835995e-001,0.000000e+000,0,,0,
1430926120.688,,1.000000e+003,1.960538e+001,3.492723e-003,2.683898e-006,3,9.941629e-001,7.684257e-002,,,,,,,,,,,,,,32,2,4.000000e+000,1.880894e-001,0.000000e+000,0,,0,
1430926182.858,,1.000000e+003,2.009826e+001,3.478550e-003,2.421962e-006,3,9.942880e-001,6.962562e-002,,,,,,,,,,,,,,32,2,4.000000e+000,1.893311e-001,0.000000e+000,0,,0,
1430926246.688,,1.000000e+003,2.060699e+001,3.464301e-003,4.243332e-006,3,9.941205e-001,1.224874e-001,,,,,,,,,,,,,,32,2,4.000000e+000,1.906509e-001,0.000000e+000,0,,0,
1430926307.458,,1.000000e+003,2.110489e+001,3.448390e-003,2.113928e-006,3,9.939510e-001,6.130188e-002,,,,,,,,,,,,,,32,2,4.000000e+000,1.930885e-001,0.000000e+000,0,,0,
1430926368.418,,1.000000e+003,2.159299e+001,3.433125e-003,2.035726e-006,3,9.939554e-001,5.929659e-002,,,,,,,,,,,,,,32,2,4.000000e+000,1.771698e-001,0.000000e+000,0,,0,
1430926432.358,,1.000000e+003,2.210181e+001,3.417936e-003,2.898748e-006,3,9.943689e-001,8.480990e-002,,,,,,,,,,,,,,32,2,4.000000e+000,1.904716e-001,0.000000e+000,0,,0,
1430926492.598,,1.000000e+003,2.259605e+001,3.403726e-003,1.579354e-006,3,9.939572e-001,4.640076e-002,,,,,,,,,,,,,,32,2,4.000000e+000,1.691303e-001,0.000000e+000,0,,0,
1430926553.438,,1.000000e+003,2.309443e+001,3.388361e-003,1.804577e-006,3,9.940350e-001,5.325809e-002,,,,,,,,,,,,,,32,2,4.000000e+000,1.736698e-001,0.000000e+000,0,,0,
1430926616.319,,1.000000e+003,2.359097e+001,3.373267e-003,1.942542e-006,3,9.941882e-001,5.758637e-002,,,,,,,,,,,,,,32,2,4.000000e+000,1.750908e-001,0.000000e+000,0,,0,
1430926679.379,,1.000000e+003,2.410135e+001,3.358458e-003,2.650477e-006,3,9.934887e-001,7.891947e-002,,,,,,,,,,,,,,32,2,4.000000e+000,1.972599e-001,0.000000e+000,0,,0,
1430926741.179,,1.000000e+003,2.460519e+001,3.340310e-003,1.503128e-006,3,9.942624e-001,4.499966e-002,,,,,,,,,,,,,,32,2,4.000000e+000,1.938610e-001,0.000000e+000,0,,0,
1430926870.749,,1.000000e+003,2.499313e+001,3.333180e-003,7.216001e-006,3,9.936591e-001,2.164900e-001,,,,,,,,,,,,,,32,2,4.000000e+000,6.208420e-003,0.000000e+000,0,,0,
1430926948.779,,1.000000e+003,2.500134e+001,3.333716e-003,0.000000e+000,3,9.929896e-001,0.000000e+000,,,,,,,,,,,,,,32,1,4.000000e+000,8.888245e-004,0.000000e+000,0,,0,
1430927015.779,,1.000000e+003,2.834008e+001,3.232726e-003,0.000000e+000,3,9.933963e-001,0.000000e+000,,,,,,,,,,,,,,32,1,4.000000e+000,6.897907e-001,0.000000e+000,0,,0,
1430927062.129,,1.000000e+003,3.145395e+001,3.124331e-003,0.000000e+000,3,9.943106e-001,0.000000e+000,,,,,,,,,,,,,,32,1,4.000000e+000,6.740494e-001,0.000000e+000,0,,0,
1430927106.379,,1.000000e+003,3.433914e+001,3.028266e-003,0.000000e+000,3,9.936886e-001,0.000000e+000,,,,,,,,,,,,,,32,1,4.000000e+000,7.269630e-001,0.000000e+000,0,,0,
1430927153.509,,1.000000e+003,3.743443e+001,2.926936e-003,0.000000e+000,3,9.940998e-001,0.000000e+000,,,,,,,,,,,,,,32,1,4.000000e+000,7.089386e-001,0.000000e+000,0,,0,
1430927198.399,,1.000000e+003,4.041582e+001,2.831144e-003,0.000000e+000,3,9.938872e-001,0.000000e+000,,,,,,,,,,,,,,32,1,4.000000e+000,6.815910e-001,0.000000e+000,0,,0,
1430927242.279,,1.000000e+003,4.324715e+001,2.747325e-003,0.000000e+000,3,9.933879e-001,0.000000e+000,,,,,,,,,,,,,,32,1,4.000000e+000,4.964104e-001,0.000000e+000,0,,0,
1430927286.549,,1.000000e+003,4.630114e+001,2.656815e-003,0.000000e+000,3,9.936768e-001,0.000000e+000,,,,,,,,,,,,,,32,1,4.000000e+000,7.061615e-001,0.000000e+000,0,,0,
1430927332.640,,1.000000e+003,4.931670e+001,2.572897e-003,0.000000e+000,3,9.937741e-001,0.000000e+000,,,,,,,,,,,,,,32,1,4.000000e+000,7.174492e-001,0.000000e+000,0,,0,
1430927380.170,,1.000000e+003,5.227479e+001,2.488896e-003,0.000000e+000,3,9.940454e-001,0.000000e+000,,,,,,,,,,,,,,32,1,4.000000e+000,6.216698e-001,0.000000e+000,0,,0,
1430927425.060,,1.000000e+003,5.529556e+001,2.410248e-003,0.000000e+000,3,9.949799e-001,0.000000e+000,,,,,,,,,,,,,,32,1,4.000000e+000,7.393913e-001,0.000000e+000,0,,0,
1430927476.300,,1.000000e+003,5.825173e+001,2.334657e-003,0.000000e+000,3,9.955207e-001,0.000000e+000,,,,,,,,,,,,,,32,1,4.000000e+000,6.185417e-001,0.000000e+000,0,,0,
1430927525.060,,1.000000e+003,6.130274e+001,2.264439e-003,0.000000e+000,3,9.951083e-001,0.000000e+000,,,,,,,,,,,,,,32,1,4.000000e+000,6.383781e-001,0.000000e+000,0,,0,
1430927571.060,,1.000000e+003,6.424088e+001,2.197142e-003,0.000000e+000,3,9.956328e-001,0.000000e+000,,,,,,,,,,,,,,32,1,4.000000e+000,6.476631e-001,0.000000e+000,0,,0,
1430927617.820,,1.000000e+003,6.727715e+001,2.131723e-003,0.000000e+000,3,9.956158e-001,0.000000e+000,,,,,,,,,,,,,,32,1,4.000000e+000,6.809616e-001,0.000000e+000,0,,0,
1430927663.790,,1.000000e+003,7.017729e+001,2.070935e-003,0.000000e+000,3,9.956054e-001,0.000000e+000,,,,,,,,,,,,,,32,1,4.000000e+000,6.732101e-001,0.000000e+000,0,,0,
1430927711.320,,1.000000e+003,7.332335e+001,2.012136e-003,0.000000e+000,3,9.959464e-001,0.000000e+000,,,,,,,,,,,,,,32,1,4.000000e+000,6.966782e-001,0.000000e+000,0,,0,
1430927757.000,,1.000000e+003,7.623855e+001,1.956985e-003,0.000000e+000,3,9.959644e-001,0.000000e+000,,,,,,,,,,,,,,32,1,4.000000e+000,7.529297e-001,0.000000e+000,0,,0,
1430927801.800,,1.000000e+003,7.925038e+001,1.905110e-003,0.000000e+000,3,9.962103e-001,0.000000e+000,,,,,,,,,,,,,,32,1,4.000000e+000,6.800919e-001,0.000000e+000,0,,0,
1430927847.870,,1.000000e+003,8.216983e+001,1.854802e-003,0.000000e+000,3,9.960642e-001,0.000000e+000,,,,,,,,,,,,,,32,1,4.000000e+000,7.078247e-001,0.000000e+000,0,,0,
1430927893.770,,1.000000e+003,8.513557e+001,1.807726e-003,0.000000e+000,3,9.965444e-001,0.000000e+000,,,,,,,,,,,,,,32,1,4.000000e+000,6.044235e-001,0.000000e+000,0,,0,
1430927941.660,,1.000000e+003,8.817615e+001,1.761664e-003,0.000000e+000,3,9.964436e-001,0.000000e+000,,,,,,,,,,,,,,32,1,4.000000e+000,7.379608e-001,0.000000e+000,0,,0,
1430927985.990,,1.000000e+003,9.119471e+001,1.719726e-003,0.000000e+000,3,9.961687e-001,0.000000e+000,,,,,,,,,,,,,,32,1,4.000000e+000,6.628265e-001,0.000000e+000,0,,0,
1430928029.601,,1.000000e+003,9.412976e+001,1.679343e-003,0.000000e+000,3,9.961342e-001,0.000000e+000,,,,,,,,,,,,,,32,1,4.000000e+000,7.241364e-001,0.000000e+000,0,,0,
1430928077.551,,1.000000e+003,9.719704e+001,1.636897e-003,0.000000e+000,3,9.966001e-001,0.000000e+000,,,,,,,,,,,,,,32,1,4.000000e+000,7.233124e-001,0.000000e+000,0,,0,
1430928121.551,,1.000000e+003,1.000997e+002,1.601907e-003,0.000000e+000,3,9.958147e-001,0.000000e+000,,,,,,,,,,,,,,32,1,4.000000e+000,6.970139e-001,0.000000e+000,0,,0,
1430928168.791,,1.000000e+003,1.030034e+002,1.565464e-003,0.000000e+000,3,9.963579e-001,0.000000e+000,,,,,,,,,,,,,,32,1,4.000000e+000,5.685959e-001,0.000000e+000,0,,0,
1430928218.941,,1.000000e+003,1.061785e+002,1.530705e-003,0.000000e+000,3,9.965863e-001,0.000000e+000,,,,,,,,,,,,,,32,1,4.000000e+000,6.174011e-001,0.000000e+000,0,,0,
1430928263.681,,1.000000e+003,1.090789e+002,1.499355e-003,0.000000e+000,3,9.966593e-001,0.000000e+000,,,,,,,,,,,,,,32,1,4.000000e+000,6.992950e-001,0.000000e+000,0,,0,
1430928309.791,,1.000000e+003,1.121436e+002,1.467423e-003,0.000000e+000,3,9.965868e-001,0.000000e+000,,,,,,,,,,,,,,32,1,4.000000e+000,7.233047e-001,0.000000e+000,0,,0,
1430928353.271,,1.000000e+003,1.150678e+002,1.433786e-003,0.000000e+000,3,9.975164e-001,0.000000e+000,,,,,,,,,,,,,,32,1,4.000000e+000,7.323990e-001,0.000000e+000,0,,0,
1430928398.381,,1.000000e+003,1.180302e+002,1.410553e-003,0.000000e+000,3,9.963031e-001,0.000000e+000,,,,,,,,,,,,,,32,1,4.000000e+000,6.774979e-001,0.000000e+000,0,,0,
1430928457.971,,1.000000e+003,1.219308e+002,1.372888e-003,0.000000e+000,3,9.969312e-001,0.000000e+000,,,,,,,,,,,,,,32,1,4.000000e+000,6.996002e-001,0.000000e+000,0,,0,
1430928490.321,,1.000000e+003,1.240554e+002,1.355414e-003,0.000000e+000,3,9.968274e-001,0.000000e+000,,,,,,,,,,,,,,32,1,4.000000e+000,7.761993e-001,0.000000e+000,0,,0,
1430928536.001,,1.000000e+003,1.270325e+002,1.330382e-003,0.000000e+000,3,9.968770e-001,0.000000e+000,,,,,,,,,,,,,,32,1,4.000000e+000,7.204971e-001,0.000000e+000,0,,0,
1430928582.991,,1.000000e+003,1.300347e+002,1.302156e-003,0.000000e+000,3,9.974402e-001,0.000000e+000,,,,,,,,,,,,,,32,1,4.000000e+000,6.492004e-001,0.000000e+000,0,,0,
1430928629.441,,1.000000e+003,1.330750e+002,1.282609e-003,0.000000e+000,3,9.967898e-001,0.000000e+000,,,,,,,,,,,,,,32,1,4.000000e+000,8.600922e-001,0.000000e+000,0,,0,
1430928666.161,,1.000000e+003,1.361392e+002,1.261867e-003,0.000000e+000,3,9.969295e-001,0.000000e+000,,,,,,,,,,,,,,32,1,4.000000e+000,8.422089e-001,0.000000e+000,0,,0,
1430928705.461,,1.000000e+003,1.389687e+002,1.239909e-003,0.000000e+000,3,9.970477e-001,0.000000e+000,,,,,,,,,,,,,,32,1,4.000000e+000,7.342987e-001,0.000000e+000,0,,0,
1430928750.652,,1.000000e+003,1.419716e+002,1.218723e-003,0.000000e+000,3,9.968646e-001,0.000000e+000,,,,,,,,,,,,,,32,1,4.000000e+000,7.503967e-001,0.000000e+000,0,,0,
1430928797.732,,1.000000e+003,1.449414e+002,1.197782e-003,0.000000e+000,3,9.967400e-001,0.000000e+000,,,,,,,,,,,,,,32,1,4.000000e+000,6.804047e-001,0.000000e+000,0,,0,
1430928845.272,,1.000000e+003,1.479246e+002,1.177948e-003,0.000000e+000,3,9.973018e-001,0.000000e+000,,,,,,,,,,,,,,32,1,4.000000e+000,6.775055e-001,0.000000e+000,0,,0,
1430928891.302,,1.000000e+003,1.509288e+002,1.161837e-003,0.000000e+000,3,9.976112e-001,0.000000e+000,,,,,,,,,,,,,,32,1,4.000000e+000,6.730957e-001,0.000000e+000,0,,0,
1430928938.152,,1.000000e+003,1.539340e+002,1.149165e-003,0.000000e+000,3,9.959550e-001,0.000000e+000,,,,,,,,,,,,,,32,1,4.000000e+000,6.667938e-001,0.000000e+000,0,,0,
1430928985.492,,1.000000e+003,1.569084e+002,1.121167e-003,0.000000e+000,3,9.969662e-001,0.000000e+000,,,,,,,,,,,,,,32,1,4.000000e+000,6.860962e-001,0.000000e+000,0,,0,
1430929033.922,,1.000000e+003,1.599138e+002,1.107418e-003,0.000000e+000,3,9.970826e-001,0.000000e+000,,,,,,,,,,,,,,32,1,4.000000e+000,7.055054e-001,0.000000e+000,0,,0,
1430929080.062,,1.000000e+003,1.628990e+002,1.083848e-003,0.000000e+000,3,9.968633e-001,0.000000e+000,,,,,,,,,,,,,,32,1,4.000000e+000,7.192993e-001,0.000000e+000,0,,0,
1430929126.952,,1.000000e+003,1.659217e+002,1.075025e-003,0.000000e+000,3,9.969072e-001,0.000000e+000,,,,,,,,,,,,,,32,1,4.000000e+000,7.761993e-001,0.000000e+000,0,,0,
1430929172.162,,1.000000e+003,1.689019e+002,1.060033e-003,0.000000e+000,3,9.974403e-001,0.000000e+000,,,,,,,,,,,,,,32,1,4.000000e+000,6.824036e-001,0.000000e+000,0,,0,
1430929219.132,,1.000000e+003,1.718329e+002,1.045093e-003,0.000000e+000,3,9.974813e-001,0.000000e+000,,,,,,,,,,,,,,32,1,4.000000e+000,6.395874e-001,0.000000e+000,0,,0,
1430929267.132,,1.000000e+003,1.748441e+002,1.024188e-003,0.000000e+000,3,9.947006e-001,0.000000e+000,,,,,,,,,,,,,,32,1,4.000000e+000,6.889038e-001,0.000000e+000,0,,0,
1430929313.612,,1.000000e+003,1.778503e+002,1.016621e-003,0.000000e+000,3,9.979051e-001,0.000000e+000,,,,,,,,,,,,,,32,1,4.000000e+000,6.909943e-001,0.000000e+000,0,,0,
1430929360.562,,1.000000e+003,1.808894e+002,1.007970e-003,0.000000e+000,3,9.964439e-001,0.000000e+000,,,,,,,,,,,,,,32,1,4.000000e+000,6.703949e-001,0.000000e+000,0,,0,
1430929403.052,,1.000000e+003,1.838372e+002,9.907220e-004,0.000000e+000,3,9.973601e-001,0.000000e+000,,,,,,,,,,,,,,32,1,4.000000e+000,7.368927e-001,0.000000e+000,0,,0,
1430929447.353,,1.000000e+003,1.868584e+002,9.777206e-004,0.000000e+000,3,9.977973e-001,0.000000e+000,,,,,,,,,,,,,,32,1,4.000000e+000,6.596985e-001,0.000000e+000,0,,0,
1430929492.323,,1.000000e+003,1.897896e+002,9.609830e-004,0.000000e+000,3,9.955844e-001,0.000000e+000,,,,,,,,,,,,,,32,1,4.000000e+000,7.120056e-001,0.000000e+000,0,,0,
1430929539.043,,1.000000e+003,1.928569e+002,9.526775e-004,0.000000e+000,3,9.978008e-001,0.000000e+000,,,,,,,,,,,,,,32,1,4.000000e+000,7.758026e-001,0.000000e+000,0,,0,
1430929583.413,,1.000000e+003,1.958174e+002,9.414271e-004,0.000000e+000,3,9.976500e-001,0.000000e+000,,,,,,,,,,,,,,32,1,4.000000e+000,6.374969e-001,0.000000e+000,0,,0,
1430929628.313,,1.000000e+003,1.987499e+002,9.302976e-004,0.000000e+000,3,9.975891e-001,0.000000e+000,,,,,,,,,,,,,,32,1,4.000000e+000,7.437897e-001,0.000000e+000,0,,0,
1430929675.573,,1.000000e+003,2.017642e+002,9.188278e-004,0.000000e+000,3,9.974904e-001,0.000000e+000,,,,,,,,,,,,,,32,1,4.000000e+000,6.486969e-001,0.000000e+000,0,,0,
1430929724.983,,1.000000e+003,2.047805e+002,9.167915e-004,0.000000e+000,3,9.958335e-001,0.000000e+000,,,,,,,,,,,,,,32,1,4.000000e+000,6.676941e-001,0.000000e+000,0,,0,
1430929771.713,,1.000000e+003,2.077266e+002,8.976630e-004,0.000000e+000,3,9.978175e-001,0.000000e+000,,,,,,,,,,,,,,32,1,4.000000e+000,6.869965e-001,0.000000e+000,0,,0,
1430929817.073,,1.000000e+003,2.106784e+002,8.797633e-004,0.000000e+000,3,9.969178e-001,0.000000e+000,,,,,,,,,,,,,,32,1,4.000000e+000,6.872101e-001,0.000000e+000,0,,0,
1430929864.853,,1.000000e+003,2.137159e+002,8.808030e-004,0.000000e+000,3,9.947519e-001,0.000000e+000,,,,,,,,,,,,,,32,1,4.000000e+000,7.274933e-001,0.000000e+000,0,,0,
1430929911.423,,1.000000e+003,2.167179e+002,8.592769e-004,0.000000e+000,3,9.963146e-001,0.000000e+000,,,,,,,,,,,,,,32,1,4.000000e+000,6.233978e-001,0.000000e+000,0,,0,
1430929956.193,,1.000000e+003,2.197209e+002,8.575198e-004,0.000000e+000,3,9.971978e-001,0.000000e+000,,,,,,,,,,,,,,32,1,4.000000e+000,7.904968e-001,0.000000e+000,0,,0,
1430930001.673,,1.000000e+003,2.227202e+002,8.487542e-004,0.000000e+000,3,9.971469e-001,0.000000e+000,,,,,,,,,,,,,,32,1,4.000000e+000,6.806030e-001,0.000000e+000,0,,0,
1430930045.633,,1.000000e+003,2.256059e+002,8.300837e-004,0.000000e+000,3,9.935482e-001,0.000000e+000,,,,,,,,,,,,,,32,1,4.000000e+000,6.420898e-001,0.000000e+000,0,,0,
1430930092.173,,1.000000e+003,2.286949e+002,8.333731e-004,0.000000e+000,3,9.957918e-001,0.000000e+000,,,,,,,,,,,,,,32,1,4.000000e+000,6.714935e-001,0.000000e+000,0,,0,
1430930137.333,,1.000000e+003,2.316797e+002,8.305173e-004,0.000000e+000,3,9.941879e-001,0.000000e+000,,,,,,,,,,,,,,32,1,4.000000e+000,6.534882e-001,0.000000e+000,0,,0,
1430930184.954,,1.000000e+003,2.346550e+002,8.136712e-004,0.000000e+000,3,9.970357e-001,0.000000e+000,,,,,,,,,,,,,,32,1,4.000000e+000,6.947021e-001,0.000000e+000,0,,0,
1430930230.234,,1.000000e+003,2.375859e+002,8.053462e-004,0.000000e+000,3,9.970725e-001,0.000000e+000,,,,,,,,,,,,,,32,1,4.000000e+000,6.996002e-001,0.000000e+000,0,,0,
1430930278.194,,1.000000e+003,2.406551e+002,7.888528e-004,0.000000e+000,3,9.938600e-001,0.000000e+000,,,,,,,,,,,,,,32,1,4.000000e+000,7.563019e-001,0.000000e+000,0,,0,
1430930323.684,,1.000000e+003,2.436400e+002,7.895022e-004,0.000000e+000,3,9.969009e-001,0.000000e+000,,,,,,,,,,,,,,32,1,4.000000e+000,7.752075e-001,0.000000e+000,0,,0,
1430930369.534,,1.000000e+003,2.465380e+002,7.791053e-004,0.000000e+000,3,9.918447e-001,0.000000e+000,,,,,,,,,,,,,,32,1,4.000000e+000,6.457977e-001,0.000000e+000,0,,0,
1430930432.324,,1.000000e+003,2.503526e+002,7.731661e-004,0.000000e+000,3,9.971058e-001,0.000000e+000,,,,,,,,,,,,,,32,1,4.000000e+000,6.588135e-001,0.000000e+000,0,,0,
1430930466.824,,1.000000e+003,2.525954e+002,7.662998e-004,0.000000e+000,3,9.964803e-001,0.000000e+000,,,,,,,,,,,,,,32,1,4.000000e+000,7.483978e-001,0.000000e+000,0,,0,
1430930511.764,,1.000000e+003,2.555376e+002,7.597880e-004,0.000000e+000,3,9.968717e-001,0.000000e+000,,,,,,,,,,,,,,32,1,4.000000e+000,5.635071e-001,0.000000e+000,0,,0,
1430930559.154,,1.000000e+003,2.586010e+002,7.530036e-004,0.000000e+000,3,9.965208e-001,0.000000e+000,,,,,,,,,,,,,,32,1,4.000000e+000,6.806030e-001,0.000000e+000,0,,0,
1430930602.094,,1.000000e+003,2.615606e+002,7.453770e-004,0.000000e+000,3,9.960531e-001,0.000000e+000,,,,,,,,,,,,,,32,1,4.000000e+000,8.250122e-001,0.000000e+000,0,,0,
1430930644.594,,1.000000e+003,2.646617e+002,7.370474e-004,0.000000e+000,3,9.957359e-001,0.000000e+000,,,,,,,,,,,,,,32,1,4.000000e+000,7.839966e-001,0.000000e+000,0,,0,
1430930684.674,,1.000000e+003,2.676195e+002,7.325126e-004,0.000000e+000,3,9.955100e-001,0.000000e+000,,,,,,,,,,,,,,32,1,4.000000e+000,6.838074e-001,0.000000e+000,0,,0,
1430930728.284,,1.000000e+003,2.705445e+002,7.257802e-004,0.000000e+000,3,9.951068e-001,0.000000e+000,,,,,,,,,,,,,,32,1,4.000000e+000,7.084045e-001,0.000000e+000,0,,0,
1430930773.364,,1.000000e+003,2.734604e+002,7.206694e-004,0.000000e+000,3,9.960038e-001,0.000000e+000,,,,,,,,,,,,,,32,1,4.000000e+000,6.917114e-001,0.000000e+000,0,,0,
1430930821.154,,1.000000e+003,2.765009e+002,7.128207e-004,0.000000e+000,3,9.964029e-001,0.000000e+000,,,,,,,,,,,,,,32,1,4.000000e+000,6.486816e-001,0.000000e+000,0,,0,
1430930869.454,,1.000000e+003,2.794799e+002,7.042285e-004,0.000000e+000,3,9.943792e-001,0.000000e+000,,,,,,,,,,,,,,32,1,4.000000e+000,6.988220e-001,0.000000e+000,0,,0,
1430930917.415,,1.000000e+003,2.824573e+002,7.008745e-004,0.000000e+000,3,9.956134e-001,0.000000e+000,,,,,,,,,,,,,,32,1,4.000000e+000,6.256104e-001,0.000000e+000,0,,0,
1430930963.505,,1.000000e+003,2.854492e+002,6.937825e-004,0.000000e+000,3,9.949501e-001,0.000000e+000,,,,,,,,,,,,,,32,1,4.000000e+000,7.312927e-001,0.000000e+000,0,,0,
1430931010.155,,1.000000e+003,2.884536e+002,6.889787e-004,0.000000e+000,3,9.951898e-001,0.000000e+000,,,,,,,,,,,,,,32,1,4.000000e+000,5.797119e-001,0.000000e+000,0,,0,
1430931057.575,,1.000000e+003,2.915029e+002,6.835458e-004,0.000000e+000,3,9.955793e-001,0.000000e+000,,,,,,,,,,,,,,32,1,4.000000e+000,6.979980e-001,0.000000e+000,0,,0,
1430931103.575,,1.000000e+003,2.943677e+002,6.755080e-004,0.000000e+000,3,9.942144e-001,0.000000e+000,,,,,,,,,,,,,,32,1,4.000000e+000,6.639099e-001,0.000000e+000,0,,0,
1430931150.845,,1.000000e+003,2.974106e+002,6.724373e-004,0.000000e+000,3,9.950793e-001,0.000000e+000,,,,,,,,,,,,,,32,1,4.000000e+000,6.636047e-001,0.000000e+000,0,,0,
1430931432.645,,1.000000e+003,3.000037e+002,6.646513e-004,0.000000e+000,3,9.935420e-001,0.000000e+000,,,,,,,,,,,,,,32,1,4.000000e+000,2.029419e-002,0.000000e+000,0,,0,