File: Publications/AErSe2/KErSe2_bulkdata/RE__CsErSe2_heat_capacity_and_magnetization_results/KErSe2_Hparatoplate_12.07.2019.dc.dat
[Header]
TITLE,MPMS DC Measurement
BYAPP,MPMS Measurement,2.1,Summary
FILEOPENTIME, 1575734548.046000 12/7/2019, 8:02:28 AM

INFO, APPNAME, MPMS MultiVu Application, Revision 1.61,  Build 082

INFO, NAME, KErSe2_Hparatoplate_12.07.2019
INFO, WEIGHT, 0.560mg
INFO, AREA, 1.000
INFO, LENGTH, 1.000
INFO, SHAPE, Plate
INFO, COMMENT, KErSe2_Hparatoplate_12.07.2019 on grease straw neutronsample
INFO, SEQUENCE FILE: Er.seq


INFO, BACKGROUND DATA FILE:, None


STARTUPAXIS,X,4,LINEAR,AUTO,0.000000,0.000000
STARTUPAXIS,Y1,5,LINEAR,AUTO,0.000000,0.000000


STARTUPGROUP,Longitudinal
FIELDGROUP,Longitudinal,1,2,3,4,5,6,7,8,9,15,16,17,18,27,28
FIELDGROUP,Transverse,1,2,3,4,10,11,12,13,14,19,20,21,22,27,28

PLOT_APPEARANCE,ALL,HORZ_GRID_ON,VERT_GRID_ON,MARKERS_AND_LINES

[Data]
Time,Comment,Field (Oe),Temperature (K),Long Moment (emu),Long Scan Std Dev,Long Algorithm,Long Reg Fit,Long Percent Error (%),Trans Moment (emu),Trans Scan Std Dev,Trans Algorithm,Trans Reg Fit,Trans Percent Error (%),Long Moment [w/o ABS] (emu),Long Scan Std Dev [w/o ABS],Long Reg Fit [w/o ABS],Long Percent Error [w/o ABS] (%),Trans Moment [w/o ABS] (emu),Trans Scan Std Dev [w/o ABS],Trans Reg Fit [w/o ABS],Trans Percent Error [w/o ABS] (%),Points per Scan,Scans per Measurement,Scan Length (cm),Delta Temp (K),Rot Position (deg),Error,EC Comp. Running,Using ABS,
1575734548.046,,6.000000e+004,1.999390e+000,5.503910e-003,0.000000e+000,3,8.781991e-001,0.000000e+000,,,,,,,,,,,,,,24,1,4.000000e+000,1.380444e-004,0.000000e+000,0,,0,
1575734904.031,,5.700000e+004,1.999303e+000,6.303633e-002,0.000000e+000,3,9.931544e-001,0.000000e+000,,,,,,,,,,,,,,24,1,4.000000e+000,7.250309e-004,0.000000e+000,0,,0,
1575735187.375,,5.100000e+004,1.999839e+000,6.196870e-002,0.000000e+000,3,9.935146e-001,0.000000e+000,,,,,,,,,,,,,,24,1,4.000000e+000,2.080202e-004,0.000000e+000,0,,0,
1575735347.859,,4.800000e+004,1.999753e+000,6.133524e-002,0.000000e+000,3,9.931922e-001,0.000000e+000,,,,,,,,,,,,,,24,1,4.000000e+000,3.809929e-004,0.000000e+000,0,,0,
1575735627.343,,4.200000e+004,1.999528e+000,6.001853e-002,0.000000e+000,3,9.934854e-001,0.000000e+000,,,,,,,,,,,,,,24,1,4.000000e+000,7.599592e-004,0.000000e+000,0,,0,
1575735787.140,,3.900000e+004,1.999649e+000,5.926875e-002,0.000000e+000,3,9.933161e-001,0.000000e+000,,,,,,,,,,,,,,24,1,4.000000e+000,1.209974e-003,0.000000e+000,0,,0,
1575736063.656,,3.300000e+004,1.999788e+000,5.758008e-002,0.000000e+000,3,9.935614e-001,0.000000e+000,,,,,,,,,,,,,,24,1,4.000000e+000,1.729727e-004,0.000000e+000,0,,0,
1575736215.078,,3.000000e+004,1.999787e+000,5.657956e-002,0.000000e+000,3,9.932977e-001,0.000000e+000,,,,,,,,,,,,,,24,1,4.000000e+000,7.259846e-004,0.000000e+000,0,,0,
1575736474.296,,2.800000e+004,1.999960e+000,5.584713e-002,0.000000e+000,3,9.934887e-001,0.000000e+000,,,,,,,,,,,,,,24,1,4.000000e+000,1.210093e-003,0.000000e+000,0,,0,
1575736618.328,,2.700000e+004,2.000150e+000,5.543488e-002,0.000000e+000,3,9.931860e-001,0.000000e+000,,,,,,,,,,,,,,24,1,4.000000e+000,3.460646e-004,0.000000e+000,0,,0,
1575736875.890,,2.500000e+004,1.999925e+000,5.460197e-002,0.000000e+000,3,9.935106e-001,0.000000e+000,,,,,,,,,,,,,,24,1,4.000000e+000,3.504753e-005,0.000000e+000,0,,0,
1575737019.718,,2.400000e+004,1.999563e+000,5.410901e-002,0.000000e+000,3,9.931872e-001,0.000000e+000,,,,,,,,,,,,,,24,1,4.000000e+000,5.528927e-004,0.000000e+000,0,,0,
1575737264.750,,2.200000e+004,1.999995e+000,5.308606e-002,0.000000e+000,3,9.933494e-001,0.000000e+000,,,,,,,,,,,,,,24,1,4.000000e+000,2.421141e-004,0.000000e+000,0,,0,
1575737413.578,,2.100000e+004,1.999978e+000,5.250963e-002,0.000000e+000,3,9.931359e-001,0.000000e+000,,,,,,,,,,,,,,24,1,4.000000e+000,2.771616e-004,0.000000e+000,0,,0,
1575737662.953,,1.900000e+004,1.999408e+000,5.124554e-002,0.000000e+000,3,9.934427e-001,0.000000e+000,,,,,,,,,,,,,,24,1,4.000000e+000,5.869865e-004,0.000000e+000,0,,0,
1575737803.671,,1.800000e+004,2.000185e+000,5.047568e-002,0.000000e+000,3,9.930363e-001,0.000000e+000,,,,,,,,,,,,,,24,1,4.000000e+000,9.679794e-004,0.000000e+000,0,,0,
1575738045.078,,1.600000e+004,2.001951e+000,4.875765e-002,0.000000e+000,3,9.932040e-001,0.000000e+000,,,,,,,,,,,,,,24,1,4.000000e+000,2.779961e-004,0.000000e+000,0,,0,
1575738187.671,,1.500000e+004,1.999269e+000,4.774194e-002,0.000000e+000,3,9.931277e-001,0.000000e+000,,,,,,,,,,,,,,24,1,4.000000e+000,2.419949e-004,0.000000e+000,0,,0,
1575738434.781,,1.300000e+004,2.000444e+000,4.529563e-002,0.000000e+000,3,9.933929e-001,0.000000e+000,,,,,,,,,,,,,,24,1,4.000000e+000,3.809929e-004,0.000000e+000,0,,0,
1575738576.484,,1.200000e+004,1.999442e+000,4.376744e-002,0.000000e+000,3,9.929827e-001,0.000000e+000,,,,,,,,,,,,,,24,1,4.000000e+000,5.179644e-004,0.000000e+000,0,,0,
1575738822.640,,1.000000e+004,1.999856e+000,4.000796e-002,0.000000e+000,3,9.932176e-001,0.000000e+000,,,,,,,,,,,,,,24,1,4.000000e+000,3.800392e-004,0.000000e+000,0,,0,
1575738962.187,,9.000000e+003,1.999735e+000,3.766679e-002,0.000000e+000,3,9.930016e-001,0.000000e+000,,,,,,,,,,,,,,24,1,4.000000e+000,3.459454e-004,0.000000e+000,0,,0,
1575739220.046,,7.000000e+003,1.999856e+000,3.183335e-002,0.000000e+000,3,9.930238e-001,0.000000e+000,,,,,,,,,,,,,,24,1,4.000000e+000,7.251501e-004,0.000000e+000,0,,0,
1575739359.671,,6.000000e+003,1.999684e+000,2.828491e-002,0.000000e+000,3,9.929454e-001,0.000000e+000,,,,,,,,,,,,,,24,1,4.000000e+000,7.950068e-004,0.000000e+000,0,,0,
1575739604.359,,4.000000e+003,2.000635e+000,1.996069e-002,0.000000e+000,3,9.931683e-001,0.000000e+000,,,,,,,,,,,,,,24,1,4.000000e+000,4.150867e-004,0.000000e+000,0,,0,
1575739754.921,,3.000000e+003,2.002783e+000,1.524863e-002,0.000000e+000,3,9.927501e-001,0.000000e+000,,,,,,,,,,,,,,24,1,4.000000e+000,6.940365e-004,0.000000e+000,0,,0,
1575739987.343,,1.800000e+003,1.998716e+000,9.291788e-003,0.000000e+000,3,9.929808e-001,0.000000e+000,,,,,,,,,,,,,,24,1,4.000000e+000,2.410412e-004,0.000000e+000,0,,0,
1575740187.437,,1.600000e+003,1.999788e+000,8.264892e-003,0.000000e+000,3,9.927011e-001,0.000000e+000,,,,,,,,,,,,,,24,1,4.000000e+000,1.729727e-004,0.000000e+000,0,,0,
1575740421.781,,1.200000e+003,2.000133e+000,6.193948e-003,0.000000e+000,3,9.926050e-001,0.000000e+000,,,,,,,,,,,,,,24,1,4.000000e+000,2.419949e-004,0.000000e+000,0,,0,
1575740549.218,,1.000000e+003,2.000081e+000,5.163390e-003,0.000000e+000,3,9.928317e-001,0.000000e+000,,,,,,,,,,,,,,24,1,4.000000e+000,3.459454e-004,0.000000e+000,0,,0,
1575740789.640,,6.000000e+002,1.999787e+000,3.073679e-003,0.000000e+000,3,9.923318e-001,0.000000e+000,,,,,,,,,,,,,,24,1,4.000000e+000,1.039505e-004,0.000000e+000,0,,0,
1575740924.078,,4.000000e+002,2.000288e+000,2.033232e-003,0.000000e+000,3,9.925945e-001,0.000000e+000,,,,,,,,,,,,,,24,1,4.000000e+000,2.770424e-004,0.000000e+000,0,,0,
1575741174.468,,0.000000e+000,1.999787e+000,-5.987322e-005,0.000000e+000,3,9.856313e-001,0.000000e+000,,,,,,,,,,,,,,24,1,4.000000e+000,4.498959e-004,0.000000e+000,0,,0,
1575744646.531,,1.000000e+004,3.488984e+002,5.421278e-004,0.000000e+000,3,9.525589e-001,0.000000e+000,,,,,,,,,,,,,,24,1,4.000000e+000,2.015076e-001,0.000000e+000,0,,0,
1575744780.062,,1.000000e+004,3.457648e+002,5.453148e-004,0.000000e+000,3,9.552787e-001,0.000000e+000,,,,,,,,,,,,,,24,1,4.000000e+000,4.067078e-001,0.000000e+000,0,,0,
1575744860.859,,1.000000e+004,3.427269e+002,5.514613e-004,0.000000e+000,3,9.559130e-001,0.000000e+000,,,,,,,,,,,,,,24,1,4.000000e+000,4.443970e-001,0.000000e+000,0,,0,
1575744938.031,,1.000000e+004,3.397645e+002,5.560746e-004,0.000000e+000,3,9.565699e-001,0.000000e+000,,,,,,,,,,,,,,24,1,4.000000e+000,4.695129e-001,0.000000e+000,0,,0,
1575745030.375,,1.000000e+004,3.367928e+002,5.605459e-004,0.000000e+000,3,9.559867e-001,0.000000e+000,,,,,,,,,,,,,,24,1,4.000000e+000,4.055176e-001,0.000000e+000,0,,0,
1575745132.046,,1.000000e+004,3.338004e+002,5.651632e-004,0.000000e+000,3,9.565506e-001,0.000000e+000,,,,,,,,,,,,,,24,1,4.000000e+000,3.975220e-001,0.000000e+000,0,,0,
1575745231.781,,1.000000e+004,3.307477e+002,5.711258e-004,0.000000e+000,3,9.572062e-001,0.000000e+000,,,,,,,,,,,,,,24,1,4.000000e+000,4.107056e-001,0.000000e+000,0,,0,
1575745325.265,,1.000000e+004,3.277457e+002,5.759554e-004,0.000000e+000,3,9.587813e-001,0.000000e+000,,,,,,,,,,,,,,24,1,4.000000e+000,5.057068e-001,0.000000e+000,0,,0,
1575745418.296,,1.000000e+004,3.247321e+002,5.822795e-004,0.000000e+000,3,9.583690e-001,0.000000e+000,,,,,,,,,,,,,,24,1,4.000000e+000,4.953918e-001,0.000000e+000,0,,0,
1575745510.203,,1.000000e+004,3.217146e+002,5.865850e-004,0.000000e+000,3,9.593946e-001,0.000000e+000,,,,,,,,,,,,,,24,1,4.000000e+000,4.556274e-001,0.000000e+000,0,,0,
1575745601.265,,1.000000e+004,3.187198e+002,5.930747e-004,0.000000e+000,3,9.601128e-001,0.000000e+000,,,,,,,,,,,,,,24,1,4.000000e+000,5.335083e-001,0.000000e+000,0,,0,
1575745692.312,,1.000000e+004,3.157529e+002,5.977106e-004,0.000000e+000,3,9.604493e-001,0.000000e+000,,,,,,,,,,,,,,24,1,4.000000e+000,4.846191e-001,0.000000e+000,0,,0,
1575745783.937,,1.000000e+004,3.127582e+002,6.030954e-004,0.000000e+000,3,9.608300e-001,0.000000e+000,,,,,,,,,,,,,,24,1,4.000000e+000,4.465027e-001,0.000000e+000,0,,0,
1575745875.125,,1.000000e+004,3.097396e+002,6.101377e-004,0.000000e+000,3,9.605209e-001,0.000000e+000,,,,,,,,,,,,,,24,1,4.000000e+000,4.916992e-001,0.000000e+000,0,,0,
1575745966.156,,1.000000e+004,3.067137e+002,6.155128e-004,0.000000e+000,3,9.614046e-001,0.000000e+000,,,,,,,,,,,,,,24,1,4.000000e+000,4.808960e-001,0.000000e+000,0,,0,
1575746057.328,,1.000000e+004,3.037185e+002,6.215516e-004,0.000000e+000,3,9.620145e-001,0.000000e+000,,,,,,,,,,,,,,24,1,4.000000e+000,5.227966e-001,0.000000e+000,0,,0,
1575746146.468,,1.000000e+004,3.007325e+002,6.279803e-004,0.000000e+000,3,9.611125e-001,0.000000e+000,,,,,,,,,,,,,,24,1,4.000000e+000,5.028992e-001,0.000000e+000,0,,0,
1575746236.687,,1.000000e+004,2.977200e+002,6.347084e-004,0.000000e+000,3,9.630260e-001,0.000000e+000,,,,,,,,,,,,,,24,1,4.000000e+000,5.498962e-001,0.000000e+000,0,,0,
1575746327.312,,1.000000e+004,2.946979e+002,6.410845e-004,0.000000e+000,3,9.625992e-001,0.000000e+000,,,,,,,,,,,,,,24,1,4.000000e+000,4.643250e-001,0.000000e+000,0,,0,
1575746415.718,,1.000000e+004,2.917415e+002,6.481166e-004,0.000000e+000,3,9.632181e-001,0.000000e+000,,,,,,,,,,,,,,24,1,4.000000e+000,5.019836e-001,0.000000e+000,0,,0,
1575746504.437,,1.000000e+004,2.887478e+002,6.546210e-004,0.000000e+000,3,9.637123e-001,0.000000e+000,,,,,,,,,,,,,,24,1,4.000000e+000,4.907837e-001,0.000000e+000,0,,0,
1575746595.328,,1.000000e+004,2.857406e+002,6.613162e-004,0.000000e+000,3,9.630089e-001,0.000000e+000,,,,,,,,,,,,,,24,1,4.000000e+000,3.958130e-001,0.000000e+000,0,,0,
1575746685.890,,1.000000e+004,2.827084e+002,6.679369e-004,0.000000e+000,3,9.629750e-001,0.000000e+000,,,,,,,,,,,,,,24,1,4.000000e+000,4.610901e-001,0.000000e+000,0,,0,
1575746775.468,,1.000000e+004,2.797315e+002,6.757430e-004,0.000000e+000,3,9.634176e-001,0.000000e+000,,,,,,,,,,,,,,24,1,4.000000e+000,4.939880e-001,0.000000e+000,0,,0,
1575746864.906,,1.000000e+004,2.767162e+002,6.824739e-004,0.000000e+000,3,9.644802e-001,0.000000e+000,,,,,,,,,,,,,,24,1,4.000000e+000,4.965210e-001,0.000000e+000,0,,0,
1575746954.046,,1.000000e+004,2.736990e+002,6.899251e-004,0.000000e+000,3,9.647546e-001,0.000000e+000,,,,,,,,,,,,,,24,1,4.000000e+000,4.638977e-001,0.000000e+000,0,,0,
1575747042.328,,1.000000e+004,2.707299e+002,6.975631e-004,0.000000e+000,3,9.641290e-001,0.000000e+000,,,,,,,,,,,,,,24,1,4.000000e+000,4.258118e-001,0.000000e+000,0,,0,
1575747131.484,,1.000000e+004,2.677652e+002,7.062697e-004,0.000000e+000,3,9.637412e-001,0.000000e+000,,,,,,,,,,,,,,24,1,4.000000e+000,4.288025e-001,0.000000e+000,0,,0,
1575747221.984,,1.000000e+004,2.647267e+002,7.143552e-004,0.000000e+000,3,9.644372e-001,0.000000e+000,,,,,,,,,,,,,,24,1,4.000000e+000,4.502258e-001,0.000000e+000,0,,0,
1575747311.531,,1.000000e+004,2.617764e+002,7.226701e-004,0.000000e+000,3,9.640030e-001,0.000000e+000,,,,,,,,,,,,,,24,1,4.000000e+000,4.328918e-001,0.000000e+000,0,,0,
1575747400.921,,1.000000e+004,2.587389e+002,7.309419e-004,0.000000e+000,3,9.642081e-001,0.000000e+000,,,,,,,,,,,,,,24,1,4.000000e+000,4.469910e-001,0.000000e+000,0,,0,
1575747488.984,,1.000000e+004,2.557525e+002,7.397892e-004,0.000000e+000,3,9.656259e-001,0.000000e+000,,,,,,,,,,,,,,24,1,4.000000e+000,4.423981e-001,0.000000e+000,0,,0,
1575747578.656,,1.000000e+004,2.527462e+002,7.486310e-004,0.000000e+000,3,9.657171e-001,0.000000e+000,,,,,,,,,,,,,,24,1,4.000000e+000,4.783936e-001,0.000000e+000,0,,0,
1575747668.828,,1.000000e+004,2.497383e+002,7.578924e-004,0.000000e+000,3,9.661638e-001,0.000000e+000,,,,,,,,,,,,,,24,1,4.000000e+000,4.324951e-001,0.000000e+000,0,,0,
1575747757.515,,1.000000e+004,2.467675e+002,7.662884e-004,0.000000e+000,3,9.658014e-001,0.000000e+000,,,,,,,,,,,,,,24,1,4.000000e+000,4.385986e-001,0.000000e+000,0,,0,
1575747848.000,,1.000000e+004,2.437339e+002,7.751152e-004,0.000000e+000,3,9.659271e-001,0.000000e+000,,,,,,,,,,,,,,24,1,4.000000e+000,5.194092e-001,0.000000e+000,0,,0,
1575747936.718,,1.000000e+004,2.407581e+002,7.851883e-004,0.000000e+000,3,9.666053e-001,0.000000e+000,,,,,,,,,,,,,,24,1,4.000000e+000,4.641113e-001,0.000000e+000,0,,0,
1575748026.812,,1.000000e+004,2.377490e+002,7.951554e-004,0.000000e+000,3,9.665934e-001,0.000000e+000,,,,,,,,,,,,,,24,1,4.000000e+000,4.521942e-001,0.000000e+000,0,,0,
1575748115.375,,1.000000e+004,2.347520e+002,8.056766e-004,0.000000e+000,3,9.668013e-001,0.000000e+000,,,,,,,,,,,,,,24,1,4.000000e+000,4.403992e-001,0.000000e+000,0,,0,
1575748205.703,,1.000000e+004,2.317506e+002,8.159480e-004,0.000000e+000,3,9.666638e-001,0.000000e+000,,,,,,,,,,,,,,24,1,4.000000e+000,4.727020e-001,0.000000e+000,0,,0,
1575748297.265,,1.000000e+004,2.287111e+002,8.270639e-004,0.000000e+000,3,9.671057e-001,0.000000e+000,,,,,,,,,,,,,,24,1,4.000000e+000,5.214996e-001,0.000000e+000,0,,0,
1575748386.109,,1.000000e+004,2.257395e+002,8.382780e-004,0.000000e+000,3,9.671012e-001,0.000000e+000,,,,,,,,,,,,,,24,1,4.000000e+000,4.290009e-001,0.000000e+000,0,,0,
1575748475.453,,1.000000e+004,2.227399e+002,8.493458e-004,0.000000e+000,3,9.682997e-001,0.000000e+000,,,,,,,,,,,,,,24,1,4.000000e+000,4.306030e-001,0.000000e+000,0,,0,
1575748565.828,,1.000000e+004,2.197307e+002,8.609195e-004,0.000000e+000,3,9.677475e-001,0.000000e+000,,,,,,,,,,,,,,24,1,4.000000e+000,4.053955e-001,0.000000e+000,0,,0,
1575748655.656,,1.000000e+004,2.167355e+002,8.723645e-004,0.000000e+000,3,9.685138e-001,0.000000e+000,,,,,,,,,,,,,,24,1,4.000000e+000,4.701996e-001,0.000000e+000,0,,0,
1575748743.750,,1.000000e+004,2.137502e+002,8.841912e-004,0.000000e+000,3,9.686676e-001,0.000000e+000,,,,,,,,,,,,,,24,1,4.000000e+000,4.156952e-001,0.000000e+000,0,,0,
1575748834.656,,1.000000e+004,2.107759e+002,8.964940e-004,0.000000e+000,3,9.691539e-001,0.000000e+000,,,,,,,,,,,,,,24,1,4.000000e+000,4.394989e-001,0.000000e+000,0,,0,
1575748924.468,,1.000000e+004,2.077591e+002,9.090973e-004,0.000000e+000,3,9.690984e-001,0.000000e+000,,,,,,,,,,,,,,24,1,4.000000e+000,4.148102e-001,0.000000e+000,0,,0,
1575749015.734,,1.000000e+004,2.047372e+002,9.223233e-004,0.000000e+000,3,9.692618e-001,0.000000e+000,,,,,,,,,,,,,,24,1,4.000000e+000,4.060974e-001,0.000000e+000,0,,0,
1575749103.640,,1.000000e+004,2.017876e+002,9.353999e-004,0.000000e+000,3,9.696742e-001,0.000000e+000,,,,,,,,,,,,,,24,1,4.000000e+000,4.162903e-001,0.000000e+000,0,,0,
1575749195.515,,1.000000e+004,1.987246e+002,9.500501e-004,0.000000e+000,3,9.696574e-001,0.000000e+000,,,,,,,,,,,,,,24,1,4.000000e+000,4.601898e-001,0.000000e+000,0,,0,
1575749284.203,,1.000000e+004,1.957682e+002,9.636587e-004,0.000000e+000,3,9.700345e-001,0.000000e+000,,,,,,,,,,,,,,24,1,4.000000e+000,4.188995e-001,0.000000e+000,0,,0,
1575749374.875,,1.000000e+004,1.927301e+002,9.783083e-004,0.000000e+000,3,9.702827e-001,0.000000e+000,,,,,,,,,,,,,,24,1,4.000000e+000,4.923096e-001,0.000000e+000,0,,0,
1575749464.437,,1.000000e+004,1.897476e+002,9.941211e-004,0.000000e+000,3,9.704461e-001,0.000000e+000,,,,,,,,,,,,,,24,1,4.000000e+000,4.705048e-001,0.000000e+000,0,,0,
1575749555.437,,1.000000e+004,1.866997e+002,1.009304e-003,0.000000e+000,3,9.716718e-001,0.000000e+000,,,,,,,,,,,,,,24,1,4.000000e+000,4.958038e-001,0.000000e+000,0,,0,
1575749644.375,,1.000000e+004,1.837663e+002,1.025312e-003,0.000000e+000,3,9.712225e-001,0.000000e+000,,,,,,,,,,,,,,24,1,4.000000e+000,4.197083e-001,0.000000e+000,0,,0,
1575749734.843,,1.000000e+004,1.807417e+002,1.041877e-003,0.000000e+000,3,9.718758e-001,0.000000e+000,,,,,,,,,,,,,,24,1,4.000000e+000,4.320984e-001,0.000000e+000,0,,0,
1575749824.906,,1.000000e+004,1.777373e+002,1.059843e-003,0.000000e+000,3,9.718631e-001,0.000000e+000,,,,,,,,,,,,,,24,1,4.000000e+000,5.077972e-001,0.000000e+000,0,,0,
1575749914.656,,1.000000e+004,1.747101e+002,1.077695e-003,0.000000e+000,3,9.719065e-001,0.000000e+000,,,,,,,,,,,,,,24,1,4.000000e+000,5.012970e-001,0.000000e+000,0,,0,
1575750002.031,,1.000000e+004,1.717780e+002,1.095834e-003,0.000000e+000,3,9.717989e-001,0.000000e+000,,,,,,,,,,,,,,24,1,4.000000e+000,4.158020e-001,0.000000e+000,0,,0,
1575750093.687,,1.000000e+004,1.687339e+002,1.116040e-003,0.000000e+000,3,9.724871e-001,0.000000e+000,,,,,,,,,,,,,,24,1,4.000000e+000,5.227051e-001,0.000000e+000,0,,0,
1575750182.781,,1.000000e+004,1.657535e+002,1.137699e-003,0.000000e+000,3,9.718750e-001,0.000000e+000,,,,,,,,,,,,,,24,1,4.000000e+000,4.550934e-001,0.000000e+000,0,,0,
1575750273.734,,1.000000e+004,1.626947e+002,1.158831e-003,0.000000e+000,3,9.716359e-001,0.000000e+000,,,,,,,,,,,,,,24,1,4.000000e+000,4.664917e-001,0.000000e+000,0,,0,
1575750363.562,,1.000000e+004,1.597493e+002,1.179183e-003,0.000000e+000,3,9.716960e-001,0.000000e+000,,,,,,,,,,,,,,24,1,4.000000e+000,4.222107e-001,0.000000e+000,0,,0,
1575750452.328,,1.000000e+004,1.567357e+002,1.201271e-003,0.000000e+000,3,9.724819e-001,0.000000e+000,,,,,,,,,,,,,,24,1,4.000000e+000,3.933105e-001,0.000000e+000,0,,0,
1575750540.062,,1.000000e+004,1.537459e+002,1.224244e-003,0.000000e+000,3,9.722855e-001,0.000000e+000,,,,,,,,,,,,,,24,1,4.000000e+000,4.077911e-001,0.000000e+000,0,,0,
1575750629.000,,1.000000e+004,1.507732e+002,1.248439e-003,0.000000e+000,3,9.729435e-001,0.000000e+000,,,,,,,,,,,,,,24,1,4.000000e+000,3.921967e-001,0.000000e+000,0,,0,
1575750718.062,,1.000000e+004,1.477894e+002,1.272813e-003,0.000000e+000,3,9.725723e-001,0.000000e+000,,,,,,,,,,,,,,24,1,4.000000e+000,4.078064e-001,0.000000e+000,0,,0,
1575750808.343,,1.000000e+004,1.447186e+002,1.299511e-003,0.000000e+000,3,9.729010e-001,0.000000e+000,,,,,,,,,,,,,,24,1,4.000000e+000,4.617004e-001,0.000000e+000,0,,0,
1575750897.171,,1.000000e+004,1.417682e+002,1.326309e-003,0.000000e+000,3,9.731459e-001,0.000000e+000,,,,,,,,,,,,,,24,1,4.000000e+000,4.073944e-001,0.000000e+000,0,,0,
1575751065.703,,1.000000e+004,1.387698e+002,1.353806e-003,0.000000e+000,3,9.734938e-001,0.000000e+000,,,,,,,,,,,,,,24,1,4.000000e+000,4.521942e-001,0.000000e+000,0,,0,
1575751156.187,,1.000000e+004,1.357416e+002,1.383959e-003,0.000000e+000,3,9.737509e-001,0.000000e+000,,,,,,,,,,,,,,24,1,4.000000e+000,4.492950e-001,0.000000e+000,0,,0,
1575751244.781,,1.000000e+004,1.327488e+002,1.413943e-003,0.000000e+000,3,9.737240e-001,0.000000e+000,,,,,,,,,,,,,,24,1,4.000000e+000,4.423981e-001,0.000000e+000,0,,0,
1575751333.890,,1.000000e+004,1.297426e+002,1.446693e-003,0.000000e+000,3,9.738730e-001,0.000000e+000,,,,,,,,,,,,,,24,1,4.000000e+000,4.468079e-001,0.000000e+000,0,,0,
1575751421.281,,1.000000e+004,1.267731e+002,1.478653e-003,0.000000e+000,3,9.740202e-001,0.000000e+000,,,,,,,,,,,,,,24,1,4.000000e+000,4.102020e-001,0.000000e+000,0,,0,
1575751510.843,,1.000000e+004,1.237556e+002,1.512932e-003,0.000000e+000,3,9.743249e-001,0.000000e+000,,,,,,,,,,,,,,24,1,4.000000e+000,4.098053e-001,0.000000e+000,0,,0,
1575751598.625,,1.000000e+004,1.207655e+002,1.552424e-003,0.000000e+000,3,9.739473e-001,0.000000e+000,,,,,,,,,,,,,,24,1,4.000000e+000,4.635010e-001,0.000000e+000,0,,0,
1575751688.406,,1.000000e+004,1.177552e+002,1.591250e-003,0.000000e+000,3,9.743210e-001,0.000000e+000,,,,,,,,,,,,,,24,1,4.000000e+000,4.212952e-001,0.000000e+000,0,,0,
1575751776.000,,1.000000e+004,1.147603e+002,1.631505e-003,0.000000e+000,3,9.745597e-001,0.000000e+000,,,,,,,,,,,,,,24,1,4.000000e+000,4.216995e-001,0.000000e+000,0,,0,
1575751863.156,,1.000000e+004,1.117661e+002,1.673631e-003,0.000000e+000,3,9.744890e-001,0.000000e+000,,,,,,,,,,,,,,24,1,4.000000e+000,4.293976e-001,0.000000e+000,0,,0,
1575751950.671,,1.000000e+004,1.087579e+002,1.718433e-003,0.000000e+000,3,9.745591e-001,0.000000e+000,,,,,,,,,,,,,,24,1,4.000000e+000,3.896942e-001,0.000000e+000,0,,0,
1575752039.046,,1.000000e+004,1.057766e+002,1.846307e-003,0.000000e+000,3,9.671382e-001,0.000000e+000,,,,,,,,,,,,,,24,1,4.000000e+000,3.848038e-001,0.000000e+000,0,,0,
1575752126.031,,1.000000e+004,1.027682e+002,1.814553e-003,0.000000e+000,3,9.747489e-001,0.000000e+000,,,,,,,,,,,,,,24,1,4.000000e+000,4.389038e-001,0.000000e+000,0,,0,
1575752213.046,,1.000000e+004,9.974641e+001,1.866900e-003,0.000000e+000,3,9.755916e-001,0.000000e+000,,,,,,,,,,,,,,24,1,4.000000e+000,4.430161e-001,0.000000e+000,0,,0,
1575752299.406,,1.000000e+004,9.675790e+001,1.924644e-003,0.000000e+000,3,9.753559e-001,0.000000e+000,,,,,,,,,,,,,,24,1,4.000000e+000,4.514465e-001,0.000000e+000,0,,0,
1575752385.500,,1.000000e+004,9.375777e+001,1.983738e-003,0.000000e+000,3,9.751815e-001,0.000000e+000,,,,,,,,,,,,,,24,1,4.000000e+000,4.445419e-001,0.000000e+000,0,,0,
1575752471.062,,1.000000e+004,9.078064e+001,2.046508e-003,0.000000e+000,3,9.756209e-001,0.000000e+000,,,,,,,,,,,,,,24,1,4.000000e+000,4.051132e-001,0.000000e+000,0,,0,
1575752557.265,,1.000000e+004,8.776085e+001,2.113547e-003,0.000000e+000,3,9.753575e-001,0.000000e+000,,,,,,,,,,,,,,24,1,4.000000e+000,4.671707e-001,0.000000e+000,0,,0,
1575752642.390,,1.000000e+004,8.475705e+001,2.186730e-003,0.000000e+000,3,9.761488e-001,0.000000e+000,,,,,,,,,,,,,,24,1,4.000000e+000,4.151993e-001,0.000000e+000,0,,0,
1575752726.625,,1.000000e+004,8.175685e+001,2.264823e-003,0.000000e+000,3,9.761203e-001,0.000000e+000,,,,,,,,,,,,,,24,1,4.000000e+000,4.247971e-001,0.000000e+000,0,,0,
1575752810.281,,1.000000e+004,7.873692e+001,2.348377e-003,0.000000e+000,3,9.761343e-001,0.000000e+000,,,,,,,,,,,,,,24,1,4.000000e+000,4.408264e-001,0.000000e+000,0,,0,
1575752892.500,,1.000000e+004,7.576935e+001,2.435868e-003,0.000000e+000,3,9.762127e-001,0.000000e+000,,,,,,,,,,,,,,24,1,4.000000e+000,3.896561e-001,0.000000e+000,0,,0,
1575752975.203,,1.000000e+004,7.279364e+001,2.531429e-003,0.000000e+000,3,9.765221e-001,0.000000e+000,,,,,,,,,,,,,,24,1,4.000000e+000,4.033661e-001,0.000000e+000,0,,0,
1575753056.812,,1.000000e+004,6.975217e+001,2.635420e-003,0.000000e+000,3,9.766424e-001,0.000000e+000,,,,,,,,,,,,,,24,1,4.000000e+000,4.558868e-001,0.000000e+000,0,,0,
1575753137.484,,1.000000e+004,6.675636e+001,2.746843e-003,0.000000e+000,3,9.767734e-001,0.000000e+000,,,,,,,,,,,,,,24,1,4.000000e+000,4.110413e-001,0.000000e+000,0,,0,
1575753216.625,,1.000000e+004,6.376919e+001,2.870990e-003,0.000000e+000,3,9.767099e-001,0.000000e+000,,,,,,,,,,,,,,24,1,4.000000e+000,4.026833e-001,0.000000e+000,0,,0,
1575753297.156,,1.000000e+004,6.072402e+001,3.004496e-003,0.000000e+000,3,9.772654e-001,0.000000e+000,,,,,,,,,,,,,,24,1,4.000000e+000,4.323387e-001,0.000000e+000,0,,0,
1575753374.390,,1.000000e+004,5.773668e+001,3.150901e-003,0.000000e+000,3,9.773821e-001,0.000000e+000,,,,,,,,,,,,,,24,1,4.000000e+000,4.725418e-001,0.000000e+000,0,,0,
1575753454.765,,1.000000e+004,5.476842e+001,3.311498e-003,0.000000e+000,3,9.773613e-001,0.000000e+000,,,,,,,,,,,,,,24,1,4.000000e+000,3.912010e-001,0.000000e+000,0,,0,
1575753540.531,,1.000000e+004,5.180241e+001,3.487361e-003,0.000000e+000,3,9.773223e-001,0.000000e+000,,,,,,,,,,,,,,24,1,4.000000e+000,3.888092e-001,0.000000e+000,0,,0,
1575753627.937,,1.000000e+004,4.876269e+001,3.761932e-003,0.000000e+000,3,9.793397e-001,0.000000e+000,,,,,,,,,,,,,,24,1,4.000000e+000,3.508797e-001,0.000000e+000,0,,0,
1575753713.796,,1.000000e+004,4.581575e+001,3.914086e-003,0.000000e+000,3,9.777642e-001,0.000000e+000,,,,,,,,,,,,,,24,1,4.000000e+000,3.624001e-001,0.000000e+000,0,,0,
1575753800.343,,1.000000e+004,4.280084e+001,4.168264e-003,0.000000e+000,3,9.781755e-001,0.000000e+000,,,,,,,,,,,,,,24,1,4.000000e+000,3.490105e-001,0.000000e+000,0,,0,
1575753885.390,,1.000000e+004,3.978957e+001,4.461369e-003,0.000000e+000,3,9.781553e-001,0.000000e+000,,,,,,,,,,,,,,24,1,4.000000e+000,3.134689e-001,0.000000e+000,0,,0,
1575753969.296,,1.000000e+004,3.679459e+001,4.798409e-003,0.000000e+000,3,9.784972e-001,0.000000e+000,,,,,,,,,,,,,,24,1,4.000000e+000,3.672180e-001,0.000000e+000,0,,0,
1575754053.296,,1.000000e+004,3.378686e+001,5.191258e-003,0.000000e+000,3,9.784911e-001,0.000000e+000,,,,,,,,,,,,,,24,1,4.000000e+000,3.364220e-001,0.000000e+000,0,,0,
1575754135.812,,1.000000e+004,3.077768e+001,5.654975e-003,0.000000e+000,3,9.786737e-001,0.000000e+000,,,,,,,,,,,,,,24,1,4.000000e+000,4.021893e-001,0.000000e+000,0,,0,
1575754217.453,,1.000000e+004,2.775315e+001,6.218504e-003,0.000000e+000,3,9.787796e-001,0.000000e+000,,,,,,,,,,,,,,24,1,4.000000e+000,4.210091e-001,0.000000e+000,0,,0,
1575754297.203,,1.000000e+004,2.470054e+001,6.914054e-003,0.000000e+000,3,9.789235e-001,0.000000e+000,,,,,,,,,,,,,,24,1,4.000000e+000,4.278202e-001,0.000000e+000,0,,0,
1575754384.671,,1.000000e+004,2.179147e+001,7.733252e-003,0.000000e+000,3,9.788285e-001,0.000000e+000,,,,,,,,,,,,,,24,1,4.000000e+000,3.553295e-001,0.000000e+000,0,,0,
1575754472.234,,1.000000e+004,1.879754e+001,8.825171e-003,0.000000e+000,3,9.788987e-001,0.000000e+000,,,,,,,,,,,,,,24,1,4.000000e+000,3.767796e-001,0.000000e+000,0,,0,
1575754560.328,,1.000000e+004,1.577868e+001,1.027523e-002,0.000000e+000,3,9.788874e-001,0.000000e+000,,,,,,,,,,,,,,24,1,4.000000e+000,3.903599e-001,0.000000e+000,0,,0,
1575754646.937,,1.000000e+004,1.273001e+001,1.220594e-002,0.000000e+000,3,9.769867e-001,0.000000e+000,,,,,,,,,,,,,,24,1,4.000000e+000,3.803005e-001,0.000000e+000,0,,0,
1575754734.406,,1.000000e+004,9.814501e+000,1.519047e-002,0.000000e+000,3,9.790336e-001,0.000000e+000,,,,,,,,,,,,,,24,1,4.000000e+000,2.774162e-001,0.000000e+000,0,,0,
1575754839.156,,1.000000e+004,6.889283e+000,2.034731e-002,0.000000e+000,3,9.792739e-001,0.000000e+000,,,,,,,,,,,,,,24,1,4.000000e+000,1.675172e-001,0.000000e+000,0,,0,
1575754937.281,,1.000000e+004,3.807235e+000,3.091191e-002,0.000000e+000,3,9.789220e-001,0.000000e+000,,,,,,,,,,,,,,24,1,4.000000e+000,3.368530e-001,0.000000e+000,0,,0,
1575758365.203,,1.000000e+003,3.500047e+002,5.526136e-005,0.000000e+000,3,9.376586e-001,0.000000e+000,,,,,,,,,,,,,,24,1,4.000000e+000,1.202393e-002,0.000000e+000,0,,0,
1575758531.046,,1.000000e+003,3.468432e+002,5.474675e-005,0.000000e+000,3,9.360686e-001,0.000000e+000,,,,,,,,,,,,,,24,1,4.000000e+000,2.573853e-001,0.000000e+000,0,,0,
1575758625.953,,1.000000e+003,3.437100e+002,5.493619e-005,0.000000e+000,3,9.281065e-001,0.000000e+000,,,,,,,,,,,,,,24,1,4.000000e+000,4.931946e-001,0.000000e+000,0,,0,
1575758701.218,,1.000000e+003,3.407062e+002,5.650273e-005,0.000000e+000,3,9.329113e-001,0.000000e+000,,,,,,,,,,,,,,24,1,4.000000e+000,4.499207e-001,0.000000e+000,0,,0,
1575758787.750,,1.000000e+003,3.377714e+002,5.729999e-005,0.000000e+000,3,9.439322e-001,0.000000e+000,,,,,,,,,,,,,,24,1,4.000000e+000,4.082031e-001,0.000000e+000,0,,0,
1575758887.671,,1.000000e+003,3.348029e+002,5.830261e-005,0.000000e+000,3,9.416224e-001,0.000000e+000,,,,,,,,,,,,,,24,1,4.000000e+000,3.786011e-001,0.000000e+000,0,,0,
1575758988.203,,1.000000e+003,3.317620e+002,5.807911e-005,0.000000e+000,3,9.478573e-001,0.000000e+000,,,,,,,,,,,,,,24,1,4.000000e+000,4.134827e-001,0.000000e+000,0,,0,
1575759083.640,,1.000000e+003,3.287604e+002,5.858611e-005,0.000000e+000,3,9.392427e-001,0.000000e+000,,,,,,,,,,,,,,24,1,4.000000e+000,4.468079e-001,0.000000e+000,0,,0,
1575759174.375,,1.000000e+003,3.257366e+002,5.988360e-005,0.000000e+000,3,9.310511e-001,0.000000e+000,,,,,,,,,,,,,,24,1,4.000000e+000,4.987793e-001,0.000000e+000,0,,0,
1575759265.671,,1.000000e+003,3.227584e+002,5.997124e-005,0.000000e+000,3,9.425848e-001,0.000000e+000,,,,,,,,,,,,,,24,1,4.000000e+000,4.590149e-001,0.000000e+000,0,,0,
1575759357.437,,1.000000e+003,3.197519e+002,6.021467e-005,0.000000e+000,3,9.403386e-001,0.000000e+000,,,,,,,,,,,,,,24,1,4.000000e+000,4.396973e-001,0.000000e+000,0,,0,
1575759449.046,,1.000000e+003,3.167493e+002,6.124596e-005,0.000000e+000,3,9.437461e-001,0.000000e+000,,,,,,,,,,,,,,24,1,4.000000e+000,4.211121e-001,0.000000e+000,0,,0,
1575759540.546,,1.000000e+003,3.137244e+002,6.158836e-005,0.000000e+000,3,9.399124e-001,0.000000e+000,,,,,,,,,,,,,,24,1,4.000000e+000,5.151978e-001,0.000000e+000,0,,0,
1575759631.390,,1.000000e+003,3.107354e+002,6.181905e-005,0.000000e+000,3,9.400753e-001,0.000000e+000,,,,,,,,,,,,,,24,1,4.000000e+000,4.767761e-001,0.000000e+000,0,,0,
1575759720.390,,1.000000e+003,3.077375e+002,6.326920e-005,0.000000e+000,3,9.412819e-001,0.000000e+000,,,,,,,,,,,,,,24,1,4.000000e+000,4.757080e-001,0.000000e+000,0,,0,
1575759810.218,,1.000000e+003,3.047505e+002,6.240239e-005,0.000000e+000,3,9.425619e-001,0.000000e+000,,,,,,,,,,,,,,24,1,4.000000e+000,4.389954e-001,0.000000e+000,0,,0,
1575759902.000,,1.000000e+003,3.017462e+002,6.305463e-005,0.000000e+000,3,9.428966e-001,0.000000e+000,,,,,,,,,,,,,,24,1,4.000000e+000,4.466248e-001,0.000000e+000,0,,0,
1575759991.265,,1.000000e+003,2.987697e+002,6.406997e-005,0.000000e+000,3,9.433599e-001,0.000000e+000,,,,,,,,,,,,,,24,1,4.000000e+000,3.947144e-001,0.000000e+000,0,,0,
1575760082.625,,1.000000e+003,2.957365e+002,6.527641e-005,0.000000e+000,3,9.431934e-001,0.000000e+000,,,,,,,,,,,,,,24,1,4.000000e+000,5.006714e-001,0.000000e+000,0,,0,
1575760172.890,,1.000000e+003,2.927211e+002,6.586397e-005,0.000000e+000,3,9.446220e-001,0.000000e+000,,,,,,,,,,,,,,24,1,4.000000e+000,4.494934e-001,0.000000e+000,0,,0,
1575760260.937,,1.000000e+003,2.897094e+002,6.681240e-005,0.000000e+000,3,9.434149e-001,0.000000e+000,,,,,,,,,,,,,,24,1,4.000000e+000,4.472046e-001,0.000000e+000,0,,0,
1575760351.562,,1.000000e+003,2.867227e+002,6.680856e-005,0.000000e+000,3,9.451530e-001,0.000000e+000,,,,,,,,,,,,,,24,1,4.000000e+000,5.292969e-001,0.000000e+000,0,,0,
1575760441.171,,1.000000e+003,2.837275e+002,6.849987e-005,0.000000e+000,3,9.468758e-001,0.000000e+000,,,,,,,,,,,,,,24,1,4.000000e+000,4.872131e-001,0.000000e+000,0,,0,
1575760531.593,,1.000000e+003,2.807124e+002,6.906034e-005,0.000000e+000,3,9.491634e-001,0.000000e+000,,,,,,,,,,,,,,24,1,4.000000e+000,4.320068e-001,0.000000e+000,0,,0,
1575760619.296,,1.000000e+003,2.777706e+002,6.976995e-005,0.000000e+000,3,9.508154e-001,0.000000e+000,,,,,,,,,,,,,,24,1,4.000000e+000,4.435120e-001,0.000000e+000,0,,0,
1575760710.562,,1.000000e+003,2.747455e+002,7.028536e-005,0.000000e+000,3,9.477048e-001,0.000000e+000,,,,,,,,,,,,,,24,1,4.000000e+000,4.328918e-001,0.000000e+000,0,,0,
1575760799.000,,1.000000e+003,2.717684e+002,7.045202e-005,0.000000e+000,3,9.448038e-001,0.000000e+000,,,,,,,,,,,,,,24,1,4.000000e+000,4.430847e-001,0.000000e+000,0,,0,
1575760889.703,,1.000000e+003,2.687654e+002,7.216612e-005,0.000000e+000,3,9.500595e-001,0.000000e+000,,,,,,,,,,,,,,24,1,4.000000e+000,4.191284e-001,0.000000e+000,0,,0,
1575760980.781,,1.000000e+003,2.657278e+002,7.302248e-005,0.000000e+000,3,9.498393e-001,0.000000e+000,,,,,,,,,,,,,,24,1,4.000000e+000,4.798889e-001,0.000000e+000,0,,0,
1575761072.750,,1.000000e+003,2.627275e+002,7.398141e-005,0.000000e+000,3,9.483997e-001,0.000000e+000,,,,,,,,,,,,,,24,1,4.000000e+000,4.867859e-001,0.000000e+000,0,,0,
1575761161.828,,1.000000e+003,2.597320e+002,7.478239e-005,0.000000e+000,3,9.475713e-001,0.000000e+000,,,,,,,,,,,,,,24,1,4.000000e+000,4.692078e-001,0.000000e+000,0,,0,
1575761249.656,,1.000000e+003,2.567371e+002,7.577449e-005,0.000000e+000,3,9.521918e-001,0.000000e+000,,,,,,,,,,,,,,24,1,4.000000e+000,5.182800e-001,0.000000e+000,0,,0,
1575761340.078,,1.000000e+003,2.537039e+002,7.681026e-005,0.000000e+000,3,9.492301e-001,0.000000e+000,,,,,,,,,,,,,,24,1,4.000000e+000,4.998016e-001,0.000000e+000,0,,0,
1575761427.890,,1.000000e+003,2.507728e+002,7.760304e-005,0.000000e+000,3,9.512501e-001,0.000000e+000,,,,,,,,,,,,,,24,1,4.000000e+000,4.363098e-001,0.000000e+000,0,,0,
1575761517.625,,1.000000e+003,2.477654e+002,7.782740e-005,0.000000e+000,3,9.489804e-001,0.000000e+000,,,,,,,,,,,,,,24,1,4.000000e+000,4.421997e-001,0.000000e+000,0,,0,
1575761608.546,,1.000000e+003,2.447501e+002,7.923513e-005,0.000000e+000,3,9.541559e-001,0.000000e+000,,,,,,,,,,,,,,24,1,4.000000e+000,4.474945e-001,0.000000e+000,0,,0,
1575761697.640,,1.000000e+003,2.417460e+002,8.006788e-005,0.000000e+000,3,9.518135e-001,0.000000e+000,,,,,,,,,,,,,,24,1,4.000000e+000,4.735107e-001,0.000000e+000,0,,0,
1575761860.828,,1.000000e+003,2.387528e+002,8.102215e-005,0.000000e+000,3,9.476701e-001,0.000000e+000,,,,,,,,,,,,,,24,1,4.000000e+000,4.405975e-001,0.000000e+000,0,,0,
1575761949.765,,1.000000e+003,2.358053e+002,8.209430e-005,0.000000e+000,3,9.479554e-001,0.000000e+000,,,,,,,,,,,,,,24,1,4.000000e+000,3.890076e-001,0.000000e+000,0,,0,
1575762041.187,,1.000000e+003,2.327441e+002,8.278526e-005,0.000000e+000,3,9.538793e-001,0.000000e+000,,,,,,,,,,,,,,24,1,4.000000e+000,4.376068e-001,0.000000e+000,0,,0,
1575762129.359,,1.000000e+003,2.297970e+002,8.425209e-005,0.000000e+000,3,9.513034e-001,0.000000e+000,,,,,,,,,,,,,,24,1,4.000000e+000,4.021912e-001,0.000000e+000,0,,0,
1575762219.390,,1.000000e+003,2.267753e+002,8.510937e-005,0.000000e+000,3,9.532884e-001,0.000000e+000,,,,,,,,,,,,,,24,1,4.000000e+000,4.003906e-001,0.000000e+000,0,,0,
1575762309.734,,1.000000e+003,2.237538e+002,8.588562e-005,0.000000e+000,3,9.571571e-001,0.000000e+000,,,,,,,,,,,,,,24,1,4.000000e+000,4.618988e-001,0.000000e+000,0,,0,
1575762399.531,,1.000000e+003,2.207471e+002,8.790361e-005,0.000000e+000,3,9.554010e-001,0.000000e+000,,,,,,,,,,,,,,24,1,4.000000e+000,4.620972e-001,0.000000e+000,0,,0,
1575762490.015,,1.000000e+003,2.177721e+002,8.811909e-005,0.000000e+000,3,9.546580e-001,0.000000e+000,,,,,,,,,,,,,,24,1,4.000000e+000,4.364014e-001,0.000000e+000,0,,0,
1575762578.906,,1.000000e+003,2.147675e+002,8.951739e-005,0.000000e+000,3,9.547342e-001,0.000000e+000,,,,,,,,,,,,,,24,1,4.000000e+000,4.114990e-001,0.000000e+000,0,,0,
1575762669.640,,1.000000e+003,2.117477e+002,9.088809e-005,0.000000e+000,3,9.543464e-001,0.000000e+000,,,,,,,,,,,,,,24,1,4.000000e+000,4.519043e-001,0.000000e+000,0,,0,
1575762759.218,,1.000000e+003,2.087917e+002,9.178153e-005,0.000000e+000,3,9.530919e-001,0.000000e+000,,,,,,,,,,,,,,24,1,4.000000e+000,3.956909e-001,0.000000e+000,0,,0,
1575762851.015,,1.000000e+003,2.057272e+002,9.332823e-005,0.000000e+000,3,9.575083e-001,0.000000e+000,,,,,,,,,,,,,,24,1,4.000000e+000,3.948975e-001,0.000000e+000,0,,0,
1575762940.421,,1.000000e+003,2.028005e+002,9.473767e-005,0.000000e+000,3,9.552999e-001,0.000000e+000,,,,,,,,,,,,,,24,1,4.000000e+000,3.983917e-001,0.000000e+000,0,,0,
1575763031.093,,1.000000e+003,1.997619e+002,9.620870e-005,0.000000e+000,3,9.595530e-001,0.000000e+000,,,,,,,,,,,,,,24,1,4.000000e+000,4.685974e-001,0.000000e+000,0,,0,
1575763121.453,,1.000000e+003,1.967484e+002,9.753383e-005,0.000000e+000,3,9.592867e-001,0.000000e+000,,,,,,,,,,,,,,24,1,4.000000e+000,4.717102e-001,0.000000e+000,0,,0,
1575763209.562,,1.000000e+003,1.937953e+002,9.911115e-005,0.000000e+000,3,9.594275e-001,0.000000e+000,,,,,,,,,,,,,,24,1,4.000000e+000,3.934937e-001,0.000000e+000,0,,0,
1575763300.515,,1.000000e+003,1.907356e+002,1.012545e-004,0.000000e+000,3,9.617257e-001,0.000000e+000,,,,,,,,,,,,,,24,1,4.000000e+000,4.689941e-001,0.000000e+000,0,,0,
1575763390.359,,1.000000e+003,1.877534e+002,1.029806e-004,0.000000e+000,3,9.611115e-001,0.000000e+000,,,,,,,,,,,,,,24,1,4.000000e+000,4.826050e-001,0.000000e+000,0,,0,
1575763479.406,,1.000000e+003,1.847163e+002,1.041109e-004,0.000000e+000,3,9.587362e-001,0.000000e+000,,,,,,,,,,,,,,24,1,4.000000e+000,4.179993e-001,0.000000e+000,0,,0,
1575763568.578,,1.000000e+003,1.817812e+002,1.057833e-004,0.000000e+000,3,9.609224e-001,0.000000e+000,,,,,,,,,,,,,,24,1,4.000000e+000,4.311981e-001,0.000000e+000,0,,0,
1575763657.640,,1.000000e+003,1.787645e+002,1.076655e-004,0.000000e+000,3,9.597045e-001,0.000000e+000,,,,,,,,,,,,,,24,1,4.000000e+000,4.166870e-001,0.000000e+000,0,,0,
1575763747.156,,1.000000e+003,1.757431e+002,1.099656e-004,0.000000e+000,3,9.592226e-001,0.000000e+000,,,,,,,,,,,,,,24,1,4.000000e+000,4.577026e-001,0.000000e+000,0,,0,
1575763836.984,,1.000000e+003,1.727841e+002,1.111881e-004,0.000000e+000,3,9.614028e-001,0.000000e+000,,,,,,,,,,,,,,24,1,4.000000e+000,4.208069e-001,0.000000e+000,0,,0,
1575763927.140,,1.000000e+003,1.697371e+002,1.130311e-004,0.000000e+000,3,9.618545e-001,0.000000e+000,,,,,,,,,,,,,,24,1,4.000000e+000,4.211884e-001,0.000000e+000,0,,0,
1575764015.968,,1.000000e+003,1.667679e+002,1.150240e-004,0.000000e+000,3,9.581802e-001,0.000000e+000,,,,,,,,,,,,,,24,1,4.000000e+000,4.013977e-001,0.000000e+000,0,,0,
1575764106.828,,1.000000e+003,1.637452e+002,1.173223e-004,0.000000e+000,3,9.637515e-001,0.000000e+000,,,,,,,,,,,,,,24,1,4.000000e+000,4.965057e-001,0.000000e+000,0,,0,
1575764196.578,,1.000000e+003,1.607224e+002,1.194015e-004,0.000000e+000,3,9.621502e-001,0.000000e+000,,,,,,,,,,,,,,24,1,4.000000e+000,4.365997e-001,0.000000e+000,0,,0,
1575764285.734,,1.000000e+003,1.577718e+002,1.211667e-004,0.000000e+000,3,9.629932e-001,0.000000e+000,,,,,,,,,,,,,,24,1,4.000000e+000,3.940887e-001,0.000000e+000,0,,0,
1575764381.062,,1.000000e+003,1.544958e+002,1.236213e-004,0.000000e+000,3,9.635454e-001,0.000000e+000,,,,,,,,,,,,,,24,1,4.000000e+000,3.311005e-001,0.000000e+000,0,,0,
1575764464.093,,1.000000e+003,1.517560e+002,1.265169e-004,0.000000e+000,3,9.654369e-001,0.000000e+000,,,,,,,,,,,,,,24,1,4.000000e+000,4.586945e-001,0.000000e+000,0,,0,
1575764555.031,,1.000000e+003,1.487372e+002,1.283591e-004,0.000000e+000,3,9.635091e-001,0.000000e+000,,,,,,,,,,,,,,24,1,4.000000e+000,4.012909e-001,0.000000e+000,0,,0,
1575764643.734,,1.000000e+003,1.457423e+002,1.311434e-004,0.000000e+000,3,9.634078e-001,0.000000e+000,,,,,,,,,,,,,,24,1,4.000000e+000,4.456024e-001,0.000000e+000,0,,0,
1575764734.031,,1.000000e+003,1.427197e+002,1.335817e-004,0.000000e+000,3,9.652795e-001,0.000000e+000,,,,,,,,,,,,,,24,1,4.000000e+000,4.018860e-001,0.000000e+000,0,,0,
1575764822.109,,1.000000e+003,1.397686e+002,1.368690e-004,0.000000e+000,3,9.632459e-001,0.000000e+000,,,,,,,,,,,,,,24,1,4.000000e+000,4.412994e-001,0.000000e+000,0,,0,
1575764909.156,,1.000000e+003,1.367774e+002,1.400379e-004,0.000000e+000,3,9.647277e-001,0.000000e+000,,,,,,,,,,,,,,24,1,4.000000e+000,4.394989e-001,0.000000e+000,0,,0,
1575764998.796,,1.000000e+003,1.337397e+002,1.428022e-004,0.000000e+000,3,9.648373e-001,0.000000e+000,,,,,,,,,,,,,,24,1,4.000000e+000,4.140015e-001,0.000000e+000,0,,0,
1575765087.453,,1.000000e+003,1.307823e+002,1.459225e-004,0.000000e+000,3,9.655098e-001,0.000000e+000,,,,,,,,,,,,,,24,1,4.000000e+000,3.990936e-001,0.000000e+000,0,,0,
1575765175.843,,1.000000e+003,1.277926e+002,1.490372e-004,0.000000e+000,3,9.680440e-001,0.000000e+000,,,,,,,,,,,,,,24,1,4.000000e+000,4.045029e-001,0.000000e+000,0,,0,
1575765264.843,,1.000000e+003,1.247372e+002,1.517911e-004,0.000000e+000,3,9.686359e-001,0.000000e+000,,,,,,,,,,,,,,24,1,4.000000e+000,4.189987e-001,0.000000e+000,0,,0,
1575765352.562,,1.000000e+003,1.217657e+002,1.555005e-004,0.000000e+000,3,9.670558e-001,0.000000e+000,,,,,,,,,,,,,,24,1,4.000000e+000,4.605026e-001,0.000000e+000,0,,0,
1575765441.453,,1.000000e+003,1.187661e+002,1.596790e-004,0.000000e+000,3,9.678416e-001,0.000000e+000,,,,,,,,,,,,,,24,1,4.000000e+000,4.107971e-001,0.000000e+000,0,,0,
1575765529.328,,1.000000e+003,1.157666e+002,1.633108e-004,0.000000e+000,3,9.677634e-001,0.000000e+000,,,,,,,,,,,,,,24,1,4.000000e+000,3.786011e-001,0.000000e+000,0,,0,
1575765629.265,,1.000000e+003,1.123142e+002,1.677586e-004,0.000000e+000,3,9.673306e-001,0.000000e+000,,,,,,,,,,,,,,24,1,4.000000e+000,3.565979e-001,0.000000e+000,0,,0,
1575765704.859,,1.000000e+003,1.097757e+002,1.725106e-004,0.000000e+000,3,9.676145e-001,0.000000e+000,,,,,,,,,,,,,,24,1,4.000000e+000,4.273071e-001,0.000000e+000,0,,0,
1575765792.281,,1.000000e+003,1.067394e+002,1.771781e-004,0.000000e+000,3,9.684888e-001,0.000000e+000,,,,,,,,,,,,,,24,1,4.000000e+000,4.816055e-001,0.000000e+000,0,,0,
1575765879.890,,1.000000e+003,1.037519e+002,1.818218e-004,0.000000e+000,3,9.704748e-001,0.000000e+000,,,,,,,,,,,,,,24,1,4.000000e+000,4.358063e-001,0.000000e+000,0,,0,
1575765967.406,,1.000000e+003,1.007417e+002,1.870190e-004,0.000000e+000,3,9.684587e-001,0.000000e+000,,,,,,,,,,,,,,24,1,4.000000e+000,4.347000e-001,0.000000e+000,0,,0,
1575766052.125,,1.000000e+003,9.776849e+001,1.924752e-004,0.000000e+000,3,9.699714e-001,0.000000e+000,,,,,,,,,,,,,,24,1,4.000000e+000,4.437256e-001,0.000000e+000,0,,0,
1575766137.921,,1.000000e+003,9.474055e+001,1.985713e-004,0.000000e+000,3,9.710569e-001,0.000000e+000,,,,,,,,,,,,,,24,1,4.000000e+000,4.506302e-001,0.000000e+000,0,,0,
1575766223.703,,1.000000e+003,9.178362e+001,2.044036e-004,0.000000e+000,3,9.701077e-001,0.000000e+000,,,,,,,,,,,,,,24,1,4.000000e+000,4.049835e-001,0.000000e+000,0,,0,
1575766309.062,,1.000000e+003,8.877383e+001,2.114343e-004,0.000000e+000,3,9.701447e-001,0.000000e+000,,,,,,,,,,,,,,24,1,4.000000e+000,3.413696e-001,0.000000e+000,0,,0,
1575766394.750,,1.000000e+003,8.574051e+001,2.182846e-004,0.000000e+000,3,9.706334e-001,0.000000e+000,,,,,,,,,,,,,,24,1,4.000000e+000,4.248581e-001,0.000000e+000,0,,0,
1575766479.843,,1.000000e+003,8.272327e+001,2.254669e-004,0.000000e+000,3,9.723256e-001,0.000000e+000,,,,,,,,,,,,,,24,1,4.000000e+000,4.152069e-001,0.000000e+000,0,,0,
1575766562.937,,1.000000e+003,7.976765e+001,2.339797e-004,0.000000e+000,3,9.707827e-001,0.000000e+000,,,,,,,,,,,,,,24,1,4.000000e+000,4.432678e-001,0.000000e+000,0,,0,
1575766646.437,,1.000000e+003,7.676053e+001,2.427904e-004,0.000000e+000,3,9.716376e-001,0.000000e+000,,,,,,,,,,,,,,24,1,4.000000e+000,4.316635e-001,0.000000e+000,0,,0,
1575766728.515,,1.000000e+003,7.376842e+001,2.517844e-004,0.000000e+000,3,9.714817e-001,0.000000e+000,,,,,,,,,,,,,,24,1,4.000000e+000,4.396591e-001,0.000000e+000,0,,0,
1575766809.515,,1.000000e+003,7.078629e+001,2.620940e-004,0.000000e+000,3,9.722114e-001,0.000000e+000,,,,,,,,,,,,,,24,1,4.000000e+000,3.921814e-001,0.000000e+000,0,,0,
1575766890.671,,1.000000e+003,6.779677e+001,2.728691e-004,0.000000e+000,3,9.717295e-001,0.000000e+000,,,,,,,,,,,,,,24,1,4.000000e+000,3.992615e-001,0.000000e+000,0,,0,
1575766971.953,,1.000000e+003,6.478758e+001,2.847920e-004,0.000000e+000,3,9.735355e-001,0.000000e+000,,,,,,,,,,,,,,24,1,4.000000e+000,4.066696e-001,0.000000e+000,0,,0,
1575767052.437,,1.000000e+003,6.170300e+001,2.981295e-004,0.000000e+000,3,9.746876e-001,0.000000e+000,,,,,,,,,,,,,,24,1,4.000000e+000,4.643097e-001,0.000000e+000,0,,0,
1575767127.234,,1.000000e+003,5.878341e+001,3.123220e-004,0.000000e+000,3,9.734703e-001,0.000000e+000,,,,,,,,,,,,,,24,1,4.000000e+000,4.195786e-001,0.000000e+000,0,,0,
1575767209.015,,1.000000e+003,5.575576e+001,3.278196e-004,0.000000e+000,3,9.730885e-001,0.000000e+000,,,,,,,,,,,,,,24,1,4.000000e+000,4.356995e-001,0.000000e+000,0,,0,
1575767295.359,,1.000000e+003,5.276834e+001,3.447100e-004,0.000000e+000,3,9.748840e-001,0.000000e+000,,,,,,,,,,,,,,24,1,4.000000e+000,3.956413e-001,0.000000e+000,0,,0,
1575767381.468,,1.000000e+003,4.980598e+001,3.648763e-004,0.000000e+000,3,9.740835e-001,0.000000e+000,,,,,,,,,,,,,,24,1,4.000000e+000,3.449707e-001,0.000000e+000,0,,0,
1575767468.609,,1.000000e+003,4.676836e+001,3.863096e-004,0.000000e+000,3,9.753761e-001,0.000000e+000,,,,,,,,,,,,,,24,1,4.000000e+000,4.019279e-001,0.000000e+000,0,,0,
1575767554.734,,1.000000e+003,4.375950e+001,4.108882e-004,0.000000e+000,3,9.751014e-001,0.000000e+000,,,,,,,,,,,,,,24,1,4.000000e+000,4.272995e-001,0.000000e+000,0,,0,
1575767637.656,,1.000000e+003,4.077016e+001,4.394149e-004,0.000000e+000,3,9.749585e-001,0.000000e+000,,,,,,,,,,,,,,24,1,4.000000e+000,3.956108e-001,0.000000e+000,0,,0,
1575767721.640,,1.000000e+003,3.778349e+001,4.714595e-004,0.000000e+000,3,9.755461e-001,0.000000e+000,,,,,,,,,,,,,,24,1,4.000000e+000,3.977203e-001,0.000000e+000,0,,0,
1575767805.031,,1.000000e+003,3.473351e+001,5.097765e-004,0.000000e+000,3,9.756289e-001,0.000000e+000,,,,,,,,,,,,,,24,1,4.000000e+000,3.830986e-001,0.000000e+000,0,,0,
1575767885.531,,1.000000e+003,3.177213e+001,5.538948e-004,0.000000e+000,3,9.756678e-001,0.000000e+000,,,,,,,,,,,,,,24,1,4.000000e+000,4.005699e-001,0.000000e+000,0,,0,
1575767966.796,,1.000000e+003,2.875584e+001,6.069009e-004,0.000000e+000,3,9.762372e-001,0.000000e+000,,,,,,,,,,,,,,24,1,4.000000e+000,4.122906e-001,0.000000e+000,0,,0,
1575768045.390,,1.000000e+003,2.576418e+001,6.715943e-004,0.000000e+000,3,9.759157e-001,0.000000e+000,,,,,,,,,,,,,,24,1,4.000000e+000,3.944607e-001,0.000000e+000,0,,0,
1575768132.265,,1.000000e+003,2.274537e+001,7.526521e-004,0.000000e+000,3,9.759803e-001,0.000000e+000,,,,,,,,,,,,,,24,1,4.000000e+000,4.231911e-001,0.000000e+000,0,,0,
1575768218.546,,1.000000e+003,1.978401e+001,8.516328e-004,0.000000e+000,3,9.759823e-001,0.000000e+000,,,,,,,,,,,,,,24,1,4.000000e+000,3.794212e-001,0.000000e+000,0,,0,
1575768305.984,,1.000000e+003,1.677051e+001,9.872739e-004,0.000000e+000,3,9.762095e-001,0.000000e+000,,,,,,,,,,,,,,24,1,4.000000e+000,3.847389e-001,0.000000e+000,0,,0,
1575768416.828,,1.000000e+003,1.297004e+001,1.234779e-003,0.000000e+000,3,9.762022e-001,0.000000e+000,,,,,,,,,,,,,,24,1,4.000000e+000,3.417406e-001,0.000000e+000,0,,0,
1575768479.953,,1.000000e+003,1.077460e+001,1.441611e-003,0.000000e+000,3,9.765040e-001,0.000000e+000,,,,,,,,,,,,,,24,1,4.000000e+000,3.528805e-001,0.000000e+000,0,,0,
1575768575.484,,1.000000e+003,7.764404e+000,1.906623e-003,0.000000e+000,3,9.767863e-001,0.000000e+000,,,,,,,,,,,,,,24,1,4.000000e+000,3.453221e-001,0.000000e+000,0,,0,
1575768680.562,,1.000000e+003,4.816596e+000,2.892510e-003,0.000000e+000,3,9.766135e-001,0.000000e+000,,,,,,,,,,,,,,24,1,4.000000e+000,3.369341e-001,0.000000e+000,0,,0,
1575768933.296,,1.000000e+003,1.993509e+000,5.393296e-003,0.000000e+000,3,9.767055e-001,0.000000e+000,,,,,,,,,,,,,,24,1,4.000000e+000,7.530451e-004,0.000000e+000,0,,0,