File: Publications/AErSe2/KErSe2_bulkdata/RE__CsErSe2_heat_capacity_and_magnetization_results/KErSe2_Hpertoplate_12.07.2019.dc.dat
[Header]
TITLE,MPMS DC Measurement
BYAPP,MPMS Measurement,2.1,Summary
FILEOPENTIME, 1575778116.937000 12/7/2019, 8:08:36 PM

INFO, APPNAME, MPMS MultiVu Application, Revision 1.61,  Build 082

INFO, NAME, KErSe2_Hpertoplate_12.07.2019
INFO, WEIGHT, 0.560mg
INFO, AREA, 1.000
INFO, LENGTH, 1.000
INFO, SHAPE, Plate
INFO, COMMENT, KErSe2_Hpertoplate_12.07.2019on grease straw neutronsample
INFO, SEQUENCE FILE: Er.seq


INFO, BACKGROUND DATA FILE:, None


STARTUPAXIS,X,4,LINEAR,AUTO,0.000000,0.000000
STARTUPAXIS,Y1,5,LINEAR,AUTO,0.000000,0.000000


STARTUPGROUP,Longitudinal
FIELDGROUP,Longitudinal,1,2,3,4,5,6,7,8,9,15,16,17,18,27,28
FIELDGROUP,Transverse,1,2,3,4,10,11,12,13,14,19,20,21,22,27,28

PLOT_APPEARANCE,ALL,HORZ_GRID_ON,VERT_GRID_ON,MARKERS_AND_LINES

[Data]
Time,Comment,Field (Oe),Temperature (K),Long Moment (emu),Long Scan Std Dev,Long Algorithm,Long Reg Fit,Long Percent Error (%),Trans Moment (emu),Trans Scan Std Dev,Trans Algorithm,Trans Reg Fit,Trans Percent Error (%),Long Moment [w/o ABS] (emu),Long Scan Std Dev [w/o ABS],Long Reg Fit [w/o ABS],Long Percent Error [w/o ABS] (%),Trans Moment [w/o ABS] (emu),Trans Scan Std Dev [w/o ABS],Trans Reg Fit [w/o ABS],Trans Percent Error [w/o ABS] (%),Points per Scan,Scans per Measurement,Scan Length (cm),Delta Temp (K),Rot Position (deg),Error,EC Comp. Running,Using ABS,
1575778116.937,,6.000000e+004,1.999097e+000,6.628656e-004,0.000000e+000,3,0.000000e+000,0.000000e+000,,,,,,,,,,,,,,24,1,4.000000e+000,1.209021e-003,0.000000e+000,0,,0,
1575778656.078,,5.700000e+004,1.998630e+000,1.386858e-003,0.000000e+000,3,9.900846e-001,0.000000e+000,,,,,,,,,,,,,,24,1,4.000000e+000,1.379251e-004,0.000000e+000,0,,0,
1575779126.109,,5.100000e+004,1.997286e+000,4.912719e-002,0.000000e+000,3,9.944450e-001,0.000000e+000,,,,,,,,,,,,,,24,1,4.000000e+000,1.101971e-003,0.000000e+000,0,,0,
1575779287.000,,4.800000e+004,2.000496e+000,4.747383e-002,0.000000e+000,3,9.942265e-001,0.000000e+000,,,,,,,,,,,,,,24,1,4.000000e+000,3.459454e-004,0.000000e+000,0,,0,
1575779567.046,,4.200000e+004,1.999925e+000,4.427018e-002,0.000000e+000,3,9.945339e-001,0.000000e+000,,,,,,,,,,,,,,24,1,4.000000e+000,1.729727e-004,0.000000e+000,0,,0,
1575779721.375,,3.900000e+004,2.000323e+000,4.266718e-002,0.000000e+000,3,9.943232e-001,0.000000e+000,,,,,,,,,,,,,,24,1,4.000000e+000,1.380444e-004,0.000000e+000,0,,0,
1575779998.937,,3.300000e+004,1.999597e+000,3.942290e-002,0.000000e+000,3,9.944623e-001,0.000000e+000,,,,,,,,,,,,,,24,1,4.000000e+000,4.839897e-004,0.000000e+000,0,,0,
1575780151.062,,3.000000e+004,2.000340e+000,3.766291e-002,0.000000e+000,3,9.942002e-001,0.000000e+000,,,,,,,,,,,,,,24,1,4.000000e+000,5.888939e-004,0.000000e+000,0,,0,
1575780403.312,,2.800000e+004,2.000219e+000,3.641100e-002,0.000000e+000,3,9.943824e-001,0.000000e+000,,,,,,,,,,,,,,24,1,4.000000e+000,4.150867e-004,0.000000e+000,0,,0,
1575780546.156,,2.700000e+004,1.999821e+000,3.573464e-002,0.000000e+000,3,9.942411e-001,0.000000e+000,,,,,,,,,,,,,,24,1,4.000000e+000,3.492832e-005,0.000000e+000,0,,0,
1575780797.218,,2.500000e+004,1.999856e+000,3.431255e-002,0.000000e+000,3,9.943116e-001,0.000000e+000,,,,,,,,,,,,,,24,1,4.000000e+000,9.330511e-004,0.000000e+000,0,,0,
1575780940.875,,2.400000e+004,1.999960e+000,3.353323e-002,0.000000e+000,3,9.941380e-001,0.000000e+000,,,,,,,,,,,,,,24,1,4.000000e+000,1.140952e-003,0.000000e+000,0,,0,
1575781197.062,,2.200000e+004,1.999459e+000,3.187191e-002,0.000000e+000,3,9.942126e-001,0.000000e+000,,,,,,,,,,,,,,24,1,4.000000e+000,1.380444e-004,0.000000e+000,0,,0,
1575781346.203,,2.100000e+004,2.000133e+000,3.094786e-002,0.000000e+000,3,9.940139e-001,0.000000e+000,,,,,,,,,,,,,,24,1,4.000000e+000,5.179644e-004,0.000000e+000,0,,0,
1575781608.515,,1.900000e+004,1.998647e+000,2.897626e-002,0.000000e+000,3,9.940966e-001,0.000000e+000,,,,,,,,,,,,,,24,1,4.000000e+000,2.409220e-004,0.000000e+000,0,,0,
1575781750.484,,1.800000e+004,1.999995e+000,2.788731e-002,0.000000e+000,3,9.939308e-001,0.000000e+000,,,,,,,,,,,,,,24,1,4.000000e+000,3.809929e-004,0.000000e+000,0,,0,
1575782005.703,,1.600000e+004,2.000219e+000,2.555508e-002,0.000000e+000,3,9.940296e-001,0.000000e+000,,,,,,,,,,,,,,24,1,4.000000e+000,0.000000e+000,0.000000e+000,0,,0,
1575782144.562,,1.500000e+004,1.999891e+000,2.423367e-002,0.000000e+000,3,9.918669e-001,0.000000e+000,,,,,,,,,,,,,,24,1,4.000000e+000,8.640289e-004,0.000000e+000,0,,0,
1575782391.937,,1.300000e+004,2.000012e+000,2.159810e-002,0.000000e+000,3,9.938909e-001,0.000000e+000,,,,,,,,,,,,,,24,1,4.000000e+000,2.759695e-004,0.000000e+000,0,,0,
1575782534.046,,1.200000e+004,1.999839e+000,2.016146e-002,0.000000e+000,3,9.937040e-001,0.000000e+000,,,,,,,,,,,,,,24,1,4.000000e+000,1.379251e-004,0.000000e+000,0,,0,
1575782779.437,,1.000000e+004,2.000133e+000,1.714230e-002,0.000000e+000,3,9.937297e-001,0.000000e+000,,,,,,,,,,,,,,24,1,4.000000e+000,7.258654e-004,0.000000e+000,0,,0,
1575782919.515,,9.000000e+003,2.000289e+000,1.555154e-002,0.000000e+000,3,9.934953e-001,0.000000e+000,,,,,,,,,,,,,,24,1,4.000000e+000,6.918907e-004,0.000000e+000,0,,0,
1575783162.171,,7.000000e+003,2.003930e+000,1.226430e-002,0.000000e+000,3,9.935061e-001,0.000000e+000,,,,,,,,,,,,,,24,1,4.000000e+000,2.081394e-004,0.000000e+000,0,,0,
1575783296.609,,6.000000e+003,2.000548e+000,1.058111e-002,0.000000e+000,3,9.934877e-001,0.000000e+000,,,,,,,,,,,,,,24,1,4.000000e+000,6.577969e-004,0.000000e+000,0,,0,
1575783617.765,,4.000000e+003,2.000704e+000,7.113050e-003,0.000000e+000,3,9.933966e-001,0.000000e+000,,,,,,,,,,,,,,24,1,4.000000e+000,1.380444e-004,0.000000e+000,0,,0,
1575783756.296,,3.000000e+003,1.999856e+000,5.348163e-003,0.000000e+000,3,9.935024e-001,0.000000e+000,,,,,,,,,,,,,,24,1,4.000000e+000,3.108978e-004,0.000000e+000,0,,0,
1575784000.046,,1.800000e+003,1.999649e+000,3.207607e-003,0.000000e+000,3,9.929675e-001,0.000000e+000,,,,,,,,,,,,,,24,1,4.000000e+000,3.799200e-004,0.000000e+000,0,,0,
1575784134.390,,1.600000e+003,2.000185e+000,2.848659e-003,0.000000e+000,3,9.934349e-001,0.000000e+000,,,,,,,,,,,,,,24,1,4.000000e+000,1.378059e-004,0.000000e+000,0,,0,
1575784367.812,,1.200000e+003,1.999424e+000,2.131767e-003,0.000000e+000,3,9.933998e-001,0.000000e+000,,,,,,,,,,,,,,24,1,4.000000e+000,6.902218e-005,0.000000e+000,0,,0,
1575784495.718,,1.000000e+003,2.000237e+000,1.775973e-003,0.000000e+000,3,9.933024e-001,0.000000e+000,,,,,,,,,,,,,,24,1,4.000000e+000,1.039505e-004,0.000000e+000,0,,0,
1575784734.140,,6.000000e+002,1.999666e+000,1.053891e-003,0.000000e+000,3,9.921035e-001,0.000000e+000,,,,,,,,,,,,,,24,1,4.000000e+000,6.220341e-004,0.000000e+000,0,,0,
1575784881.296,,4.000000e+002,1.999960e+000,6.975897e-004,0.000000e+000,3,9.934515e-001,0.000000e+000,,,,,,,,,,,,,,24,1,4.000000e+000,4.500151e-004,0.000000e+000,0,,0,
1575785113.812,,0.000000e+000,2.000082e+000,-2.403565e-005,0.000000e+000,3,9.395490e-001,0.000000e+000,,,,,,,,,,,,,,24,1,4.000000e+000,4.149675e-004,0.000000e+000,0,,0,
1575788619.000,,1.000000e+004,3.488865e+002,5.224047e-004,0.000000e+000,3,9.810721e-001,0.000000e+000,,,,,,,,,,,,,,24,1,4.000000e+000,2.252197e-001,0.000000e+000,0,,0,
1575788752.046,,1.000000e+004,3.457648e+002,5.275454e-004,0.000000e+000,3,9.818255e-001,0.000000e+000,,,,,,,,,,,,,,24,1,4.000000e+000,4.299011e-001,0.000000e+000,0,,0,
1575788833.593,,1.000000e+004,3.427042e+002,5.326092e-004,0.000000e+000,3,9.818811e-001,0.000000e+000,,,,,,,,,,,,,,24,1,4.000000e+000,5.581970e-001,0.000000e+000,0,,0,
1575788910.968,,1.000000e+004,3.397200e+002,5.387246e-004,0.000000e+000,3,9.818822e-001,0.000000e+000,,,,,,,,,,,,,,24,1,4.000000e+000,5.586853e-001,0.000000e+000,0,,0,
1575789004.281,,1.000000e+004,3.367545e+002,5.452534e-004,0.000000e+000,3,9.826381e-001,0.000000e+000,,,,,,,,,,,,,,24,1,4.000000e+000,4.162903e-001,0.000000e+000,0,,0,
1575789106.593,,1.000000e+004,3.337682e+002,5.497143e-004,0.000000e+000,3,9.843304e-001,0.000000e+000,,,,,,,,,,,,,,24,1,4.000000e+000,4.619141e-001,0.000000e+000,0,,0,
1575789206.515,,1.000000e+004,3.306899e+002,5.555077e-004,0.000000e+000,3,9.834607e-001,0.000000e+000,,,,,,,,,,,,,,24,1,4.000000e+000,5.263062e-001,0.000000e+000,0,,0,
1575789298.062,,1.000000e+004,3.277044e+002,5.605709e-004,0.000000e+000,3,9.834302e-001,0.000000e+000,,,,,,,,,,,,,,24,1,4.000000e+000,5.674133e-001,0.000000e+000,0,,0,
1575789388.687,,1.000000e+004,3.247422e+002,5.656130e-004,0.000000e+000,3,9.832250e-001,0.000000e+000,,,,,,,,,,,,,,24,1,4.000000e+000,4.751892e-001,0.000000e+000,0,,0,
1575789481.140,,1.000000e+004,3.217246e+002,5.500665e-004,0.000000e+000,3,9.193854e-001,0.000000e+000,,,,,,,,,,,,,,24,1,4.000000e+000,5.151978e-001,0.000000e+000,0,,0,
1575789573.875,,1.000000e+004,3.187101e+002,5.784142e-004,0.000000e+000,3,9.841074e-001,0.000000e+000,,,,,,,,,,,,,,24,1,4.000000e+000,4.560242e-001,0.000000e+000,0,,0,
1575789665.359,,1.000000e+004,3.156960e+002,5.842645e-004,0.000000e+000,3,9.845912e-001,0.000000e+000,,,,,,,,,,,,,,24,1,4.000000e+000,5.984192e-001,0.000000e+000,0,,0,
1575789755.453,,1.000000e+004,3.127257e+002,5.910015e-004,0.000000e+000,3,9.857224e-001,0.000000e+000,,,,,,,,,,,,,,24,1,4.000000e+000,5.302124e-001,0.000000e+000,0,,0,
1575789847.125,,1.000000e+004,3.097032e+002,5.968105e-004,0.000000e+000,3,9.848065e-001,0.000000e+000,,,,,,,,,,,,,,24,1,4.000000e+000,5.278931e-001,0.000000e+000,0,,0,
1575789937.140,,1.000000e+004,3.067048e+002,6.033581e-004,0.000000e+000,3,9.862951e-001,0.000000e+000,,,,,,,,,,,,,,24,1,4.000000e+000,4.809265e-001,0.000000e+000,0,,0,
1575790026.343,,1.000000e+004,3.037229e+002,6.095584e-004,0.000000e+000,3,9.867620e-001,0.000000e+000,,,,,,,,,,,,,,24,1,4.000000e+000,5.490112e-001,0.000000e+000,0,,0,
1575790116.625,,1.000000e+004,3.006985e+002,6.164629e-004,0.000000e+000,3,9.864459e-001,0.000000e+000,,,,,,,,,,,,,,24,1,4.000000e+000,5.367737e-001,0.000000e+000,0,,0,
1575790206.453,,1.000000e+004,2.977242e+002,6.233234e-004,0.000000e+000,3,9.871567e-001,0.000000e+000,,,,,,,,,,,,,,24,1,4.000000e+000,5.415955e-001,0.000000e+000,0,,0,
1575790297.734,,1.000000e+004,2.947144e+002,6.300119e-004,0.000000e+000,3,9.879059e-001,0.000000e+000,,,,,,,,,,,,,,24,1,4.000000e+000,5.295105e-001,0.000000e+000,0,,0,
1575790387.078,,1.000000e+004,2.917296e+002,6.367566e-004,0.000000e+000,3,9.884440e-001,0.000000e+000,,,,,,,,,,,,,,24,1,4.000000e+000,4.938965e-001,0.000000e+000,0,,0,
1575790477.062,,1.000000e+004,2.886973e+002,6.441190e-004,0.000000e+000,3,9.883427e-001,0.000000e+000,,,,,,,,,,,,,,24,1,4.000000e+000,4.983215e-001,0.000000e+000,0,,0,
1575790567.296,,1.000000e+004,2.857292e+002,6.516512e-004,0.000000e+000,3,9.879906e-001,0.000000e+000,,,,,,,,,,,,,,24,1,4.000000e+000,5.101013e-001,0.000000e+000,0,,0,
1575790656.656,,1.000000e+004,2.827195e+002,6.582960e-004,0.000000e+000,3,9.877015e-001,0.000000e+000,,,,,,,,,,,,,,24,1,4.000000e+000,4.834900e-001,0.000000e+000,0,,0,
1575790745.171,,1.000000e+004,2.797134e+002,6.668789e-004,0.000000e+000,3,9.887834e-001,0.000000e+000,,,,,,,,,,,,,,24,1,4.000000e+000,5.594177e-001,0.000000e+000,0,,0,
1575790835.750,,1.000000e+004,2.766808e+002,6.741883e-004,0.000000e+000,3,9.881288e-001,0.000000e+000,,,,,,,,,,,,,,24,1,4.000000e+000,4.963989e-001,0.000000e+000,0,,0,
1575790924.234,,1.000000e+004,2.737198e+002,6.822555e-004,0.000000e+000,3,9.885147e-001,0.000000e+000,,,,,,,,,,,,,,24,1,4.000000e+000,4.916992e-001,0.000000e+000,0,,0,
1575791013.828,,1.000000e+004,2.706693e+002,6.906212e-004,0.000000e+000,3,9.890493e-001,0.000000e+000,,,,,,,,,,,,,,24,1,4.000000e+000,5.606995e-001,0.000000e+000,0,,0,
1575791102.875,,1.000000e+004,2.677323e+002,6.986949e-004,0.000000e+000,3,9.894769e-001,0.000000e+000,,,,,,,,,,,,,,24,1,4.000000e+000,5.341797e-001,0.000000e+000,0,,0,
1575791192.390,,1.000000e+004,2.647204e+002,7.072797e-004,0.000000e+000,3,9.884250e-001,0.000000e+000,,,,,,,,,,,,,,24,1,4.000000e+000,5.402222e-001,0.000000e+000,0,,0,
1575791282.687,,1.000000e+004,2.617325e+002,7.160368e-004,0.000000e+000,3,9.888309e-001,0.000000e+000,,,,,,,,,,,,,,24,1,4.000000e+000,4.954834e-001,0.000000e+000,0,,0,
1575791372.546,,1.000000e+004,2.586685e+002,7.255222e-004,0.000000e+000,3,9.893210e-001,0.000000e+000,,,,,,,,,,,,,,24,1,4.000000e+000,5.142822e-001,0.000000e+000,0,,0,
1575791460.687,,1.000000e+004,2.557137e+002,7.340707e-004,0.000000e+000,3,9.890093e-001,0.000000e+000,,,,,,,,,,,,,,24,1,4.000000e+000,4.960938e-001,0.000000e+000,0,,0,
1575791549.718,,1.000000e+004,2.527433e+002,7.438288e-004,0.000000e+000,3,9.898195e-001,0.000000e+000,,,,,,,,,,,,,,24,1,4.000000e+000,4.958954e-001,0.000000e+000,0,,0,
1575791638.671,,1.000000e+004,2.497354e+002,7.533413e-004,0.000000e+000,3,9.891919e-001,0.000000e+000,,,,,,,,,,,,,,24,1,4.000000e+000,5.178986e-001,0.000000e+000,0,,0,
1575791730.093,,1.000000e+004,2.467286e+002,7.631812e-004,0.000000e+000,3,9.895540e-001,0.000000e+000,,,,,,,,,,,,,,24,1,4.000000e+000,4.828949e-001,0.000000e+000,0,,0,
1575791819.953,,1.000000e+004,2.437258e+002,7.733799e-004,0.000000e+000,3,9.897056e-001,0.000000e+000,,,,,,,,,,,,,,24,1,4.000000e+000,5.248108e-001,0.000000e+000,0,,0,
1575791908.828,,1.000000e+004,2.407266e+002,7.833956e-004,0.000000e+000,3,9.900467e-001,0.000000e+000,,,,,,,,,,,,,,24,1,4.000000e+000,5.063019e-001,0.000000e+000,0,,0,
1575791999.593,,1.000000e+004,2.377157e+002,7.941118e-004,0.000000e+000,3,9.905694e-001,0.000000e+000,,,,,,,,,,,,,,24,1,4.000000e+000,4.982910e-001,0.000000e+000,0,,0,
1575792089.531,,1.000000e+004,2.347270e+002,8.055790e-004,0.000000e+000,3,9.904810e-001,0.000000e+000,,,,,,,,,,,,,,24,1,4.000000e+000,4.702911e-001,0.000000e+000,0,,0,
1575792180.046,,1.000000e+004,2.316703e+002,8.164856e-004,0.000000e+000,3,9.907778e-001,0.000000e+000,,,,,,,,,,,,,,24,1,4.000000e+000,5.063934e-001,0.000000e+000,0,,0,
1575792270.046,,1.000000e+004,2.287205e+002,8.285433e-004,0.000000e+000,3,9.903418e-001,0.000000e+000,,,,,,,,,,,,,,24,1,4.000000e+000,4.645996e-001,0.000000e+000,0,,0,
1575792357.750,,1.000000e+004,2.257188e+002,8.396056e-004,0.000000e+000,3,9.906526e-001,0.000000e+000,,,,,,,,,,,,,,24,1,4.000000e+000,5.073090e-001,0.000000e+000,0,,0,
1575792449.375,,1.000000e+004,2.226818e+002,8.520844e-004,0.000000e+000,3,9.902478e-001,0.000000e+000,,,,,,,,,,,,,,24,1,4.000000e+000,6.276093e-001,0.000000e+000,0,,0,
1575792538.453,,1.000000e+004,2.197068e+002,8.649445e-004,0.000000e+000,3,9.907131e-001,0.000000e+000,,,,,,,,,,,,,,24,1,4.000000e+000,4.358978e-001,0.000000e+000,0,,0,
1575792627.593,,1.000000e+004,2.167271e+002,8.771474e-004,0.000000e+000,3,9.901778e-001,0.000000e+000,,,,,,,,,,,,,,24,1,4.000000e+000,5.209961e-001,0.000000e+000,0,,0,
1575792717.484,,1.000000e+004,2.137873e+002,8.911981e-004,0.000000e+000,3,9.909952e-001,0.000000e+000,,,,,,,,,,,,,,24,1,4.000000e+000,4.239960e-001,0.000000e+000,0,,0,
1575792806.890,,1.000000e+004,2.107679e+002,9.046578e-004,0.000000e+000,3,9.906787e-001,0.000000e+000,,,,,,,,,,,,,,24,1,4.000000e+000,4.474945e-001,0.000000e+000,0,,0,
1575792899.234,,1.000000e+004,2.077185e+002,9.183588e-004,0.000000e+000,3,9.913701e-001,0.000000e+000,,,,,,,,,,,,,,24,1,4.000000e+000,4.960022e-001,0.000000e+000,0,,0,
1575792990.093,,1.000000e+004,2.046884e+002,9.332175e-004,0.000000e+000,3,9.914898e-001,0.000000e+000,,,,,,,,,,,,,,24,1,4.000000e+000,5.337067e-001,0.000000e+000,0,,0,
1575793079.906,,1.000000e+004,2.016709e+002,9.472758e-004,0.000000e+000,3,9.913705e-001,0.000000e+000,,,,,,,,,,,,,,24,1,4.000000e+000,5.105896e-001,0.000000e+000,0,,0,
1575793167.906,,1.000000e+004,1.987140e+002,9.620907e-004,0.000000e+000,3,9.916551e-001,0.000000e+000,,,,,,,,,,,,,,24,1,4.000000e+000,4.600983e-001,0.000000e+000,0,,0,
1575793259.046,,1.000000e+004,1.957578e+002,9.777099e-004,0.000000e+000,3,9.918369e-001,0.000000e+000,,,,,,,,,,,,,,24,1,4.000000e+000,4.463043e-001,0.000000e+000,0,,0,
1575793348.484,,1.000000e+004,1.927252e+002,9.934900e-004,0.000000e+000,3,9.918553e-001,0.000000e+000,,,,,,,,,,,,,,24,1,4.000000e+000,4.889069e-001,0.000000e+000,0,,0,
1575793437.500,,1.000000e+004,1.896848e+002,1.010393e-003,0.000000e+000,3,9.920424e-001,0.000000e+000,,,,,,,,,,,,,,24,1,4.000000e+000,5.249023e-001,0.000000e+000,0,,0,
1575793526.359,,1.000000e+004,1.867370e+002,1.027149e-003,0.000000e+000,3,9.918074e-001,0.000000e+000,,,,,,,,,,,,,,24,1,4.000000e+000,4.523010e-001,0.000000e+000,0,,0,
1575793614.468,,1.000000e+004,1.837482e+002,1.044325e-003,0.000000e+000,3,9.926641e-001,0.000000e+000,,,,,,,,,,,,,,24,1,4.000000e+000,4.920959e-001,0.000000e+000,0,,0,
1575793704.156,,1.000000e+004,1.807607e+002,1.062353e-003,0.000000e+000,3,9.922143e-001,0.000000e+000,,,,,,,,,,,,,,24,1,4.000000e+000,4.524994e-001,0.000000e+000,0,,0,
1575793795.453,,1.000000e+004,1.777133e+002,1.081404e-003,0.000000e+000,3,9.926633e-001,0.000000e+000,,,,,,,,,,,,,,24,1,4.000000e+000,5.047913e-001,0.000000e+000,0,,0,
1575793886.671,,1.000000e+004,1.747074e+002,1.100394e-003,0.000000e+000,3,9.926585e-001,0.000000e+000,,,,,,,,,,,,,,24,1,4.000000e+000,5.285034e-001,0.000000e+000,0,,0,
1575793998.421,,1.000000e+004,1.709035e+002,1.123039e-003,0.000000e+000,3,9.923441e-001,0.000000e+000,,,,,,,,,,,,,,24,1,4.000000e+000,3.489990e-001,0.000000e+000,0,,0,
1575794066.203,,1.000000e+004,1.687364e+002,1.140331e-003,0.000000e+000,3,9.932979e-001,0.000000e+000,,,,,,,,,,,,,,24,1,4.000000e+000,4.669952e-001,0.000000e+000,0,,0,
1575794154.968,,1.000000e+004,1.657535e+002,1.161518e-003,0.000000e+000,3,9.929636e-001,0.000000e+000,,,,,,,,,,,,,,24,1,4.000000e+000,4.355927e-001,0.000000e+000,0,,0,
1575794242.843,,1.000000e+004,1.627866e+002,1.183163e-003,0.000000e+000,3,9.931924e-001,0.000000e+000,,,,,,,,,,,,,,24,1,4.000000e+000,4.055939e-001,0.000000e+000,0,,0,
1575794334.156,,1.000000e+004,1.597404e+002,1.206579e-003,0.000000e+000,3,9.929697e-001,0.000000e+000,,,,,,,,,,,,,,24,1,4.000000e+000,5.130005e-001,0.000000e+000,0,,0,
1575794498.921,,1.000000e+004,1.567228e+002,1.229722e-003,0.000000e+000,3,9.937750e-001,0.000000e+000,,,,,,,,,,,,,,24,1,4.000000e+000,4.806061e-001,0.000000e+000,0,,0,
1575794587.375,,1.000000e+004,1.537502e+002,1.254772e-003,0.000000e+000,3,9.940365e-001,0.000000e+000,,,,,,,,,,,,,,24,1,4.000000e+000,4.920044e-001,0.000000e+000,0,,0,
1575794676.265,,1.000000e+004,1.507168e+002,1.280202e-003,0.000000e+000,3,9.939418e-001,0.000000e+000,,,,,,,,,,,,,,24,1,4.000000e+000,4.968872e-001,0.000000e+000,0,,0,
1575794765.843,,1.000000e+004,1.477797e+002,1.306559e-003,0.000000e+000,3,9.941549e-001,0.000000e+000,,,,,,,,,,,,,,24,1,4.000000e+000,4.272003e-001,0.000000e+000,0,,0,
1575794854.859,,1.000000e+004,1.447484e+002,1.334645e-003,0.000000e+000,3,9.941303e-001,0.000000e+000,,,,,,,,,,,,,,24,1,4.000000e+000,4.842987e-001,0.000000e+000,0,,0,
1575794945.734,,1.000000e+004,1.417164e+002,1.363742e-003,0.000000e+000,3,9.943525e-001,0.000000e+000,,,,,,,,,,,,,,24,1,4.000000e+000,4.392090e-001,0.000000e+000,0,,0,
1575795035.265,,1.000000e+004,1.387083e+002,1.393578e-003,0.000000e+000,3,9.944161e-001,0.000000e+000,,,,,,,,,,,,,,24,1,4.000000e+000,5.202026e-001,0.000000e+000,0,,0,
1575795124.062,,1.000000e+004,1.357154e+002,1.425001e-003,0.000000e+000,3,9.947376e-001,0.000000e+000,,,,,,,,,,,,,,24,1,4.000000e+000,4.359894e-001,0.000000e+000,0,,0,
1575795209.812,,1.000000e+004,1.327442e+002,1.457726e-003,0.000000e+000,3,9.944608e-001,0.000000e+000,,,,,,,,,,,,,,24,1,4.000000e+000,4.895020e-001,0.000000e+000,0,,0,
1575795298.609,,1.000000e+004,1.297560e+002,1.491859e-003,0.000000e+000,3,9.946017e-001,0.000000e+000,,,,,,,,,,,,,,24,1,4.000000e+000,4.438934e-001,0.000000e+000,0,,0,
1575795388.718,,1.000000e+004,1.267275e+002,1.528515e-003,0.000000e+000,3,9.945156e-001,0.000000e+000,,,,,,,,,,,,,,24,1,4.000000e+000,5.186005e-001,0.000000e+000,0,,0,
1575795476.859,,1.000000e+004,1.237119e+002,1.565531e-003,0.000000e+000,3,9.949107e-001,0.000000e+000,,,,,,,,,,,,,,24,1,4.000000e+000,4.422989e-001,0.000000e+000,0,,0,
1575795565.656,,1.000000e+004,1.207330e+002,1.604769e-003,0.000000e+000,3,9.949155e-001,0.000000e+000,,,,,,,,,,,,,,24,1,4.000000e+000,4.867020e-001,0.000000e+000,0,,0,
1575795653.890,,1.000000e+004,1.177343e+002,1.645408e-003,0.000000e+000,3,9.951753e-001,0.000000e+000,,,,,,,,,,,,,,24,1,4.000000e+000,4.928970e-001,0.000000e+000,0,,0,
1575795741.203,,1.000000e+004,1.147686e+002,1.688455e-003,0.000000e+000,3,9.952385e-001,0.000000e+000,,,,,,,,,,,,,,24,1,4.000000e+000,4.477005e-001,0.000000e+000,0,,0,
1575795829.859,,1.000000e+004,1.117314e+002,1.733381e-003,0.000000e+000,3,9.952741e-001,0.000000e+000,,,,,,,,,,,,,,24,1,4.000000e+000,4.493027e-001,0.000000e+000,0,,0,
1575795917.468,,1.000000e+004,1.087453e+002,1.779990e-003,0.000000e+000,3,9.952530e-001,0.000000e+000,,,,,,,,,,,,,,24,1,4.000000e+000,4.574966e-001,0.000000e+000,0,,0,
1575796004.015,,1.000000e+004,1.057607e+002,1.829146e-003,0.000000e+000,3,9.951968e-001,0.000000e+000,,,,,,,,,,,,,,24,1,4.000000e+000,4.608002e-001,0.000000e+000,0,,0,
1575796091.390,,1.000000e+004,1.027643e+002,1.882507e-003,0.000000e+000,3,9.955260e-001,0.000000e+000,,,,,,,,,,,,,,24,1,4.000000e+000,4.048004e-001,0.000000e+000,0,,0,
1575796177.281,,1.000000e+004,9.977845e+001,1.937108e-003,0.000000e+000,3,9.952525e-001,0.000000e+000,,,,,,,,,,,,,,24,1,4.000000e+000,4.111786e-001,0.000000e+000,0,,0,
1575796264.250,,1.000000e+004,9.672357e+001,1.996640e-003,0.000000e+000,3,9.954891e-001,0.000000e+000,,,,,,,,,,,,,,24,1,4.000000e+000,4.796371e-001,0.000000e+000,0,,0,
1575796350.484,,1.000000e+004,9.372163e+001,2.058982e-003,0.000000e+000,3,9.954168e-001,0.000000e+000,,,,,,,,,,,,,,24,1,4.000000e+000,4.883194e-001,0.000000e+000,0,,0,
1575796436.640,,1.000000e+004,9.071805e+001,2.124093e-003,0.000000e+000,3,9.955276e-001,0.000000e+000,,,,,,,,,,,,,,24,1,4.000000e+000,4.887238e-001,0.000000e+000,0,,0,
1575796523.328,,1.000000e+004,8.775661e+001,2.193829e-003,0.000000e+000,3,9.960299e-001,0.000000e+000,,,,,,,,,,,,,,24,1,4.000000e+000,4.312057e-001,0.000000e+000,0,,0,
1575796607.453,,1.000000e+004,8.475055e+001,2.266707e-003,0.000000e+000,3,9.959529e-001,0.000000e+000,,,,,,,,,,,,,,24,1,4.000000e+000,3.919144e-001,0.000000e+000,0,,0,
1575796691.265,,1.000000e+004,8.178442e+001,2.345670e-003,0.000000e+000,3,9.961318e-001,0.000000e+000,,,,,,,,,,,,,,24,1,4.000000e+000,4.034729e-001,0.000000e+000,0,,0,
1575796774.062,,1.000000e+004,7.875694e+001,2.429203e-003,0.000000e+000,3,9.961151e-001,0.000000e+000,,,,,,,,,,,,,,24,1,4.000000e+000,4.321289e-001,0.000000e+000,0,,0,
1575796857.312,,1.000000e+004,7.577466e+001,2.518812e-003,0.000000e+000,3,9.961092e-001,0.000000e+000,,,,,,,,,,,,,,24,1,4.000000e+000,4.453888e-001,0.000000e+000,0,,0,
1575796939.796,,1.000000e+004,7.278320e+001,2.613940e-003,0.000000e+000,3,9.964305e-001,0.000000e+000,,,,,,,,,,,,,,24,1,4.000000e+000,4.089508e-001,0.000000e+000,0,,0,
1575797022.796,,1.000000e+004,6.971191e+001,2.719268e-003,0.000000e+000,3,9.965604e-001,0.000000e+000,,,,,,,,,,,,,,24,1,4.000000e+000,4.274368e-001,0.000000e+000,0,,0,
1575797104.437,,1.000000e+004,6.670444e+001,2.831632e-003,0.000000e+000,3,9.964522e-001,0.000000e+000,,,,,,,,,,,,,,24,1,4.000000e+000,4.151917e-001,0.000000e+000,0,,0,
1575797182.531,,1.000000e+004,6.372720e+001,2.950761e-003,0.000000e+000,3,9.967936e-001,0.000000e+000,,,,,,,,,,,,,,24,1,4.000000e+000,4.837494e-001,0.000000e+000,0,,0,
1575797261.859,,1.000000e+004,6.073412e+001,3.081091e-003,0.000000e+000,3,9.968585e-001,0.000000e+000,,,,,,,,,,,,,,24,1,4.000000e+000,4.814377e-001,0.000000e+000,0,,0,
1575797339.312,,1.000000e+004,5.772358e+001,3.221276e-003,0.000000e+000,3,9.969258e-001,0.000000e+000,,,,,,,,,,,,,,24,1,4.000000e+000,4.770889e-001,0.000000e+000,0,,0,
1575797419.921,,1.000000e+004,5.477702e+001,3.372797e-003,0.000000e+000,3,9.970624e-001,0.000000e+000,,,,,,,,,,,,,,24,1,4.000000e+000,3.956108e-001,0.000000e+000,0,,0,
1575797506.078,,1.000000e+004,5.177993e+001,3.540087e-003,0.000000e+000,3,9.970945e-001,0.000000e+000,,,,,,,,,,,,,,24,1,4.000000e+000,3.932419e-001,0.000000e+000,0,,0,
1575797595.593,,1.000000e+004,4.870767e+001,3.730612e-003,0.000000e+000,3,9.972461e-001,0.000000e+000,,,,,,,,,,,,,,24,1,4.000000e+000,3.517570e-001,0.000000e+000,0,,0,
1575797679.171,,1.000000e+004,4.577935e+001,3.932238e-003,0.000000e+000,3,9.974502e-001,0.000000e+000,,,,,,,,,,,,,,24,1,4.000000e+000,4.065704e-001,0.000000e+000,0,,0,
1575797764.828,,1.000000e+004,4.279939e+001,4.161905e-003,0.000000e+000,3,9.975663e-001,0.000000e+000,,,,,,,,,,,,,,24,1,4.000000e+000,3.912926e-001,0.000000e+000,0,,0,
1575797850.500,,1.000000e+004,3.976818e+001,4.420070e-003,0.000000e+000,3,9.975303e-001,0.000000e+000,,,,,,,,,,,,,,24,1,4.000000e+000,4.015884e-001,0.000000e+000,0,,0,
1575797933.484,,1.000000e+004,3.676308e+001,4.710791e-003,0.000000e+000,3,9.976778e-001,0.000000e+000,,,,,,,,,,,,,,24,1,4.000000e+000,4.156990e-001,0.000000e+000,0,,0,
1575798015.953,,1.000000e+004,3.377129e+001,5.037291e-003,0.000000e+000,3,9.977630e-001,0.000000e+000,,,,,,,,,,,,,,24,1,4.000000e+000,4.328499e-001,0.000000e+000,0,,0,
1575798111.250,,1.000000e+004,3.029296e+001,5.478941e-003,0.000000e+000,3,9.975490e-001,0.000000e+000,,,,,,,,,,,,,,24,1,4.000000e+000,3.490200e-001,0.000000e+000,0,,0,
1575798177.562,,1.000000e+004,2.776334e+001,5.840896e-003,0.000000e+000,3,9.978533e-001,0.000000e+000,,,,,,,,,,,,,,24,1,4.000000e+000,3.800106e-001,0.000000e+000,0,,0,
1575798256.093,,1.000000e+004,2.476892e+001,6.338582e-003,0.000000e+000,3,9.978896e-001,0.000000e+000,,,,,,,,,,,,,,24,1,4.000000e+000,3.508816e-001,0.000000e+000,0,,0,
1575798345.703,,1.000000e+004,2.178810e+001,6.905796e-003,0.000000e+000,3,9.978879e-001,0.000000e+000,,,,,,,,,,,,,,24,1,4.000000e+000,3.184700e-001,0.000000e+000,0,,0,
1575798433.406,,1.000000e+004,1.877459e+001,7.578199e-003,0.000000e+000,3,9.979288e-001,0.000000e+000,,,,,,,,,,,,,,24,1,4.000000e+000,3.818398e-001,0.000000e+000,0,,0,
1575798520.500,,1.000000e+004,1.580312e+001,8.364955e-003,0.000000e+000,3,9.979122e-001,0.000000e+000,,,,,,,,,,,,,,24,1,4.000000e+000,3.887396e-001,0.000000e+000,0,,0,
1575798607.000,,1.000000e+004,1.274749e+001,9.299246e-003,0.000000e+000,3,9.978716e-001,0.000000e+000,,,,,,,,,,,,,,24,1,4.000000e+000,3.950195e-001,0.000000e+000,0,,0,
1575798695.531,,1.000000e+004,9.815181e+000,1.036794e-002,0.000000e+000,3,9.979252e-001,0.000000e+000,,,,,,,,,,,,,,24,1,4.000000e+000,3.205776e-001,0.000000e+000,0,,0,
1575798801.078,,1.000000e+004,6.891952e+000,1.181016e-002,0.000000e+000,3,9.978288e-001,0.000000e+000,,,,,,,,,,,,,,24,1,4.000000e+000,1.809521e-001,0.000000e+000,0,,0,
1575798899.343,,1.000000e+004,3.825388e+000,1.413647e-002,0.000000e+000,3,9.975963e-001,0.000000e+000,,,,,,,,,,,,,,24,1,4.000000e+000,3.339269e-001,0.000000e+000,0,,0,
1575802343.078,,1.000000e+003,3.499988e+002,5.218096e-005,0.000000e+000,3,9.781131e-001,0.000000e+000,,,,,,,,,,,,,,24,1,4.000000e+000,4.769897e-002,0.000000e+000,0,,0,
1575802510.296,,1.000000e+003,3.468315e+002,5.253037e-005,0.000000e+000,3,9.697419e-001,0.000000e+000,,,,,,,,,,,,,,24,1,4.000000e+000,2.574158e-001,0.000000e+000,0,,0,
1575802626.062,,1.000000e+003,3.427781e+002,5.391457e-005,0.000000e+000,3,9.768541e-001,0.000000e+000,,,,,,,,,,,,,,24,1,4.000000e+000,3.874817e-001,0.000000e+000,0,,0,
1575802682.734,,1.000000e+003,3.406895e+002,5.402130e-005,0.000000e+000,3,9.752421e-001,0.000000e+000,,,,,,,,,,,,,,24,1,4.000000e+000,5.509949e-001,0.000000e+000,0,,0,
1575802769.953,,1.000000e+003,3.377273e+002,5.423788e-005,0.000000e+000,3,9.728274e-001,0.000000e+000,,,,,,,,,,,,,,24,1,4.000000e+000,5.184021e-001,0.000000e+000,0,,0,
1575802871.656,,1.000000e+003,3.347543e+002,5.482898e-005,0.000000e+000,3,9.809418e-001,0.000000e+000,,,,,,,,,,,,,,24,1,4.000000e+000,4.542236e-001,0.000000e+000,0,,0,
1575802970.296,,1.000000e+003,3.317514e+002,5.606561e-005,0.000000e+000,3,9.859719e-001,0.000000e+000,,,,,,,,,,,,,,24,1,4.000000e+000,4.346008e-001,0.000000e+000,0,,0,
1575803064.312,,1.000000e+003,3.287292e+002,5.627652e-005,0.000000e+000,3,9.910058e-001,0.000000e+000,,,,,,,,,,,,,,24,1,4.000000e+000,4.674988e-001,0.000000e+000,0,,0,
1575803158.531,,1.000000e+003,3.257416e+002,5.612645e-005,0.000000e+000,3,9.826360e-001,0.000000e+000,,,,,,,,,,,,,,24,1,4.000000e+000,4.684143e-001,0.000000e+000,0,,0,
1575803256.140,,1.000000e+003,3.224045e+002,5.710526e-005,0.000000e+000,3,9.823156e-001,0.000000e+000,,,,,,,,,,,,,,24,1,4.000000e+000,3.085022e-001,0.000000e+000,0,,0,
1575803343.734,,1.000000e+003,3.196739e+002,5.793394e-005,0.000000e+000,3,9.818613e-001,0.000000e+000,,,,,,,,,,,,,,24,1,4.000000e+000,5.762939e-001,0.000000e+000,0,,0,
1575803435.718,,1.000000e+003,3.166872e+002,5.892589e-005,0.000000e+000,3,9.821449e-001,0.000000e+000,,,,,,,,,,,,,,24,1,4.000000e+000,4.495850e-001,0.000000e+000,0,,0,
1575803525.968,,1.000000e+003,3.137150e+002,5.901384e-005,0.000000e+000,3,9.818672e-001,0.000000e+000,,,,,,,,,,,,,,24,1,4.000000e+000,4.776917e-001,0.000000e+000,0,,0,
1575803617.250,,1.000000e+003,3.107354e+002,5.915751e-005,0.000000e+000,3,9.852942e-001,0.000000e+000,,,,,,,,,,,,,,24,1,4.000000e+000,4.767761e-001,0.000000e+000,0,,0,
1575803706.265,,1.000000e+003,3.076971e+002,6.063704e-005,0.000000e+000,3,9.806882e-001,0.000000e+000,,,,,,,,,,,,,,24,1,4.000000e+000,5.740967e-001,0.000000e+000,0,,0,
1575803796.890,,1.000000e+003,3.047242e+002,5.983996e-005,0.000000e+000,3,9.777386e-001,0.000000e+000,,,,,,,,,,,,,,24,1,4.000000e+000,5.443115e-001,0.000000e+000,0,,0,
1575803886.156,,1.000000e+003,3.017420e+002,6.145124e-005,0.000000e+000,3,9.800226e-001,0.000000e+000,,,,,,,,,,,,,,24,1,4.000000e+000,4.893799e-001,0.000000e+000,0,,0,
1575803977.156,,1.000000e+003,2.987236e+002,6.258069e-005,0.000000e+000,3,9.882689e-001,0.000000e+000,,,,,,,,,,,,,,24,1,4.000000e+000,5.204773e-001,0.000000e+000,0,,0,
1575804067.203,,1.000000e+003,2.957404e+002,6.302054e-005,0.000000e+000,3,9.879020e-001,0.000000e+000,,,,,,,,,,,,,,24,1,4.000000e+000,4.760742e-001,0.000000e+000,0,,0,
1575804158.375,,1.000000e+003,2.927011e+002,6.370085e-005,0.000000e+000,3,9.896820e-001,0.000000e+000,,,,,,,,,,,,,,24,1,4.000000e+000,5.857849e-001,0.000000e+000,0,,0,
1575804269.203,,1.000000e+003,2.888412e+002,6.429642e-005,0.000000e+000,3,9.876246e-001,0.000000e+000,,,,,,,,,,,,,,24,1,4.000000e+000,2.728882e-001,0.000000e+000,0,,0,
1575804335.359,,1.000000e+003,2.866997e+002,6.499862e-005,0.000000e+000,3,9.843621e-001,0.000000e+000,,,,,,,,,,,,,,24,1,4.000000e+000,5.598145e-001,0.000000e+000,0,,0,
1575804425.937,,1.000000e+003,2.837088e+002,6.574929e-005,0.000000e+000,3,9.916974e-001,0.000000e+000,,,,,,,,,,,,,,24,1,4.000000e+000,4.945984e-001,0.000000e+000,0,,0,
1575804516.500,,1.000000e+003,2.806870e+002,6.645185e-005,0.000000e+000,3,9.920356e-001,0.000000e+000,,,,,,,,,,,,,,24,1,4.000000e+000,5.855103e-001,0.000000e+000,0,,0,
1575804604.515,,1.000000e+003,2.777134e+002,6.782953e-005,0.000000e+000,3,9.906202e-001,0.000000e+000,,,,,,,,,,,,,,24,1,4.000000e+000,5.577087e-001,0.000000e+000,0,,0,
1575804695.015,,1.000000e+003,2.746688e+002,6.780429e-005,0.000000e+000,3,9.899181e-001,0.000000e+000,,,,,,,,,,,,,,24,1,4.000000e+000,4.884949e-001,0.000000e+000,0,,0,
1575804783.703,,1.000000e+003,2.717480e+002,6.944038e-005,0.000000e+000,3,9.904090e-001,0.000000e+000,,,,,,,,,,,,,,24,1,4.000000e+000,4.838867e-001,0.000000e+000,0,,0,
1575804874.687,,1.000000e+003,2.687156e+002,7.004716e-005,0.000000e+000,3,9.910605e-001,0.000000e+000,,,,,,,,,,,,,,24,1,4.000000e+000,5.186157e-001,0.000000e+000,0,,0,
1575804963.734,,1.000000e+003,2.657116e+002,7.115749e-005,0.000000e+000,3,9.914791e-001,0.000000e+000,,,,,,,,,,,,,,24,1,4.000000e+000,4.733887e-001,0.000000e+000,0,,0,
1575805055.921,,1.000000e+003,2.627307e+002,7.117797e-005,0.000000e+000,3,9.853400e-001,0.000000e+000,,,,,,,,,,,,,,24,1,4.000000e+000,4.931030e-001,0.000000e+000,0,,0,
1575805144.500,,1.000000e+003,2.597474e+002,7.173306e-005,0.000000e+000,3,9.879622e-001,0.000000e+000,,,,,,,,,,,,,,24,1,4.000000e+000,4.754028e-001,0.000000e+000,0,,0,
1575805232.031,,1.000000e+003,2.567220e+002,7.342902e-005,0.000000e+000,3,9.869607e-001,0.000000e+000,,,,,,,,,,,,,,24,1,4.000000e+000,4.398804e-001,0.000000e+000,0,,0,
1575805406.437,,1.000000e+003,2.537245e+002,7.443717e-005,0.000000e+000,3,9.873586e-001,0.000000e+000,,,,,,,,,,,,,,24,1,4.000000e+000,4.940033e-001,0.000000e+000,0,,0,
1575805496.234,,1.000000e+003,2.507412e+002,7.471468e-005,0.000000e+000,3,9.862611e-001,0.000000e+000,,,,,,,,,,,,,,24,1,4.000000e+000,4.878082e-001,0.000000e+000,0,,0,
1575805586.921,,1.000000e+003,2.477151e+002,7.567126e-005,0.000000e+000,3,9.888517e-001,0.000000e+000,,,,,,,,,,,,,,24,1,4.000000e+000,5.204010e-001,0.000000e+000,0,,0,
1575805676.718,,1.000000e+003,2.446737e+002,7.724544e-005,0.000000e+000,3,9.870958e-001,0.000000e+000,,,,,,,,,,,,,,24,1,4.000000e+000,5.236969e-001,0.000000e+000,0,,0,
1575805765.156,,1.000000e+003,2.417328e+002,7.795107e-005,0.000000e+000,3,9.869069e-001,0.000000e+000,,,,,,,,,,,,,,24,1,4.000000e+000,5.000000e-001,0.000000e+000,0,,0,
1575805854.156,,1.000000e+003,2.387451e+002,7.921798e-005,0.000000e+000,3,9.878249e-001,0.000000e+000,,,,,,,,,,,,,,24,1,4.000000e+000,4.871979e-001,0.000000e+000,0,,0,
1575805944.281,,1.000000e+003,2.357221e+002,8.028149e-005,0.000000e+000,3,9.891412e-001,0.000000e+000,,,,,,,,,,,,,,24,1,4.000000e+000,5.048065e-001,0.000000e+000,0,,0,
1575806034.890,,1.000000e+003,2.327099e+002,8.093419e-005,0.000000e+000,3,9.881540e-001,0.000000e+000,,,,,,,,,,,,,,24,1,4.000000e+000,5.455017e-001,0.000000e+000,0,,0,
1575806124.062,,1.000000e+003,2.297325e+002,8.235726e-005,0.000000e+000,3,9.899516e-001,0.000000e+000,,,,,,,,,,,,,,24,1,4.000000e+000,4.736023e-001,0.000000e+000,0,,0,
1575806213.296,,1.000000e+003,2.267148e+002,1.360082e-004,0.000000e+000,3,4.720114e-001,0.000000e+000,,,,,,,,,,,,,,24,1,4.000000e+000,4.468079e-001,0.000000e+000,0,,0,
1575806302.437,,1.000000e+003,2.237267e+002,8.491107e-005,0.000000e+000,3,9.905962e-001,0.000000e+000,,,,,,,,,,,,,,24,1,4.000000e+000,4.707947e-001,0.000000e+000,0,,0,
1575806392.281,,1.000000e+003,2.207712e+002,8.592005e-005,0.000000e+000,3,9.929438e-001,0.000000e+000,,,,,,,,,,,,,,24,1,4.000000e+000,4.402924e-001,0.000000e+000,0,,0,
1575806484.234,,1.000000e+003,2.176781e+002,8.728918e-005,0.000000e+000,3,9.899672e-001,0.000000e+000,,,,,,,,,,,,,,24,1,4.000000e+000,5.043945e-001,0.000000e+000,0,,0,
1575806571.953,,1.000000e+003,2.146908e+002,8.894381e-005,0.000000e+000,3,9.904602e-001,0.000000e+000,,,,,,,,,,,,,,24,1,4.000000e+000,4.900055e-001,0.000000e+000,0,,0,
1575806661.531,,1.000000e+003,2.117276e+002,8.964632e-005,0.000000e+000,3,9.924502e-001,0.000000e+000,,,,,,,,,,,,,,24,1,4.000000e+000,5.083008e-001,0.000000e+000,0,,0,
1575806751.578,,1.000000e+003,2.086785e+002,9.153158e-005,0.000000e+000,3,9.901386e-001,0.000000e+000,,,,,,,,,,,,,,24,1,4.000000e+000,5.516968e-001,0.000000e+000,0,,0,
1575806840.296,,1.000000e+003,2.057426e+002,9.294466e-005,0.000000e+000,3,9.892758e-001,0.000000e+000,,,,,,,,,,,,,,24,1,4.000000e+000,4.938049e-001,0.000000e+000,0,,0,
1575806930.843,,1.000000e+003,2.026954e+002,9.457907e-005,0.000000e+000,3,9.905864e-001,0.000000e+000,,,,,,,,,,,,,,24,1,4.000000e+000,4.753113e-001,0.000000e+000,0,,0,
1575807019.593,,1.000000e+003,1.997386e+002,9.586389e-005,0.000000e+000,3,9.922953e-001,0.000000e+000,,,,,,,,,,,,,,24,1,4.000000e+000,4.505920e-001,0.000000e+000,0,,0,
1575807108.859,,1.000000e+003,1.967328e+002,9.718605e-005,0.000000e+000,3,9.918318e-001,0.000000e+000,,,,,,,,,,,,,,24,1,4.000000e+000,4.612885e-001,0.000000e+000,0,,0,
1575807200.187,,1.000000e+003,1.937232e+002,9.876843e-005,0.000000e+000,3,9.917263e-001,0.000000e+000,,,,,,,,,,,,,,24,1,4.000000e+000,5.108032e-001,0.000000e+000,0,,0,
1575807287.093,,1.000000e+003,1.907665e+002,1.004381e-004,0.000000e+000,3,9.912125e-001,0.000000e+000,,,,,,,,,,,,,,24,1,4.000000e+000,4.463959e-001,0.000000e+000,0,,0,
1575807378.750,,1.000000e+003,1.876935e+002,1.020346e-004,0.000000e+000,3,9.900432e-001,0.000000e+000,,,,,,,,,,,,,,24,1,4.000000e+000,5.074921e-001,0.000000e+000,0,,0,
1575807467.078,,1.000000e+003,1.847682e+002,1.038180e-004,0.000000e+000,3,9.938654e-001,0.000000e+000,,,,,,,,,,,,,,24,1,4.000000e+000,4.425964e-001,0.000000e+000,0,,0,
1575807557.906,,1.000000e+003,1.816779e+002,1.055621e-004,0.000000e+000,3,9.933723e-001,0.000000e+000,,,,,,,,,,,,,,24,1,4.000000e+000,4.660950e-001,0.000000e+000,0,,0,
1575807646.359,,1.000000e+003,1.787318e+002,1.073619e-004,0.000000e+000,3,9.927637e-001,0.000000e+000,,,,,,,,,,,,,,24,1,4.000000e+000,5.220947e-001,0.000000e+000,0,,0,
1575807735.921,,1.000000e+003,1.757459e+002,1.090608e-004,0.000000e+000,3,9.923062e-001,0.000000e+000,,,,,,,,,,,,,,24,1,4.000000e+000,4.853058e-001,0.000000e+000,0,,0,
1575807826.328,,1.000000e+003,1.727281e+002,1.111183e-004,0.000000e+000,3,9.924774e-001,0.000000e+000,,,,,,,,,,,,,,24,1,4.000000e+000,4.259033e-001,0.000000e+000,0,,0,
1575807915.734,,1.000000e+003,1.697372e+002,1.133636e-004,0.000000e+000,3,9.903604e-001,0.000000e+000,,,,,,,,,,,,,,24,1,4.000000e+000,4.623108e-001,0.000000e+000,0,,0,
1575808006.109,,1.000000e+003,1.667433e+002,1.151499e-004,0.000000e+000,3,9.929705e-001,0.000000e+000,,,,,,,,,,,,,,24,1,4.000000e+000,5.003967e-001,0.000000e+000,0,,0,
1575808094.375,,1.000000e+003,1.637118e+002,7.860574e-005,0.000000e+000,3,0.000000e+000,0.000000e+000,,,,,,,,,,,,,,24,1,4.000000e+000,4.676056e-001,0.000000e+000,0,,0,
1575808184.468,,1.000000e+003,1.607132e+002,1.195781e-004,0.000000e+000,3,9.914351e-001,0.000000e+000,,,,,,,,,,,,,,24,1,4.000000e+000,4.365997e-001,0.000000e+000,0,,0,
1575808273.734,,1.000000e+003,1.577475e+002,1.221132e-004,0.000000e+000,3,9.924604e-001,0.000000e+000,,,,,,,,,,,,,,24,1,4.000000e+000,4.515991e-001,0.000000e+000,0,,0,
1575808362.296,,1.000000e+003,1.547405e+002,1.243011e-004,0.000000e+000,3,9.926891e-001,0.000000e+000,,,,,,,,,,,,,,24,1,4.000000e+000,4.897919e-001,0.000000e+000,0,,0,
1575808450.437,,1.000000e+003,1.517499e+002,1.267593e-004,0.000000e+000,3,9.924054e-001,0.000000e+000,,,,,,,,,,,,,,24,1,4.000000e+000,4.709930e-001,0.000000e+000,0,,0,
1575808539.750,,1.000000e+003,1.487375e+002,1.297092e-004,0.000000e+000,3,9.925088e-001,0.000000e+000,,,,,,,,,,,,,,24,1,4.000000e+000,4.957123e-001,0.000000e+000,0,,0,
1575808630.203,,1.000000e+003,1.457500e+002,1.326804e-004,0.000000e+000,3,9.924341e-001,0.000000e+000,,,,,,,,,,,,,,24,1,4.000000e+000,4.909973e-001,0.000000e+000,0,,0,
1575808718.437,,1.000000e+003,1.427379e+002,1.355442e-004,0.000000e+000,3,9.928808e-001,0.000000e+000,,,,,,,,,,,,,,24,1,4.000000e+000,4.890137e-001,0.000000e+000,0,,0,
1575808807.484,,1.000000e+003,1.397339e+002,1.381547e-004,0.000000e+000,3,9.933119e-001,0.000000e+000,,,,,,,,,,,,,,24,1,4.000000e+000,4.757996e-001,0.000000e+000,0,,0,
1575808895.296,,1.000000e+003,1.367459e+002,1.413998e-004,0.000000e+000,3,9.929336e-001,0.000000e+000,,,,,,,,,,,,,,24,1,4.000000e+000,4.757996e-001,0.000000e+000,0,,0,
1575808982.937,,1.000000e+003,1.337240e+002,1.444056e-004,0.000000e+000,3,9.942199e-001,0.000000e+000,,,,,,,,,,,,,,24,1,4.000000e+000,4.902954e-001,0.000000e+000,0,,0,
1575809072.203,,1.000000e+003,1.307473e+002,1.479195e-004,0.000000e+000,3,9.948931e-001,0.000000e+000,,,,,,,,,,,,,,24,1,4.000000e+000,4.384918e-001,0.000000e+000,0,,0,
1575809160.515,,1.000000e+003,1.277171e+002,1.514410e-004,0.000000e+000,3,9.955155e-001,0.000000e+000,,,,,,,,,,,,,,24,1,4.000000e+000,4.621964e-001,0.000000e+000,0,,0,
1575809249.109,,1.000000e+003,1.247484e+002,1.554416e-004,0.000000e+000,3,9.932672e-001,0.000000e+000,,,,,,,,,,,,,,24,1,4.000000e+000,4.468994e-001,0.000000e+000,0,,0,
1575809335.828,,1.000000e+003,1.217512e+002,1.592172e-004,0.000000e+000,3,9.946457e-001,0.000000e+000,,,,,,,,,,,,,,24,1,4.000000e+000,4.524002e-001,0.000000e+000,0,,0,
1575809424.859,,1.000000e+003,1.187522e+002,1.631338e-004,0.000000e+000,3,9.948472e-001,0.000000e+000,,,,,,,,,,,,,,24,1,4.000000e+000,4.031982e-001,0.000000e+000,0,,0,
1575809513.156,,1.000000e+003,1.157439e+002,1.670308e-004,0.000000e+000,3,9.941839e-001,0.000000e+000,,,,,,,,,,,,,,24,1,4.000000e+000,4.575043e-001,0.000000e+000,0,,0,
1575809601.687,,1.000000e+003,1.127540e+002,1.713696e-004,0.000000e+000,3,9.948286e-001,0.000000e+000,,,,,,,,,,,,,,24,1,4.000000e+000,4.095993e-001,0.000000e+000,0,,0,
1575809688.859,,1.000000e+003,1.097509e+002,1.759604e-004,0.000000e+000,3,9.942571e-001,0.000000e+000,,,,,,,,,,,,,,24,1,4.000000e+000,4.551010e-001,0.000000e+000,0,,0,
1575809776.000,,1.000000e+003,1.067352e+002,1.811699e-004,0.000000e+000,3,9.950631e-001,0.000000e+000,,,,,,,,,,,,,,24,1,4.000000e+000,4.570999e-001,0.000000e+000,0,,0,
1575809861.890,,1.000000e+003,1.037645e+002,1.862281e-004,0.000000e+000,3,9.938758e-001,0.000000e+000,,,,,,,,,,,,,,24,1,4.000000e+000,4.649048e-001,0.000000e+000,0,,0,
1575809950.171,,1.000000e+003,1.007517e+002,1.917671e-004,0.000000e+000,3,9.952757e-001,0.000000e+000,,,,,,,,,,,,,,24,1,4.000000e+000,4.619980e-001,0.000000e+000,0,,0,
1575810035.859,,1.000000e+003,9.776499e+001,1.970882e-004,0.000000e+000,3,9.955350e-001,0.000000e+000,,,,,,,,,,,,,,24,1,4.000000e+000,4.162903e-001,0.000000e+000,0,,0,
1575810121.000,,1.000000e+003,9.478318e+001,1.643494e-004,0.000000e+000,3,8.599252e-003,0.000000e+000,,,,,,,,,,,,,,24,1,4.000000e+000,4.333191e-001,0.000000e+000,0,,0,
1575810206.921,,1.000000e+003,9.175119e+001,2.097233e-004,0.000000e+000,3,9.953904e-001,0.000000e+000,,,,,,,,,,,,,,24,1,4.000000e+000,4.273529e-001,0.000000e+000,0,,0,
1575810292.531,,1.000000e+003,8.879298e+001,2.166671e-004,0.000000e+000,3,9.949095e-001,0.000000e+000,,,,,,,,,,,,,,24,1,4.000000e+000,3.740616e-001,0.000000e+000,0,,0,
1575810377.625,,1.000000e+003,8.575905e+001,2.243327e-004,0.000000e+000,3,9.954356e-001,0.000000e+000,,,,,,,,,,,,,,24,1,4.000000e+000,4.461441e-001,0.000000e+000,0,,0,
1575810462.562,,1.000000e+003,8.273195e+001,2.317704e-004,0.000000e+000,3,9.954535e-001,0.000000e+000,,,,,,,,,,,,,,24,1,4.000000e+000,4.521713e-001,0.000000e+000,0,,0,
1575810545.375,,1.000000e+003,7.971729e+001,2.403647e-004,0.000000e+000,3,9.957265e-001,0.000000e+000,,,,,,,,,,,,,,24,1,4.000000e+000,3.970795e-001,0.000000e+000,0,,0,
1575810629.515,,1.000000e+003,7.672021e+001,2.488277e-004,0.000000e+000,3,9.956958e-001,0.000000e+000,,,,,,,,,,,,,,24,1,4.000000e+000,3.804932e-001,0.000000e+000,0,,0,
1575810711.453,,1.000000e+003,7.371664e+001,2.581704e-004,0.000000e+000,3,9.957343e-001,0.000000e+000,,,,,,,,,,,,,,24,1,4.000000e+000,4.292831e-001,0.000000e+000,0,,0,
1575810792.593,,1.000000e+003,7.072180e+001,2.680580e-004,0.000000e+000,3,9.960897e-001,0.000000e+000,,,,,,,,,,,,,,24,1,4.000000e+000,4.632950e-001,0.000000e+000,0,,0,
1575810874.421,,1.000000e+003,6.771230e+001,2.791520e-004,0.000000e+000,3,9.956208e-001,0.000000e+000,,,,,,,,,,,,,,24,1,4.000000e+000,5.151062e-001,0.000000e+000,0,,0,
1575810954.171,,1.000000e+003,6.474856e+001,2.909811e-004,0.000000e+000,3,9.964874e-001,0.000000e+000,,,,,,,,,,,,,,24,1,4.000000e+000,4.392700e-001,0.000000e+000,0,,0,
1575811034.171,,1.000000e+003,6.172081e+001,3.036321e-004,0.000000e+000,3,9.965426e-001,0.000000e+000,,,,,,,,,,,,,,24,1,4.000000e+000,4.809799e-001,0.000000e+000,0,,0,
1575811111.312,,1.000000e+003,5.872799e+001,3.166351e-004,0.000000e+000,3,9.969764e-001,0.000000e+000,,,,,,,,,,,,,,24,1,4.000000e+000,4.756088e-001,0.000000e+000,0,,0,
1575811191.984,,1.000000e+003,5.576398e+001,3.318053e-004,0.000000e+000,3,9.967532e-001,0.000000e+000,,,,,,,,,,,,,,24,1,4.000000e+000,4.058075e-001,0.000000e+000,0,,0,
1575811280.546,,1.000000e+003,5.275329e+001,3.478609e-004,0.000000e+000,3,9.966535e-001,0.000000e+000,,,,,,,,,,,,,,24,1,4.000000e+000,3.556709e-001,0.000000e+000,0,,0,
1575811367.343,,1.000000e+003,4.979507e+001,3.653164e-004,0.000000e+000,3,9.967496e-001,0.000000e+000,,,,,,,,,,,,,,24,1,4.000000e+000,3.828392e-001,0.000000e+000,0,,0,
1575811453.890,,1.000000e+003,4.679982e+001,3.857795e-004,0.000000e+000,3,9.973354e-001,0.000000e+000,,,,,,,,,,,,,,24,1,4.000000e+000,3.736115e-001,0.000000e+000,0,,0,
1575811538.875,,1.000000e+003,4.380431e+001,4.071807e-004,0.000000e+000,3,9.971481e-001,0.000000e+000,,,,,,,,,,,,,,24,1,4.000000e+000,3.514099e-001,0.000000e+000,0,,0,
1575811625.406,,1.000000e+003,4.076186e+001,4.324124e-004,0.000000e+000,3,9.972677e-001,0.000000e+000,,,,,,,,,,,,,,24,1,4.000000e+000,3.585701e-001,0.000000e+000,0,,0,
1575811710.046,,1.000000e+003,3.775948e+001,4.605291e-004,0.000000e+000,3,9.978979e-001,0.000000e+000,,,,,,,,,,,,,,24,1,4.000000e+000,4.048004e-001,0.000000e+000,0,,0,
1575811791.906,,1.000000e+003,3.473830e+001,4.920979e-004,0.000000e+000,3,9.978904e-001,0.000000e+000,,,,,,,,,,,,,,24,1,4.000000e+000,3.821411e-001,0.000000e+000,0,,0,
1575811871.546,,1.000000e+003,3.179972e+001,5.868340e-004,0.000000e+000,3,9.029331e-001,0.000000e+000,,,,,,,,,,,,,,24,1,4.000000e+000,3.959293e-001,0.000000e+000,0,,0,
1575811951.281,,1.000000e+003,2.878796e+001,5.683723e-004,0.000000e+000,3,9.980209e-001,0.000000e+000,,,,,,,,,,,,,,24,1,4.000000e+000,3.716908e-001,0.000000e+000,0,,0,
1575812031.875,,1.000000e+003,2.572818e+001,6.164004e-004,0.000000e+000,3,9.979619e-001,0.000000e+000,,,,,,,,,,,,,,24,1,4.000000e+000,3.968105e-001,0.000000e+000,0,,0,
1575812118.031,,1.000000e+003,2.274961e+001,6.717923e-004,0.000000e+000,3,9.981908e-001,0.000000e+000,,,,,,,,,,,,,,24,1,4.000000e+000,4.413815e-001,0.000000e+000,0,,0,
1575812204.843,,1.000000e+003,1.976099e+001,7.353224e-004,0.000000e+000,3,9.982033e-001,0.000000e+000,,,,,,,,,,,,,,24,1,4.000000e+000,4.199314e-001,0.000000e+000,0,,0,
1575812292.203,,1.000000e+003,1.676843e+001,8.103601e-004,0.000000e+000,3,9.982319e-001,0.000000e+000,,,,,,,,,,,,,,24,1,4.000000e+000,3.898792e-001,0.000000e+000,0,,0,
1575812380.281,,1.000000e+003,1.375268e+001,8.998137e-004,0.000000e+000,3,9.980511e-001,0.000000e+000,,,,,,,,,,,,,,24,1,4.000000e+000,3.897495e-001,0.000000e+000,0,,0,
1575812467.890,,1.000000e+003,1.075691e+001,1.003910e-003,0.000000e+000,3,9.980310e-001,0.000000e+000,,,,,,,,,,,,,,24,1,4.000000e+000,3.270597e-001,0.000000e+000,0,,0,
1575812561.765,,1.000000e+003,7.782275e+000,1.139604e-003,0.000000e+000,3,9.980636e-001,0.000000e+000,,,,,,,,,,,,,,24,1,4.000000e+000,3.084931e-001,0.000000e+000,0,,0,
1575812725.296,,1.000000e+003,4.773704e+000,1.344083e-003,0.000000e+000,3,9.980042e-001,0.000000e+000,,,,,,,,,,,,,,24,1,4.000000e+000,3.370681e-001,0.000000e+000,0,,0,
1575812974.765,,1.000000e+003,1.993371e+000,1.825250e-003,0.000000e+000,3,9.978569e-001,0.000000e+000,,,,,,,,,,,,,,24,1,4.000000e+000,5.480051e-004,0.000000e+000,0,,0,